Workbook

Sheet Inversión Inicial
A1: Inversión Inicial
A2: Tipo de inversión | B2: Valor
A3: Diseño UX/UI | B3: =B29 -> 5000000
A4: Producción de contenidos interactivos | B4: =B37 -> 3740000
A5: Equipos de cómputo y hardware | B5: =D17 -> 9100000
A6: Marketing, lanzamiento y proyección | B6: =B45 -> 16000000
A7: Consultoría especializada y mentoría | B7: =B52 -> 6000000
A8: Creación de infraestructura y arquitectura de software | B8: =B60 -> 3700000
A9: SUBTOTAL | B9: =SUM(B3:B8) -> 43540000
A11: Activos Tangibles
A12: Concepto | B12: Cantidad | C12: Valor Unitario | D12: Valor Total
A13: Computadoras/Laptops | B13: 2 | C13: 3000000 | D13: =C13*B13 -> 6000000
A14: Monitores | B14: 2 | C14: 800000 | D14: =C14*B14 -> 1600000
A15: Perifericos (Mouse, Teclados, Audifonos) | B15: 2 | C15: 300000 | D15: =C15*B15 -> 600000
A16: Accesorios (Papeleria, etc) | B16: 2 | C16: 450000 | D16: =C16*B16 -> 900000
A17: SUBTOTAL | D17: =SUM(D13:D16) -> 9100000
A19: Capital Social
A20: Tipo de inversión | B20: Valor
A21: Financiamiento por Deuda | B21: =B9*0.65 -> 28301000
A22: Capital Social | B22: =B9*0.35 -> 15239000
A24: Inversión en Diseño UX/UI
A25: Concepto | B25: Valor
A26: Investigación UX (Tesis y Entrevistas) | B26: 1500000
A27: Diseño UI (Mockups y Prototipos) | B27: 2000000
A28: Prubeas de Usabilidad y Ajustes | B28: 1500000
A29: SUBTOTAL | B29: =SUM(B26:B28) -> 5000000
A31: Inversión en Producción de Contenidos Interactivos
A32: Concepto | B32: Valor
A33: Guión y Diseño | B33: 920000
A34: Desarrollo de Simuladores | B34: 1300000
A35: Licencias y Recursos (Stock y Assets) | B35: 600000
A36: Producción Multimedia (Audios y Videos) | B36: 920000
A37: SUBTOTAL | B37: =SUM(B33:B36) -> 3740000
A39: Inversión en Marketing, Lanzamiento y Proyección
A40: Concepto | B40: Valor
A41: Estrategia y Branding (Diseño y Marca) | B41: 3500000
A42: Campañas digitales (Google Ads o RRSS) | B42: 7000000
A43: Producción Audiovisual Promocional | B43: 3500000
A44: Eventos y Demostraciones (Material Físico) | B44: 2000000
A45: SUBTOTAL | B45: =SUM(B41:B44) -> 16000000
...

Sheet Costos de Operación Gravables
A1: Costos de Operación Gravables | F1: Costos de Operación Gravables (valor trimestral)
A2: Sueldos de los Empleados | F2: Sueldos de los Empleados
A3: Tipo de inversión | B3: Unidades | C3: Valor Unitario/mes | D3: Valor Total/mes | F3: Valor de 0 | G3: Conversión Anual | H3: Tasa de Crecimiento | I3: Año 0 | J3: Año 1 | K3: Año 2 | L3: Año 3 | M3: Año 4 | N3: Año 5
A4: Líder de Desarrollo | B4: 1 | C4: 3000000 | D4: =C4*B4 -> 3000000 | F4: =D6 -> 6000000 | G4: =F4*12 -> 72000000 | H4: 0.1 | I4: 0 | J4: =G4 -> 72000000 | K4: =J$4*($H$4+1) -> 79200000 | L4: =K$4*($H$4+1) -> 87120000 | M4: =L$4*($H$4+1) -> 95832000 | N4: =M$4*($H$4+1) -> 1.054152e+08
A5: Líder I+D+I | B5: 1 | C5: 3000000 | D5: =C5*B5 -> 3000000 | F5: Prestaciones y Parafiscales
A6: Total | C6: =SUM(C4:C5) -> 6000000 | D6: =SUM(D4:D5) -> 6000000 | F6: Valor de 0 | G6: Conversión Anual | H6: Tasa de Crecimiento | I6: Año 0 | J6: Año 1 | K6: Año 2 | L6: Año 3 | M6: Año 4 | N6: Año 5
A7: Prestaciones y Parafiscales | F7: =D17 -> 1788578 | G7: =F7*12 -> 21462936 | H7: 0.1 | I7: 0 | J7: =G7 -> 21462936 | K7: =J7*($H$7+1) -> 23609230 | L7: =K7*($H$7+1) -> 25970153 | M7: =L7*($H$7+1) -> 28567168 | N7: =M7*($H$7+1) -> 31423885
A8: Tipo de inversión | B8: Unidades | C8: Valor Unitario/mes | D8: Valor Total/mes | F8: Infraestructuras
A9: Cesantias | B9: =SUM($B$4:$B$6) -> 2 | C9: 166600 | D9: =C9*B9 -> 333200 | F9: Valor de 0 | G9: Conversión Anual | H9: Tasa de Crecimiento | I9: Año 0 | J9: Año 1 | K9: Año 2 | L9: Año 3 | M9: Año 4 | N9: Año 5
A10: Intereses sobre cesantias | B10: =SUM($B$4:$B$6) -> 2 | C10: 20000 | D10: =C10*B10 -> 40000 | F10: =D22 -> 3720000 | G10: =F10*12 -> 44640000 | H10: 0.06 | I10: 0 | J10: =G10 -> 44640000 | K10: =J10*($H$10+1) -> 47318400 | L10: =K10*($H$7+1) -> 52050240 | M10: =L10*($H$7+1) -> 57255264 | N10: =M10*($H$7+1) -> 62980790
A11: Primas | B11: =SUM($B$4:$B$6) -> 2 | C11: 166600 | D11: =C11*B11 -> 333200 | F11: Otros
A12: Vacaciones | B12: =SUM($B$4:$B$6) -> 2 | C12: 73013 | D12: =C12*B12 -> 146026 | F12: Valor de 0 | G12: Conversión Anual | H12: Tasa de Crecimiento | I12: Año 0 | J12: Año 1 | K12: Año 2 | L12: Año 3 | M12: Año 4 | N12: Año 5
A13: Pensiones (AFP) | B13: =SUM($B$4:$B$6) -> 2 | C13: 210109 | D13: =C13*B13 -> 420218 | F13: =D26 -> 1451000 | G13: N/A | H13: N/A | I13: =F13 -> 1451000
A14: Salud (EPS) | B14: =SUM($B$4:$B$6) -> 2 | C14: 148827 | D14: =C14*B14 -> 297654 | F14: TOTAL
A15: Riesgos Laborales (ARL) | B15: =SUM($B$4:$B$6) -> 2 | C15: 9140 | D15: =C15*B15 -> 18280 | I15: =SUM(I4,I7,I10,I13) -> 1451000 | J15: =SUM(J4,J7,J10,J13) -> 138102936 | K15: =SUM(K4,K7,K10,K13) -> 1.5012763e+08 | L15: =SUM(L4,L7,L10,L13) -> 1.6514039e+08 | M15: =SUM(M4,M7,M10,M13) -> 1.8165443e+08 | N15: =SUM(N4,N7,N10,N13) -> 1.9981987e+08
A16: Caja de Compensación Familiar | B16: =SUM($B$4:$B$6) -> 2 | C16: 100000 | D16: =C16*B16 -> 200000
A17: Total | C17: =SUM(C9:C16) -> 894289 | D17: =SUM(D9:D16) -> 1788578
A18: Infraestructuras
A19: Tipo de inversión | B19: Unidades | C19: Valor Unitario/mes | D19: Valor Total/mes
A20: Internet | B20: 1 | C20: 220000 | D20: =C20*B20 -> 220000
A21: Servicios de Infraestructura/Hosting | B21: 1 | C21: 3500000 | D21: =C21*B21 -> 3500000
A22: Total | C22: =SUM(C20:C21) -> 3720000 | D22: =SUM(D20:D21) -> 3720000
A23: Otros
A24: Tipo de inversión | B24: Unidades | C24: Valor Unitario/mes | D24: Valor Total/mes
A25: Registros y Estatos | B25: 1 | C25: =B36 -> 1451000 | D25: =C25*B25 -> 1451000
A26: Total | C26: =SUM(C25) -> 1451000 | D26: =SUM(D25) -> 1451000
A28: Activos Fijos Intangibles
A29: Concepto | B29: Valor
A30: Registro de Marca | B30: 1288000
A31: Estatutos | B31: 30000
A32: Registro Cámara de Comercio de Bogotá | B32: 69000
A33: Inscripción de Libros Contables | B33: 64000
A34: Apertura de Cuentas Bancarias | B34: N/A
A35: Formulario Único de Registro Empresarial | B35: N/A
A36: Total | B36: =SUM(B30:B33) -> 1451000
A38: Activos Fijos
A39: Concepto | B39: Valor
A40: Activos Fijos Tangibles | B40: ='Inversión Inicial'!D17 -> 9100000
A41: Activos Fijos Intangibles | B41: =B36 -> 1451000
A42: Total | B42: =SUM(B40:B41) -> 10551000

Sheet Proyección de Ventas e Incremen
A1: Ingresos y Proyecciones de Venta | H1: Proyección Incremento de Ventas
A2: Ingresos | H2: IPC Proyectado y Flujo de Efectivo
A3: Concepto | C3: Unidades | D3: Valor/mes | E3: Valor/trimestre | F3: Valor/año | H3: Indicador | I3: Año 0 | J3: Año 1 (2027) | K3: Año 2 (2028) | L3: Año 3 (2029) | M3: Año 4 (2030) | N3: Año 5 (2031)
A4: Plan Gratuito | C4: N/A | D4: 0 | E4: =D4*3 -> 0 | F4: =D4*12 -> 0 | H4: IPC Proyectado | J4: 0.046 | K4: 0.039 | L4: 0.037 | M4: 0.035 | N4: 0.034
A5: Plan Suscriptor | C5: N/A | D5: 30000 | E5: =D5*3 -> 90000 | F5: =D5*12 -> 360000 | H5: % Crecimiento de Ventas | J5: 0.25 | K5: 0.22 | L5: 0.25 | M5: 0.29 | N5: 0.34
A6: Publicidad de Plan Gratuito | C6: N/A | D6: 300 | E6: =D6*3 -> 900 | F6: =D6*12 -> 3600 | H6: Crecimiento de ventas indexación IPC y % crecimiento | J6: =SUM(J4:J5) -> 0.296 | K6: =SUM(K4:K5) -> 0.259 | L6: =SUM(L4:L5) -> 0.287 | M6: =SUM(M4:M5) -> 0.325 | N6: =SUM(N4:N5) -> 0.374
A7: Proyección de Ventas | H7: Flujo de efectivo | J7: =F12*(1+J6) -> 139968000 | K7: =J7*(1+K6) -> 176219712 | L7: =K7*(1+L6) -> 2.2679477e+08 | M7: =L7*(1+M6) -> 3.0050307e+08 | N7: =M7*(1+N6) -> 4.1289122e+08
A8: Servicio | B8: Valor/mes | C8: N° Suscripción/mes | D8: Ingreso/mes | E8: Ingreso/trimestre | F8: Ingreso/anual
A9: Plan Gratuito | B9: =D4 -> 0 | C9: 3000 | D9: =B9*$C$9 -> 0 | E9: =D9*3 -> 0 | F9: =D9*12 -> 0
A10: Plan Suscriptor | B10: =D5 -> 30000 | C10: =C9*0.09 -> 270 | D10: =B10*$C$10 -> 8100000 | E10: =D10*3 -> 24300000 | F10: =D10*12 -> 97200000
A11: Publicidad de Plan Gratuito | B11: 300 | C11: =C9 -> 3000 | D11: =B11*$C$11 -> 900000 | E11: =D11*3 -> 2700000 | F11: =D11*12 -> 10800000
A12: Total | C12: =SUM(C10:C11) -> 3270 | D12: =SUM(D9:D11) -> 9000000 | E12: =SUM(E9:E11) -> 27000000 | F12: =SUM(F9:F11) -> 108000000
A14: Tabla de Financiamiento
A15: Concepto | B15: Valor
A16: Financiamiento Externo | B16: ='Costos de Operación Gravables'!$B$42*0.65 -> 6858150
A17: Aportes Sociales | B17: ='Costos de Operación Gravables'!$B$42*0.35 -> 3692850
A18: Total | B18: =SUM(B16:B17) -> 10551000

Sheet Amortización y Depreciación
A1: Amortización y Depreciación | D1: Amortización de Crédito
A2: Préstamo (en Banco GNB Sudameris) | D2: Período | E2: Saldo | F2: Interes | G2: Amortización | H2: Pago al Crédito | I2: Saldo Final
A3: Concepto | B3: Unidades | D3: Año 0 | E3: =B4 -> 28301000 | F3: 0 | G3: 0 | H3: 0 | I3: =E3 -> 28301000
A4: Valor del Préstamo | B4: ='Inversión Inicial'!B9*0.65 -> 28301000 | D4: Año 1 | E4: =I3 -> 28301000 | F4: =E4*$B$7 -> 4709286.4 | G4: =$B$8 -> 10243567 | H4: =G4-F4 -> 5534280.4 | I4: =E4-H4 -> 22766720
A5: Cuota Inicial | B5: 0 | D5: Año 2 | E5: =I4 -> 22766720 | F5: =E5*$B$7 -> 3788382.1 | G5: =$B$8 -> 10243567 | H5: =G5-F5 -> 6455184.7 | I5: =E5-H5 -> 16311535
A6: Plazo | B6: 48 meses | D6: Año 3 | E6: =I5 -> 16311535 | F6: =E6*$B$7 -> 2714239.4 | G6: =$B$8 -> 10243567 | H6: =G6-F6 -> 7529327.4 | I6: =E6-H6 -> 8782207.6
A7: Tasa de Interés (trimestralmente) | B7: 0.1664 | D7: Año 4 | E7: =I6 -> 8782207.6 | F7: =E7*$B$7 -> 1461359.3 | G7: =$B$8 -> 10243567 | H7: =G7-F7 -> 8782207.5 | I7: =E7-H7 -> 0.09296336
A8: Pago Mensual | B8: 10243567 | D8: Año 5 | E8: =I7 -> 0.09296336 | F8: =E8*$B$7 -> 0.015469103 | G8: 0 | H8: =G8-F8 -> -0.015469103 | I8: =E8-H8 -> 0.10843246
D10: Depreciación
D11: Activos Fijos | E11: Vida Útil | F11: Valor Inicial | G11: Año 1 | H11: Año 2 | I11: Año 3 | J11: Año 4 | K11: Año 5
D12: Computador 1 | E12: 5 años | F12: ='Inversión Inicial'!$C$13 -> 3000000 | G12: =$F12*G$17 -> 600000 | H12: =$F12*H$17 -> 1200000 | I12: =$F12*I$17 -> 1800000 | J12: =$F12*J$17 -> 2400000 | K12: =$F12*K$17 -> 3000000
D13: Perifericos 1 | E13: 5 años | F13: ='Inversión Inicial'!$C$15 -> 300000 | G13: =$F13*G$17 -> 60000 | H13: =$F13*H$17 -> 120000 | I13: =$F13*I$17 -> 180000 | J13: =$F13*J$17 -> 240000 | K13: =$F13*K$17 -> 300000
D14: Computador 2 | E14: 5 años | F14: ='Inversión Inicial'!$C$13 -> 3000000 | G14: =$F14*G$17 -> 600000 | H14: =$F14*H$17 -> 1200000 | I14: =$F14*I$17 -> 1800000 | J14: =$F14*J$17 -> 2400000 | K14: =$F14*K$17 -> 3000000
D15: Perifericos 2 | E15: 5 años | F15: ='Inversión Inicial'!$C$15 -> 300000 | G15: =$F15*G$17 -> 60000 | H15: =$F15*H$17 -> 120000 | I15: =$F15*I$17 -> 180000 | J15: =$F15*J$17 -> 240000 | K15: =$F15*K$17 -> 300000
D16: Depreciación Total | G16: =SUM(G12:G15) -> 1320000 | H16: =SUM(H12:H15) -> 2640000 | I16: =SUM(I12:I15) -> 3960000 | J16: =SUM(J12:J15) -> 5280000 | K16: =SUM(K12:K15) -> 6600000
D17: Tasa de Depreciación Total | G17: 0.2 | H17: 0.4 | I17: 0.6 | J17: 0.8 | K17: 1
D19: Depreciación
D20: Activos Fijos | E20: Vida Útil | F20: Valor Inicial | G20: Año 1 | H20: Año 2 | I20: Año 3 | J20: Año 4 | K20: Año 5
D21: Computador 1 | E21: 5 años | F21: ='Inversión Inicial'!$C$13 -> 3000000 | G21: =$F21-($F21*G$26) -> 2400000 | H21: =$F21-($F21*H$26) -> 1800000 | I21: =$F21-($F21*I$26) -> 1200000 | J21: =$F21-($F21*J$26) -> 600000 | K21: =$F21-($F21*K$26) -> 0
D22: Perifericos 1 | E22: 5 años | F22: ='Inversión Inicial'!$C$15 -> 300000 | G22: =$F22-($F22*G$26) -> 240000 | H22: =$F22-($F22*H$26) -> 180000 | I22: =$F22-($F22*I$26) -> 120000 | J22: =$F22-($F22*J$26) -> 60000 | K22: =$F22-($F22*K$26) -> 0
D23: Computador 2 | E23: 5 años | F23: ='Inversión Inicial'!$C$13 -> 3000000 | G23: =$F23-($F23*G$26) -> 2400000 | H23: =$F23-($F23*H$26) -> 1800000 | I23: =$F23-($F23*I$26) -> 1200000 | J23: =$F23-($F23*J$26) -> 600000 | K23: =$F23-($F23*K$26) -> 0
D24: Perifericos 2 | E24: 5 años | F24: ='Inversión Inicial'!$C$15 -> 300000 | G24: =$F24-($F24*G$26) -> 240000 | H24: =$F24-($F24*H$26) -> 180000 | I24: =$F24-($F24*I$26) -> 120000 | J24: =$F24-($F24*J$26) -> 60000 | K24: =$F24-($F24*K$26) -> 0
D25: Depreciación Total | G25: =SUM(G21:G24) -> 5280000 | H25: =SUM(H21:H24) -> 3960000 | I25: =SUM(I21:I24) -> 2640000 | J25: =SUM(J21:J24) -> 1320000 | K25: =SUM(K21:K24) -> 0
D26: Tasa de Depreciación Total | G26: 0.2 | H26: 0.4 | I26: 0.6 | J26: 0.8 | K26: 1

Sheet Balance General
A1: BALANCE GENERAL PROYECTADO
A2: EDUCAFIN S.A.S.
A4: TRIMESTRE | C4: AÑO 0 | D4: AÑO 1 | E4: AÑO 2 | F4: AÑO 3 | G4: AÑO 4 | H4: AÑO 5
A5: ACTIVOS
A6: ACTIVOS CORRIENTES
B7: Efectivo y Equivalente de Efectivo | C7: ='Proyección de Ventas e Incremen'!I7 -> 0 | D7: ='Proyección de Ventas e Incremen'!J7 -> 139968000 | E7: ='Proyección de Ventas e Incremen'!K7 -> 176219712 | F7: ='Proyección de Ventas e Incremen'!L7 -> 2.2679477e+08 | G7: ='Proyección de Ventas e Incremen'!M7 -> 3.0050307e+08 | H7: ='Proyección de Ventas e Incremen'!N7 -> 4.1289122e+08
B8: Cuentas por Cobrar al Personal y Accionistas | C8: ='[1]Proyección de Ventas e Incremen'!I8 -> 0 | D8: 0 | E8: 0 | F8: 0 | G8: 0 | H8: 0
B9: Gastos Pagados por Anticipado | C9: 0 | D9: 0 | E9: 0 | F9: 0 | G9: 0 | H9: 0
B10: Otros Activos | C10: 0 | D10: 0 | E10: 0 | F10: 0 | G10: 0 | H10: 0
B11: Total Activos Corrientes | C11: =SUM(C7:C10) -> 0 | D11: =SUM(D7:D10) -> 139968000 | E11: =SUM(E7:E10) -> 176219712 | F11: =SUM(F7:F10) -> 2.2679477e+08 | G11: =SUM(G7:G10) -> 3.0050307e+08 | H11: =SUM(H7:H10) -> 4.1289122e+08
A13: ACTIVOS NO CORRIENTES
B14: Inmuebles y Equipos (neto) | C14: ='Inversión Inicial'!$D$17-C16 -> 9100000 | D14: ='Inversión Inicial'!$D$17-D16 -> 7780000 | E14: ='Inversión Inicial'!$D$17-E16 -> 6460000 | F14: ='Inversión Inicial'!$D$17-F16 -> 5140000 | G14: ='Inversión Inicial'!$D$17-G16 -> 3820000 | H14: ='Inversión Inicial'!$D$17-H16 -> 2500000
B15: Intangibles (neto) | C15: ='Costos de Operación Gravables'!B36 -> 1451000 | D15: =C15*104% -> 1509040 | E15: =D15*104% -> 1569401.6 | F15: =E15*104% -> 1632177.7 | G15: =F15*104% -> 1697464.8 | H15: =G15*104% -> 1765363.4
B16: Depreciación de Equipos | C16: 0 | D16: ='Amortización y Depreciación'!G16 -> 1320000 | E16: ='Amortización y Depreciación'!H16 -> 2640000 | F16: ='Amortización y Depreciación'!I16 -> 3960000 | G16: ='Amortización y Depreciación'!J16 -> 5280000 | H16: ='Amortización y Depreciación'!K16 -> 6600000
B17: Total Activos No Corrientes | C17: =SUM(C14:C15) -> 10551000 | D17: =SUM(D12:D15) -> 9289040 | E17: =SUM(E12:E15) -> 8029401.6 | F17: =SUM(F12:F15) -> 6772177.7 | G17: =SUM(G12:G15) -> 5517464.8 | H17: =SUM(H12:H15) -> 4265363.4
A19: ACTIVOS DIFERIDOS
B20: Propiedad Intelectual | C20: 0 | D20: 0 | E20: 0 | F20: 0 | G20: 0 | H20: 0
B21: Gastos Legales | C21: 0 | D21: 0 | E21: 0 | F21: 0 | G21: 0 | H21: 0
B22: Otros Seguros | C22: 0 | D22: 0 | E22: 0 | F22: 0 | G22: 0 | H22: 0
B23: Total Activos Diferidos | C23: =SUM(C20:C22) -> 0 | D23: =SUM(D20:D22) -> 0 | E23: =SUM(E20:E22) -> 0 | F23: =SUM(F20:F22) -> 0 | G23: =SUM(G20:G22) -> 0 | H23: =SUM(H20:H22) -> 0
A25: TOTAL ACTIVO | C25: =SUM(C11,C17,C23) -> 10551000 | D25: =SUM(D11,D17,D23) -> 149257040 | E25: =SUM(E11,E17,E23) -> 1.8424911e+08 | F25: =SUM(F11,F17,F23) -> 2.3356695e+08 | G25: =SUM(G11,G17,G23) -> 3.0602053e+08 | H25: =SUM(H11,H17,H23) -> 4.1715658e+08
A26: PASIVOS
A27: PASIVOS CORRIENTES
B28: Prestaciones y Parafiscales | C28: ='Costos de Operación Gravables'!I7 -> 0 | D28: ='Costos de Operación Gravables'!J7 -> 21462936 | E28: ='Costos de Operación Gravables'!K7 -> 23609230 | F28: ='Costos de Operación Gravables'!L7 -> 25970153 | G28: ='Costos de Operación Gravables'!M7 -> 28567168 | H28: ='Costos de Operación Gravables'!N7 -> 31423885
B29: Infraestructura | C29: ='Costos de Operación Gravables'!I10 -> 0 | D29: ='Costos de Operación Gravables'!J10 -> 44640000 | E29: ='Costos de Operación Gravables'!K10 -> 47318400 | F29: ='Costos de Operación Gravables'!L10 -> 52050240 | G29: ='Costos de Operación Gravables'!M10 -> 57255264 | H29: ='Costos de Operación Gravables'!N10 -> 62980790
B30: Amortización | C30: ='Amortización y Depreciación'!G3 -> 0 | D30: ='Amortización y Depreciación'!G4 -> 10243567 | E30: ='Amortización y Depreciación'!G5 -> 10243567 | F30: ='Amortización y Depreciación'!G6 -> 10243567 | G30: ='Amortización y Depreciación'!G7 -> 10243567 | H30: ='Amortización y Depreciación'!G8 -> 0
B31: Nómina | C31: ='Costos de Operación Gravables'!I4 -> 0 | D31: ='Costos de Operación Gravables'!J4 -> 72000000 | E31: ='Costos de Operación Gravables'!K4 -> 79200000 | F31: ='Costos de Operación Gravables'!L4 -> 87120000 | G31: ='Costos de Operación Gravables'!M4 -> 95832000 | H31: ='Costos de Operación Gravables'!N4 -> 1.054152e+08
B32: Tributos (Impuestos) por pagar | C32: =C25*0.04 -> 422040 | D32: =D25*0.04 -> 5970281.6 | E32: =E25*0.04 -> 7369964.5 | F32: =F25*0.04 -> 9342677.9 | G32: =G25*0.04 -> 12240821 | H32: =H25*0.04 -> 16686263
B33: Total Pasivos Corrientes | C33: =SUM(C28:C32) -> 422040 | D33: =SUM(D28:D32) -> 1.5431678e+08 | E33: =SUM(E28:E32) -> 1.6774116e+08 | F33: =SUM(F28:F32) -> 1.8472664e+08 | G33: =SUM(G28:G32) -> 2.0413882e+08 | H33: =SUM(H28:H32) -> 2.1650614e+08
A35: PASIVOS NO CORRIENTES
B36: Inversión Inicial | C36: ='Inversión Inicial'!B9 -> 43540000 | D36: 0 | E36: 0 | F36: 0 | G36: 0 | H36: 0
B37: Total Pasivos No Corrientes | C37: =SUM(C36) -> 43540000 | D37: =SUM(D36) -> 0 | E37: =SUM(E36) -> 0 | F37: =SUM(F36) -> 0 | G37: =SUM(G36) -> 0 | H37: =SUM(H36) -> 0
A39: TOTAL PASIVOS | C39: =C33+C37 -> 43962040 | D39: =D33+D37 -> 1.5431678e+08 | E39: =E33+E37 -> 1.6774116e+08 | F39: =F33+F37 -> 1.8472664e+08 | G39: =G33+G37 -> 2.0413882e+08 | H39: =H33+H37 -> 2.1650614e+08
A41: CAPITAL
B42: Capital Social | C42: ='Inversión Inicial'!B22 -> 15239000 | D42: =C42 -> 15239000 | E42: =D42 -> 15239000 | F42: =E42 -> 15239000 | G42: =F42 -> 15239000 | H42: =G42 -> 15239000
B43: Utilidad o Pérdida del Ejercicio | C43: ='Estado de Resultados'!C32 -> -45413040 | D43: ='Estado de Resultados'!D32 -> -15668784 | E43: ='Estado de Resultados'!E32 -> 7158551.1 | F43: ='Estado de Resultados'!F32 -> 40748132 | G43: ='Estado de Resultados'!G32 -> 95044249 | H43: ='Estado de Resultados'!H32 -> 1.9506508e+08
A45: TOTAL CAPITAL | C45: =SUM(C42:C43) -> -30174040 | D45: =SUM(D42:D43) -> -429784.4 | E45: =SUM(E42:E43) -> 22397551 | F45: =SUM(F42:F43) -> 55987132 | G45: =SUM(G42:G43) -> 1.1028325e+08 | H45: =SUM(H42:H43) -> 2.1030408e+08
A47: SUMA PASIVOS + CAPITAL | C47: =C39+C45 -> 13788000 | D47: =D39+D45 -> 153887000 | E47: =E39+E45 -> 190138712 | F47: =F39+F45 -> 2.4071377e+08 | G47: =G39+G45 -> 3.1442207e+08 | H47: =H39+H45 -> 4.2681022e+08

Sheet Hoja1

Sheet Estado de Resultados
A1: ESTADO DE RESULTADOS
A2: EDUCAFIN S.A.S.
A4: TRIMESTRE | C4: AÑO 0 | D4: AÑO 1 | E4: AÑO 2 | F4: AÑO 3 | G4: AÑO 4 | H4: AÑO 5
A5: EFECTIVO
B6: Efectivo y equivalente de efectivo | C6: ='Balance General'!C7 -> 0 | D6: ='Balance General'!D7 -> 139968000 | E6: ='Balance General'!E7 -> 176219712 | F6: ='Balance General'!F7 -> 2.2679477e+08 | G6: ='Balance General'!G7 -> 3.0050307e+08 | H6: ='Balance General'!H7 -> 4.1289122e+08
B7: Devoluciones | C7: ='[1]Proyección de Ventas e Incremen'!I8 -> 0 | D7: 0 | E7: 0 | F7: 0 | G7: 0 | H7: 0
B8: Total Ventas Netas | C8: =SUM(C6:C7) -> 0 | D8: =SUM(D6:D7) -> 139968000 | E8: =SUM(E6:E7) -> 176219712 | F8: =SUM(F6:F7) -> 2.2679477e+08 | G8: =SUM(G6:G7) -> 3.0050307e+08 | H8: =SUM(H6:H7) -> 4.1289122e+08
A10: UTILIDAD
B11: Inversion Inicial | C11: ='Balance General'!C36 -> 43540000 | D11: ='Balance General'!D36 -> 0 | E11: ='Balance General'!E36 -> 0 | F11: ='Balance General'!F36 -> 0 | G11: ='Balance General'!G36 -> 0 | H11: ='Balance General'!H36 -> 0
B12: Mano de Obra Fija | C12: ='Balance General'!C28+'Balance General'!C31 -> 0 | D12: ='Balance General'!D28+'Balance General'!D31 -> 93462936 | E12: ='Balance General'!E28+'Balance General'!E31 -> 1.0280923e+08 | F12: ='Balance General'!F28+'Balance General'!F31 -> 1.1309015e+08 | G12: ='Balance General'!G28+'Balance General'!G31 -> 1.2439917e+08 | H12: ='Balance General'!H28+'Balance General'!H31 -> 1.3683908e+08
B13: Diferidos | C13: ='[1]Balance General'!C23 -> 0 | D13: ='[1]Balance General'!D23 -> 0 | E13: ='[1]Balance General'!E23 -> 0 | F13: ='[1]Balance General'!F23 -> 0 | G13: ='[1]Balance General'!G23 -> 0 | H13: ='[1]Balance General'!H23 -> 0
B14: Depreciación | C14: 0 | D14: ='Amortización y Depreciación'!$G$16 -> 1320000 | E14: ='Amortización y Depreciación'!$G$16 -> 1320000 | F14: ='Amortización y Depreciación'!$G$16 -> 1320000 | G14: ='Amortización y Depreciación'!$G$16 -> 1320000 | H14: ='Amortización y Depreciación'!$G$16 -> 1320000
B15: Total Costo de Ventas | C15: =SUM(C11:C14) -> 43540000 | D15: =SUM(D11:D14) -> 94782936 | E15: =SUM(E11:E14) -> 1.0412923e+08 | F15: =SUM(F11:F14) -> 1.1441015e+08 | G15: =SUM(G11:G14) -> 1.2571917e+08 | H15: =SUM(H11:H14) -> 1.3815908e+08
B16: Utilidad Bruta (Ventas - Costo de Ventas) | C16: =C8-C15 -> -43540000 | D16: =D8-D15 -> 45185064 | E16: =E8-E15 -> 72090482 | F16: =F8-F15 -> 1.1238462e+08 | G16: =G8-G15 -> 1.747839e+08 | H16: =H8-H15 -> 2.7473213e+08
A18: UTILIDAD OPERACIONAL
B19: Gastos Administrativos | C19: ='Balance General'!C30+'Balance General'!C29+'Balance General'!C15 -> 1451000 | D19: ='Balance General'!D30+'Balance General'!D29 -> 54883567 | E19: ='Balance General'!E30+'Balance General'!E29 -> 57561967 | F19: ='Balance General'!F30+'Balance General'!F29 -> 62293807 | G19: ='Balance General'!G30+'Balance General'!G29 -> 67498831 | H19: ='Balance General'!H30+'Balance General'!H29 -> 62980790
B20: Gastos de Ventas | C20: 0 | D20: 0 | E20: 0 | F20: 0 | G20: 0 | H20: 0
B21: Total Utilidad Operacional | C21: =C16-SUM(C19:C20) -> -44991000 | D21: =D16-SUM(D19:D20) -> -9698502.8 | E21: =E16-SUM(E19:E20) -> 14528516 | F21: =F16-SUM(F19:F20) -> 50090810 | G21: =G16-SUM(G19:G20) -> 1.0728507e+08 | H21: =H16-SUM(H19:H20) -> 2.1175134e+08
A23: OTRAS UTILIDADES
B24: Otros Egresos | C24: =0 -> 0 | D24: =0 -> 0 | E24: =0 -> 0 | F24: =0 -> 0 | G24: =0 -> 0 | H24: =0 -> 0
B25: Gastos Financieros | C25: =0 -> 0 | D25: =0 -> 0 | E25: =0 -> 0 | F25: =0 -> 0 | G25: =0 -> 0 | H25: =0 -> 0
B26: Total Otras Utilidades | C26: =C21-SUM(C24:C25) -> -44991000 | D26: =D21-SUM(D24:D25) -> -9698502.8 | E26: =E21-SUM(E24:E25) -> 14528516 | F26: =F21-SUM(F24:F25) -> 50090810 | G26: =G21-SUM(G24:G25) -> 1.0728507e+08 | H26: =H21-SUM(H24:H25) -> 2.1175134e+08
A28: IMPUESTOS
B29: Impuestos | C29: ='Balance General'!C32 -> 422040 | D29: ='Balance General'!D32 -> 5970281.6 | E29: ='Balance General'!E32 -> 7369964.5 | F29: ='Balance General'!F32 -> 9342677.9 | G29: ='Balance General'!G32 -> 12240821 | H29: ='Balance General'!H32 -> 16686263
B30: Total Impuestos | C30: =SUM(C29) -> 422040 | D30: =SUM(D29) -> 5970281.6 | E30: =SUM(E29) -> 7369964.5 | F30: =SUM(F29) -> 9342677.9 | G30: =SUM(G29) -> 12240821 | H30: =SUM(H29) -> 16686263
A32: UTILIDAD NETA | C32: =C26-C30 -> -45413040 | D32: =D26-D30 -> -15668784 | E32: =E26-E30 -> 7158551.1 | F32: =F26-F30 -> 40748132 | G32: =G26-G30 -> 95044249 | H32: =H26-H30 -> 1.9506508e+08

Sheet Flujo de Caja
A1: FLUJO DE CAJA
A2: EDUCAFIN S.A.S.
A4: TRIMESTRE | C4: AÑO 0 | D4: AÑO 1 | E4: AÑO 2 | F4: AÑO 3 | G4: AÑO 4 | H4: AÑO 5
A5: INVERSIÓN INICIAL
B6: Equipos de Cómputo | C6: ='Inversión Inicial'!B5 -> 9100000 | D6: 0 | E6: 0 | F6: 0 | G6: 0 | H6: 0
B7: Equipos de Oficina | C7: =0 -> 0 | D7: =0 -> 0 | E7: =0 -> 0 | F7: =0 -> 0 | G7: =0 -> 0 | H7: =0 -> 0
B8: Capital de Trabajo | C8: =0 -> 0 | D8: =0 -> 0 | E8: =0 -> 0 | F8: =0 -> 0 | G8: =0 -> 0 | H8: =0 -> 0
B9: Preoperativos | C9: =SUM('Inversión Inicial'!B3:B4,'Inversión Inicial'!B6:B7) -> 30740000 | D9: =0 -> 0 | E9: =0 -> 0 | F9: =0 -> 0 | G9: =0 -> 0 | H9: =0 -> 0
B10: Costos de Infraestructura Iniciales | C10: ='Inversión Inicial'!B8 -> 3700000 | D10: =0 -> 0 | E10: =0 -> 0 | F10: =0 -> 0 | G10: =0 -> 0 | H10: =0 -> 0
B11: Total de Inversión Inicial | C11: =SUM(C6:C10) -> 43540000 | D11: =SUM(D6:D10) -> 0 | E11: =SUM(E6:E10) -> 0 | F11: =SUM(F6:F10) -> 0 | G11: =SUM(G6:G10) -> 0 | H11: =SUM(H6:H10) -> 0
A13: ENTRADAS E INGRESOS
B14: Aportaciones de Socios | C14: ='Balance General'!C42 -> 15239000 | D14: =0 -> 0 | E14: =0 -> 0 | F14: =0 -> 0 | G14: =0 -> 0 | H14: =0 -> 0
B15: Aportes de Financiamiento | C15: ='Inversión Inicial'!B21 -> 28301000 | D15: =0 -> 0 | E15: =0 -> 0 | F15: =0 -> 0 | G15: =0 -> 0 | H15: =0 -> 0
B16: Ingresos | C16: ='Proyección de Ventas e Incremen'!I7 -> 0 | D16: ='Proyección de Ventas e Incremen'!J7 -> 139968000 | E16: ='Proyección de Ventas e Incremen'!K7 -> 176219712 | F16: ='Proyección de Ventas e Incremen'!L7 -> 2.2679477e+08 | G16: ='Proyección de Ventas e Incremen'!M7 -> 3.0050307e+08 | H16: ='Proyección de Ventas e Incremen'!N7 -> 4.1289122e+08
B17: Total de Entradas | C17: =SUM(C14:C16) -> 43540000 | D17: =SUM(D14:D16) -> 139968000 | E17: =SUM(E14:E16) -> 176219712 | F17: =SUM(F14:F16) -> 2.2679477e+08 | G17: =SUM(G14:G16) -> 3.0050307e+08 | H17: =SUM(H14:H16) -> 4.1289122e+08
A19: EGRESOS
B20: Mantenimiento de Infraestructura | C20: =0 -> 0 | D20: ='Costos de Operación Gravables'!J10 -> 44640000 | E20: ='Costos de Operación Gravables'!K10 -> 47318400 | F20: ='Costos de Operación Gravables'!L10 -> 52050240 | G20: ='Costos de Operación Gravables'!M10 -> 57255264 | H20: ='Costos de Operación Gravables'!N10 -> 62980790
B21: Amortización | C21: ='Balance General'!C30 -> 0 | D21: ='Balance General'!D30-D22 -> 5534280.4 | E21: ='Balance General'!E30-E22 -> 6455184.7 | F21: ='Balance General'!F30-F22 -> 7529327.4 | G21: ='Balance General'!G30-G22 -> 8782207.5 | H21: ='Balance General'!H30 -> 0
B22: Intereses | C22: 0 | D22: ='Amortización y Depreciación'!F4 -> 4709286.4 | E22: ='Amortización y Depreciación'!F5 -> 3788382.1 | F22: ='Amortización y Depreciación'!F6 -> 2714239.4 | G22: ='Amortización y Depreciación'!F7 -> 1461359.3 | H22: =0 -> 0
B23: Nómina y Prestaciones | C23: ='Balance General'!C31+'Balance General'!C28 -> 0 | D23: ='Balance General'!D31+'Balance General'!D28 -> 93462936 | E23: ='Balance General'!E31+'Balance General'!E28 -> 1.0280923e+08 | F23: ='Balance General'!F31+'Balance General'!F28 -> 1.1309015e+08 | G23: ='Balance General'!G31+'Balance General'!G28 -> 1.2439917e+08 | H23: ='Balance General'!H31+'Balance General'!H28 -> 1.3683908e+08
B24: Remuneraciones y Participaciones por Pagar | C24: =0 -> 0 | D24: =0 -> 0 | E24: =0 -> 0 | F24: =0 -> 0 | G24: =0 -> 0 | H24: =0 -> 0
B25: Total Utilidad Operacional | C25: =SUM(C20:C24) -> 0 | D25: =SUM(D20:D24) -> 1.483465e+08 | E25: =SUM(E20:E24) -> 1.603712e+08 | F25: =SUM(F20:F24) -> 1.7538396e+08 | G25: =SUM(G20:G24) -> 1.91898e+08 | H25: =SUM(H20:H24) -> 1.9981987e+08
A27: DEPRECIACIÓN
B28: Equipos de Cómputo | C28: ='Estado de Resultados'!C14 -> 0 | D28: ='Estado de Resultados'!D14 -> 1320000 | E28: ='Estado de Resultados'!E14 -> 1320000 | F28: ='Estado de Resultados'!F14 -> 1320000 | G28: ='Estado de Resultados'!G14 -> 1320000 | H28: ='Estado de Resultados'!H14 -> 1320000
B29: Total Depreciación | C29: =C28 -> 0 | D29: =D28 -> 1320000 | E29: =E28 -> 1320000 | F29: =F28 -> 1320000 | G29: =G28 -> 1320000 | H29: =H28 -> 1320000
A31: FLUJO DE OPERACIÓN
B32: Impuestos | C32: ='Estado de Resultados'!C29 -> 422040 | D32: ='Estado de Resultados'!D29 -> 5970281.6 | E32: ='Estado de Resultados'!E29 -> 7369964.5 | F32: ='Estado de Resultados'!F29 -> 9342677.9 | G32: ='Estado de Resultados'!G29 -> 12240821 | H32: ='Estado de Resultados'!H29 -> 16686263
B33: Total Flujo de Operación | C33: =C32 -> 422040 | D33: =D32 -> 5970281.6 | E33: =E32 -> 7369964.5 | F33: =F32 -> 9342677.9 | G33: =G32 -> 12240821 | H33: =H32 -> 16686263
A35: FLUJO DE CAJA LIBRE | C35: =C17-(SUM(C11,C25,C29,C33)) -> -422040 | D35: =D17-(SUM(D11,D25,D29,D33)) -> -15668784 | E35: =E17-(SUM(E11,E25,E29,E33)) -> 7158551.1 | F35: =F17-(SUM(F11,F25,F29,F33)) -> 40748132 | G35: =G17-(SUM(G11,G25,G29,G33)) -> 95044249 | H35: =H17-(SUM(H11,H25,H29,H33)) -> 1.9506508e+08

Sheet Flujo de Efectivo
A1: FLUJO DE EFECTIVO
A2: EDUCAFIN S.A.S.
A4: TRIMESTRE | C4: AÑO 0 | D4: AÑO 1 | E4: AÑO 2 | F4: AÑO 3 | G4: AÑO 4 | H4: AÑO 5
A5: FLUJO DE CAJA DE OPERACIÓN
B6: Utilidad del Ejercicio | C6: ='Estado de Resultados'!C32 -> -45413040 | D6: ='Estado de Resultados'!D32 -> -15668784 | E6: ='Estado de Resultados'!E32 -> 7158551.1 | F6: ='Estado de Resultados'!F32 -> 40748132 | G6: ='Estado de Resultados'!G32 -> 95044249 | H6: ='Estado de Resultados'!H32 -> 1.9506508e+08
B7: Depreciaciones | C7: ='Flujo de Caja'!C29 -> 0 | D7: ='Flujo de Caja'!D29 -> 1320000 | E7: ='Flujo de Caja'!E29 -> 1320000 | F7: ='Flujo de Caja'!F29 -> 1320000 | G7: ='Flujo de Caja'!G29 -> 1320000 | H7: ='Flujo de Caja'!H29 -> 1320000
B8: Amortización | C8: ='Flujo de Caja'!C21 -> 0 | D8: ='Flujo de Caja'!D21 -> 5534280.4 | E8: ='Flujo de Caja'!E21 -> 6455184.7 | F8: ='Flujo de Caja'!F21 -> 7529327.4 | G8: ='Flujo de Caja'!G21 -> 8782207.5 | H8: ='Flujo de Caja'!H21 -> 0
B9: Intereses | C9: ='Flujo de Caja'!C22 -> 0 | D9: ='Flujo de Caja'!D22 -> 4709286.4 | E9: ='Flujo de Caja'!E22 -> 3788382.1 | F9: ='Flujo de Caja'!F22 -> 2714239.4 | G9: ='Flujo de Caja'!G22 -> 1461359.3 | H9: ='Flujo de Caja'!H22 -> 0
B10: Impuestos de la Renta | C10: ='Flujo de Caja'!C32 -> 422040 | D10: ='Flujo de Caja'!D32 -> 5970281.6 | E10: ='Flujo de Caja'!E32 -> 7369964.5 | F10: ='Flujo de Caja'!F32 -> 9342677.9 | G10: ='Flujo de Caja'!G32 -> 12240821 | H10: ='Flujo de Caja'!H32 -> 16686263
B11: Flujo de Caja Operativo Neto | C11: =SUM(C6:C10) -> -44991000 | D11: =SUM(D6:D10) -> 1865064 | E11: =SUM(E6:E10) -> 26092082 | F11: =SUM(F6:F10) -> 61654377 | G11: =SUM(G6:G10) -> 1.1884864e+08 | H11: =SUM(H6:H10) -> 2.1307134e+08
A13: FLUJO DE CAJA DE INVERSIÓN
B14: Inversión de Equipos de Computación | C14: ='Inversión Inicial'!B5 -> 9100000 | D14: =0 -> 0 | E14: =0 -> 0 | F14: =0 -> 0 | G14: =0 -> 0 | H14: =0 -> 0
B15: Flujo de Caja de Inversión Neto | C15: =SUM(C14:C14) -> 9100000 | D15: =SUM(D14:D14) -> 0 | E15: =SUM(E14:E14) -> 0 | F15: =SUM(F14:F14) -> 0 | G15: =SUM(G14:G14) -> 0 | H15: =SUM(H14:H14) -> 0
A17: FLUJO DE CAJA DE FINANCIAMIENTO
B18: Capital Social | C18: ='Balance General'!C42 -> 15239000 | D18: ='Balance General'!D42 -> 15239000 | E18: ='Balance General'!E42 -> 15239000 | F18: ='Balance General'!F42 -> 15239000 | G18: ='Balance General'!G42 -> 15239000 | H18: ='Balance General'!H42 -> 15239000
B19: Desembolso Pasivo | C19: ='Flujo de Caja'!C15 -> 28301000 | D19: ='Flujo de Caja'!D15 -> 0 | E19: ='Flujo de Caja'!E15 -> 0 | F19: ='Flujo de Caja'!F15 -> 0 | G19: ='Flujo de Caja'!G15 -> 0 | H19: ='Flujo de Caja'!H15 -> 0
B20: Amortizaciones | C20: =C8 -> 0 | D20: =D8 -> 5534280.4 | E20: =E8 -> 6455184.7 | F20: =F8 -> 7529327.4 | G20: =G8 -> 8782207.5 | H20: =H8 -> 0
B21: Intereses | C21: =C9 -> 0 | D21: =D9 -> 4709286.4 | E21: =E9 -> 3788382.1 | F21: =F9 -> 2714239.4 | G21: =G9 -> 1461359.3 | H21: =H9 -> 0
B22: Flujo de Caja de Financiamiento Neto | C22: =SUM(C18:C21) -> 43540000 | D22: =SUM(D18:D21) -> 25482567 | E22: =SUM(E18:E21) -> 25482567 | F22: =SUM(F18:F21) -> 25482567 | G22: =SUM(G18:G21) -> 25482567 | H22: =SUM(H18:H21) -> 15239000

Sheet Costos Fijos y Punto de Equil.
B2: Costos Fijos y Variables
B3: Costos y/o gastos | D3: Administración y ventas | E3: Producción
B4: Número de producción | D4: 0 | E4: ='Balance General'!D31+'Balance General'!D29 -> 116640000
B5: Numero permanente (100%) | C5: =E4 -> 116640000 | D5: 0 | E5: 0
B6: Otros gastos administrativos | D6: ='Balance General'!D30+'Estado de Resultados'!D29 -> 16213848 | E6: 0
B7: Depreciación de producción | D7: 0 | E7: ='Balance General'!D16 -> 1320000
B8: Depreciación de administración | D8: 0 | E8: 0
B9: Subtotal | D9: =SUM(D4:D8) -> 16213848 | E9: =SUM(E4:E8) -> 117960000
B10: Imprevistos | C10: 0.1 | D10: =D9*$C$10 -> 1621384.8 | E10: =E9*$C$10 -> 11796000
B11: Total | D11: =D9-D10 -> 14592464 | E11: =E9-E10 -> 106164000
B13: Estimaciones del Punto de Equilibrio
B14: Ventas Iniciales Planteadas | C14: 270
B15: Costo de producción por unidad | C15: =E11/C14 -> 393200
B16: Costo por unidad | C16: =SUM(D11:E11)/C14 -> 447246.16
B17: Valor agregado (19%) | C17: =C16*0.19 -> 84976.771
B18: Precio por unidad | C18: =SUM(C16:C17) -> 532222.93
B19: Punto de equilibrio | C19: =((C16-C15)*C14)/(C18-C16) -> 171.72297
B21: Punto de Equilibrio
B22: Costo de referencia | C22: =C18 -> 532222.93
B23: Unidades mínimas vendidas | C23: 270
B24: Ventas anuales mínimas | C24: =C22*C23 -> 1.4370019e+08

Sheet Grafica Punto de Equilibrio
C1: ='Costos Fijos y Punto de Equil.'!D11 -> 14592464
C2: ='Costos Fijos y Punto de Equil.'!C16 -> 447246.16 | D2: ='Costos Fijos y Punto de Equil.'!C18 -> 532222.93
C3: Costos | D3: Ventas
B4: 0 | C4: =($C$2*B4)+$C$1 -> 14592464 | D4: =$D$2*B4 -> 0
B5: 1 | C5: =($C$2*B5)+$C$1 -> 15039710 | D5: =$D$2*B5 -> 532222.93
B6: 2 | C6: =($C$2*B6)+$C$1 -> 15486956 | D6: =$D$2*B6 -> 1064445.9
B7: 3 | C7: =($C$2*B7)+$C$1 -> 15934202 | D7: =$D$2*B7 -> 1596668.8
B8: 4 | C8: =($C$2*B8)+$C$1 -> 16381448 | D8: =$D$2*B8 -> 2128891.7
B9: 5 | C9: =($C$2*B9)+$C$1 -> 16828694 | D9: =$D$2*B9 -> 2661114.7
B10: 6 | C10: =($C$2*B10)+$C$1 -> 17275941 | D10: =$D$2*B10 -> 3193337.6
B11: 7 | C11: =($C$2*B11)+$C$1 -> 17723187 | D11: =$D$2*B11 -> 3725560.5
B12: 8 | C12: =($C$2*B12)+$C$1 -> 18170433 | D12: =$D$2*B12 -> 4257783.5
B13: 9 | C13: =($C$2*B13)+$C$1 -> 18617679 | D13: =$D$2*B13 -> 4790006.4
B14: 10 | C14: =($C$2*B14)+$C$1 -> 19064925 | D14: =$D$2*B14 -> 5322229.3
B15: 11 | C15: =($C$2*B15)+$C$1 -> 19512171 | D15: =$D$2*B15 -> 5854452.3
... B304: 300 | C304: =($C$2*B304)+$C$1 -> 1.4876631e+08 | D304: =$D$2*B304 -> 1.5966688e+08

Sheet Indicadores Financieros
B2: Indicadores financieros | I2: Flujo de caja libre | L2: VAN, TIR y RBC
B3: Período | C3: Año 1 | D3: Año 2 | E3: Año 3 | F3: Año 4 | G3: Año 5 | I3: Período | J3: Flujo de efectivo | L3: Tipo | M3: Valor
B4: Liquidez - razón corriente | C4: ='Balance General'!D11/'Balance General'!D33 -> 0.90701734 | D4: ='Balance General'!E11/'Balance General'!E33 -> 1.0505454 | E4: ='Balance General'!F11/'Balance General'!F33 -> 1.2277318 | F4: ='Balance General'!G11/'Balance General'!G33 -> 1.4720525 | G4: ='Balance General'!H11/'Balance General'!H33 -> 1.9070647 | I4: Año 0 | J4: ='Flujo de Caja'!C35 -> -422040 | L4: TIO | M4: 0.15
B5: Nivel de endeudamiento total | C5: ='Balance General'!D39/'Balance General'!D25 -> 1.0338995 | D5: ='Balance General'!E39/'Balance General'!E25 -> 0.91040417 | E5: ='Balance General'!F39/'Balance General'!F25 -> 0.79089374 | F5: ='Balance General'!G39/'Balance General'!G25 -> 0.66707556 | G5: ='Balance General'!H39/'Balance General'!H25 -> 0.51900449 | I5: Año 1 | J5: ='Flujo de Caja'!D35 -> -15668784 | L5: VPN | M5: =M6+J4 -> 1.6948206e+08
B6: Rentabilidad operacional | C6: ='Estado de Resultados'!D21/'Estado de Resultados'!D8 -> -0.069290858 | D6: ='Estado de Resultados'!E21/'Estado de Resultados'!E8 -> 0.082445462 | E6: ='Estado de Resultados'!F21/'Estado de Resultados'!F8 -> 0.22086404 | F6: ='Estado de Resultados'!G21/'Estado de Resultados'!G8 -> 0.35701822 | G6: ='Estado de Resultados'!H21/'Estado de Resultados'!H8 -> 0.5128502 | I6: Año 2 | J6: ='Flujo de Caja'!E35 -> 7158551.1 | L6: VAN | M6: =NPV(M4,J5:J9) -> 1.699041e+08
B7: Rentabilidad neta | C7: ='Estado de Resultados'!D32/'Estado de Resultados'!D8 -> -0.11194548 | D7: ='Estado de Resultados'!E32/'Estado de Resultados'!E8 -> 0.040622873 | E7: ='Estado de Resultados'!F32/'Estado de Resultados'!F8 -> 0.17966963 | F7: ='Estado de Resultados'!G32/'Estado de Resultados'!G8 -> 0.31628379 | G7: ='Estado de Resultados'!H32/'Estado de Resultados'!H8 -> 0.47243698 | I7: Año 3 | J7: ='Flujo de Caja'!F35 -> 40748132 | L7: TIR | M7: =IRR(J4:J9) -> 1.695844
B8: Rentabilidad de patriominio | C8: ='Estado de Resultados'!D32/'Balance General'!#REF! -> #REF! | D8: ='Estado de Resultados'!E32/'Balance General'!#REF! -> #REF! | E8: ='Estado de Resultados'!F32/'Balance General'!#REF! -> #REF! | F8: ='Estado de Resultados'!G32/'Balance General'!#REF! -> #REF! | G8: ='Estado de Resultados'!H32/'Balance General'!#REF! -> #REF! | I8: Año 4 | J8: ='Flujo de Caja'!G35 -> 95044249 | L8: RBC | M8: =-NPV(M4,J5:J9)/J4 -> 402.57819
I9: Año 5 | J9: ='Flujo de Caja'!H35 -> 1.9506508e+08
