Workbook

Sheet Balance General
A1: BALANCE GENERAL PROYECTADO
A2: EDUCAFIN S.A.S.
A4: TRIMESTRE | C4: TRIMESTRE 1 | D4: TRIMESTRE 2 | E4: TRIMESTRE 3 | F4: TRIMESTRE 4 | G4: TRIMESTRE 5 | H4: TRIMESTRE 6 | I4: TRIMESTRE 7 | J4: TRIMESTRE 8 | K4: TRIMESTRE 9 | L4: TRIMESTRE 10 | M4: TRIMESTRE 11 | N4: TRIMESTRE 12 | O4: TRIMESTRE 13 | P4: TRIMESTRE 14 | Q4: TRIMESTRE 15 | R4: TRIMESTRE 16 | S4: TRIMESTRE 17 | T4: TRIMESTRE 18 | U4: TRIMESTRE 19 | V4: TRIMESTRE 20
A5: ACTIVOS
A6: ACTIVOS CORRIENTES
B7: Efectivo y Equivalente de Efectivo | C7: ='Proyección de Ventas e Incremen'!I7 -> 0 | D7: ='Proyección de Ventas e Incremen'!J7 -> 0 | E7: ='Proyección de Ventas e Incremen'!K7 -> 0 | F7: ='Proyección de Ventas e Incremen'!L7 -> 54691200 | G7: ='Proyección de Ventas e Incremen'!M7 -> 87204600 | H7: ='Proyección de Ventas e Incremen'!N7 -> 92114219 | I7: ='Proyección de Ventas e Incremen'!O7 -> 96839678 | J7: ='Proyección de Ventas e Incremen'!P7 -> 1.0200123e+08 | ... V7: ='Proyección de Ventas e Incremen'!AB7 -> 2.8227005e+08
B8: Cuentas por Cobrar al Personal y Accionistas | C8: ='Proyección de Ventas e Incremen'!I8 -> 0 | D8: 0 | E8: 0 | F8: 0 | G8: 0 | H8: 0 | I8: 0 | J8: 0 | K8: 0 | L8: 0 | M8: 0 | N8: 0 | O8: 0 | P8: 0 | Q8: 0 | R8: 0 | S8: 0 | T8: 0 | U8: 0 | V8: 0
B9: Gastos Pagados por Anticipado | C9: 0 | D9: 0 | E9: 0 | F9: 0 | G9: 0 | H9: 0 | I9: 0 | J9: 0 | K9: 0 | L9: 0 | M9: 0 | N9: 0 | O9: 0 | P9: 0 | Q9: 0 | R9: 0 | S9: 0 | T9: 0 | U9: 0 | V9: 0
B10: Otros Activos | C10: 0 | D10: 0 | E10: 0 | F10: 0 | G10: 0 | H10: 0 | I10: 0 | J10: 0 | K10: 0 | L10: 0 | M10: 0 | N10: 0 | O10: 0 | P10: 0 | Q10: 0 | R10: 0 | S10: 0 | T10: 0 | U10: 0 | V10: 0
B11: Total Activos Corrientes | C11: =SUM(C7:C10) -> 0 | D11: =SUM(D7:D10) -> 0 | E11: =SUM(E7:E10) -> 0 | F11: =SUM(F7:F10) -> 54691200 | G11: =SUM(G7:G10) -> 87204600 | H11: =SUM(H7:H10) -> 92114219 | I11: =SUM(I7:I10) -> 96839678 | J11: =SUM(J7:J10) -> 1.0200123e+08 | ... V11: =SUM(V7:V10) -> 2.8227005e+08
A13: ACTIVOS NO CORRIENTES
B14: Inmuebles y Equipos (neto) | C14: ='Inversión Inicial'!$D$17-C16 -> 26310000 | D14: ='Inversión Inicial'!$D$17-D16 -> 25320000 | E14: ='Inversión Inicial'!$D$17-E16 -> 24330000 | F14: ='Inversión Inicial'!$D$17-F16 -> 23340000 | G14: ='Inversión Inicial'!$D$17-G16 -> 22350000 | H14: ='Inversión Inicial'!$D$17-H16 -> 21360000 | I14: ='Inversión Inicial'!$D$17-I16 -> 20370000 | J14: ='Inversión Inicial'!$D$17-J16 -> 19380000 | ... V14: ='Inversión Inicial'!$D$17-V16 -> 7500000
B15: Intangibles (neto) | C15: ='Costos de Operación Gravables'!B41 -> 1451000 | D15: =C15*101% -> 1465510 | E15: =D15*101% -> 1480165.1 | F15: =E15*101% -> 1494966.8 | G15: =F15*101% -> 1509916.4 | H15: =G15*101% -> 1525015.6 | I15: =H15*101% -> 1540265.7 | J15: =I15*101% -> 1555668.4 | K15: =J15*101% -> 1571225.1 | ... V15: =U15*101% -> 1752966.1
B16: Depreciación de Equipos | C16: ='Amortización y Depreciación'!$G$35*1/4 -> 990000 | D16: =C16+'Amortización y Depreciación'!$G$35*1/4 -> 1980000 | E16: =D16+'Amortización y Depreciación'!$G$35*1/4 -> 2970000 | F16: =E16+'Amortización y Depreciación'!$G$35*1/4 -> 3960000 | G16: =F16+'Amortización y Depreciación'!$G$35*1/4 -> 4950000 | H16: =G16+'Amortización y Depreciación'!$G$35*1/4 -> 5940000 | I16: =H16+'Amortización y Depreciación'!$G$35*1/4 -> 6930000 | J16: =I16+'Amortización y Depreciación'!$G$35*1/4 -> 7920000 | K16: =J16+'Amortización y Depreciación'!$G$35*1/4 -> 8910000 | ... V16: =U16+'Amortización y Depreciación'!$G$35*1/4 -> 19800000
B17: Total Activos No Corrientes | C17: =SUM(C14:C15) -> 27761000 | D17: =SUM(D12:D15) -> 26785510 | E17: =SUM(E12:E15) -> 25810165 | F17: =SUM(F12:F15) -> 24834967 | G17: =SUM(G12:G15) -> 23859916 | H17: =SUM(H12:H15) -> 22885016 | I17: =SUM(I12:I15) -> 21910266 | J17: =SUM(J12:J15) -> 20935668 | K17: =SUM(K12:K15) -> 19961225 | ... V17: =SUM(V12:V15) -> 9252966.1
A19: ACTIVOS DIFERIDOS
B20: Propiedad Intelectual | C20: 0 | D20: 0 | E20: 0 | F20: 0 | G20: 0 | H20: 0 | I20: 0 | J20: 0 | K20: 0 | L20: 0 | M20: 0 | N20: 0 | O20: 0 | P20: 0 | Q20: 0 | R20: 0 | S20: 0 | T20: 0 | U20: 0 | V20: 0
B21: Gastos Legales | C21: 0 | D21: 0 | E21: 0 | F21: 0 | G21: 0 | H21: 0 | I21: 0 | J21: 0 | K21: 0 | L21: 0 | M21: 0 | N21: 0 | O21: 0 | P21: 0 | Q21: 0 | R21: 0 | S21: 0 | T21: 0 | U21: 0 | V21: 0
B22: Otros Seguros | C22: 0 | D22: 0 | E22: 0 | F22: 0 | G22: 0 | H22: 0 | I22: 0 | J22: 0 | K22: 0 | L22: 0 | M22: 0 | N22: 0 | O22: 0 | P22: 0 | Q22: 0 | R22: 0 | S22: 0 | T22: 0 | U22: 0 | V22: 0
B23: Total Activos Diferidos | C23: =SUM(C20:C22) -> 0 | D23: =SUM(D20:D22) -> 0 | E23: =SUM(E20:E22) -> 0 | F23: =SUM(F20:F22) -> 0 | G23: =SUM(G20:G22) -> 0 | H23: =SUM(H20:H22) -> 0 | I23: =SUM(I20:I22) -> 0 | J23: =SUM(J20:J22) -> 0 | ... V23: =SUM(V20:V22) -> 0
A25: TOTAL ACTIVO | C25: =SUM(C11,C17,C23) -> 27761000 | D25: =SUM(D11,D17,D23) -> 26785510 | E25: =SUM(E11,E17,E23) -> 25810165 | F25: =SUM(F11,F17,F23) -> 79526167 | G25: =SUM(G11,G17,G23) -> 1.1106452e+08 | H25: =SUM(H11,H17,H23) -> 1.1499923e+08 | I25: =SUM(I11,I17,I23) -> 1.1874994e+08 | J25: =SUM(J11,J17,J23) -> 1.229369e+08 | ... V25: =SUM(V11,V17,V23) -> 2.9152302e+08
A26: PASIVOS
A27: PASIVOS CORRIENTES
B28: Prestaciones y Parafiscales | C28: =SUM('Costos de Operación Gravables'!I10,'Costos de Operación Gravables'!I13) -> 37290000 | D28: =SUM('Costos de Operación Gravables'!J10,'Costos de Operación Gravables'!J13) -> 37290000 | E28: =SUM('Costos de Operación Gravables'!K10,'Costos de Operación Gravables'!K13) -> 37290000 | F28: =SUM('Costos de Operación Gravables'!L10,'Costos de Operación Gravables'!L13) -> 23730000 | G28: =SUM('Costos de Operación Gravables'!M10,'Costos de Operación Gravables'!M13) -> 10170000 | H28: =SUM('Costos de Operación Gravables'!N10,'Costos de Operación Gravables'!N13) -> 10373400 | I28: =SUM('Costos de Operación Gravables'!O10,'Costos de Operación Gravables'!O13) -> 10580868 | J28: =SUM('Costos de Operación Gravables'!P10,'Costos de Operación Gravables'!P13) -> 10792485 | ... V28: =SUM('Costos de Operación Gravables'!AB10,'Costos de Operación Gravables'!AB13) -> 13687481
B29: Infraestructura | C29: ='Costos de Operación Gravables'!I16 -> 0 | D29: ='Costos de Operación Gravables'!J16 -> 0 | E29: ='Costos de Operación Gravables'!K16 -> 0 | F29: ='Costos de Operación Gravables'!L16 -> 11160000 | G29: ='Costos de Operación Gravables'!M16 -> 11829600 | H29: ='Costos de Operación Gravables'!N16 -> 12539376 | I29: ='Costos de Operación Gravables'!O16 -> 13291739 | J29: ='Costos de Operación Gravables'!P16 -> 14089243 | ... V29: ='Costos de Operación Gravables'!AB16 -> 28350325
B30: Amortización | C30: ='Amortización y Depreciación'!$B$8 -> 7128803 | D30: ='Amortización y Depreciación'!$B$8 -> 7128803 | E30: ='Amortización y Depreciación'!$B$8 -> 7128803 | F30: ='Amortización y Depreciación'!$B$8 -> 7128803 | G30: ='Amortización y Depreciación'!$B$8 -> 7128803 | H30: ='Amortización y Depreciación'!$B$8 -> 7128803 | I30: ='Amortización y Depreciación'!$B$8 -> 7128803 | J30: ='Amortización y Depreciación'!$B$8 -> 7128803 | ... R30: ='Amortización y Depreciación'!$B$8 -> 7128803 | S30: 0 | T30: 0 | U30: 0 | V30: 0
B31: Nómina | C31: =SUM('Costos de Operación Gravables'!I4,'Costos de Operación Gravables'!I7) -> 113400000 | D31: =SUM('Costos de Operación Gravables'!J4,'Costos de Operación Gravables'!J7) -> 113400000 | E31: =SUM('Costos de Operación Gravables'!K4,'Costos de Operación Gravables'!K7) -> 113400000 | F31: =SUM('Costos de Operación Gravables'!L4,'Costos de Operación Gravables'!L7) -> 73650000 | G31: =SUM('Costos de Operación Gravables'!M4,'Costos de Operación Gravables'!M7) -> 33900000 | H31: =SUM('Costos de Operación Gravables'!N4,'Costos de Operación Gravables'!N7) -> 34578000 | I31: =SUM('Costos de Operación Gravables'!O4,'Costos de Operación Gravables'!O7) -> 35269560 | J31: =SUM('Costos de Operación Gravables'!P4,'Costos de Operación Gravables'!P7) -> 35974951 | ... V31: =SUM('Costos de Operación Gravables'!AB4,'Costos de Operación Gravables'!AB7) -> 45624937
B32: Tributos (Impuestos) por pagar | C32: =C25*0.04 -> 1110440 | D32: =D25*0.04 -> 1071420.4 | E32: =E25*0.04 -> 1032406.6 | F32: =F25*0.04 -> 3181046.7 | G32: =G25*0.04 -> 4442580.7 | H32: =H25*0.04 -> 4599969.4 | I32: =I25*0.04 -> 4749997.8 | J32: =J25*0.04 -> 4917476.1 | ... V32: =V25*0.04 -> 11660921
B33: Total Pasivos Corrientes | C33: =SUM(C28:C32) -> 158929243 | D33: =SUM(D28:D32) -> 1.5889022e+08 | E33: =SUM(E28:E32) -> 1.5885121e+08 | F33: =SUM(F28:F32) -> 1.1884985e+08 | G33: =SUM(G28:G32) -> 67470984 | H33: =SUM(H28:H32) -> 69219548 | I33: =SUM(I28:I32) -> 71020967 | J33: =SUM(J28:J32) -> 72902959 | ... V33: =SUM(V28:V32) -> 99323663
A35: PASIVOS NO CORRIENTES
B36: Inversión Inicial | C36: ='Inversión Inicial'!B9 -> 126300000 | D36: 0 | E36: 0 | F36: 0 | G36: 0 | H36: 0 | I36: 0 | J36: 0 | K36: 0 | L36: 0 | M36: 0 | N36: 0 | O36: 0 | P36: 0 | Q36: 0 | R36: 0 | S36: 0 | T36: 0 | U36: 0 | V36: 0
B37: Total Pasivos No Corrientes | C37: =SUM(C36) -> 126300000 | D37: =SUM(D36) -> 0 | E37: =SUM(E36) -> 0 | F37: =SUM(F36) -> 0 | G37: =SUM(G36) -> 0 | H37: =SUM(H36) -> 0 | I37: =SUM(I36) -> 0 | J37: =SUM(J36) -> 0 | ... V37: =SUM(V36) -> 0
A39: TOTAL PASIVOS | C39: =C33+C37 -> 285229243 | D39: =D33+D37 -> 1.5889022e+08 | E39: =E33+E37 -> 1.5885121e+08 | F39: =F33+F37 -> 1.1884985e+08 | G39: =G33+G37 -> 67470984 | H39: =H33+H37 -> 69219548 | I39: =I33+I37 -> 71020967 | J39: =J33+J37 -> 72902959 | ... V39: =V33+V37 -> 99323663
A41: CAPITAL
B42: Capital Social | C42: ='Inversión Inicial'!B22 -> 44205000 | D42: 0 | E42: 0 | F42: 0 | G42: 0 | H42: 0 | I42: 0 | J42: 0 | K42: 0 | L42: 0 | M42: 0 | N42: 0 | O42: 0 | P42: 0 | Q42: 0 | R42: 0 | S42: 0 | T42: 0 | U42: 0 | V42: 0
A44: TOTAL CAPITAL | C44: =C42 -> 44205000 | D44: =D42 -> 0 | E44: =E42 -> 0 | F44: =F42 -> 0 | G44: =G42 -> 0 | H44: =H42 -> 0 | I44: =I42 -> 0 | J44: =J42 -> 0 | ... V44: =V42 -> 0
A46: FINANCIAMIENTO TOTAL | C46: =C25-(C39+C44) -> -301673243 | D46: =D25-(D39+D44) -> -1.3210471e+08 | E46: =E25-(E39+E44) -> -1.3304104e+08 | F46: =F25-(F39+F44) -> -39323683 | G46: =G25-(G39+G44) -> 43593533 | H46: =H25-(H39+H44) -> 45779686 | I46: =I25-(I39+I44) -> 47728977 | J46: =J25-(J39+J44) -> 50033943 | ... V46: =V25-(V39+V44) -> 1.9219936e+08

Sheet Estado de Resultados
A1: ESTADO DE RESULTADOS
A2: EDUCAFIN S.A.S.
A4: TRIMESTRE | C4: TRIMESTRE 1 | D4: TRIMESTRE 2 | E4: TRIMESTRE 3 | F4: TRIMESTRE 4 | G4: TRIMESTRE 5 | H4: TRIMESTRE 6 | I4: TRIMESTRE 7 | J4: TRIMESTRE 8 | K4: TRIMESTRE 9 | L4: TRIMESTRE 10 | M4: TRIMESTRE 11 | N4: TRIMESTRE 12 | O4: TRIMESTRE 13 | P4: TRIMESTRE 14 | Q4: TRIMESTRE 15 | R4: TRIMESTRE 16 | S4: TRIMESTRE 17 | T4: TRIMESTRE 18 | U4: TRIMESTRE 19 | V4: TRIMESTRE 20
A5: EFECTIVO
B6: Efectivo y equivalente de efectivo | C6: ='Proyección de Ventas e Incremen'!I7 -> 0 | D6: ='Proyección de Ventas e Incremen'!J7 -> 0 | E6: ='Proyección de Ventas e Incremen'!K7 -> 0 | F6: ='Proyección de Ventas e Incremen'!L7 -> 54691200 | G6: ='Proyección de Ventas e Incremen'!M7 -> 87204600 | H6: ='Proyección de Ventas e Incremen'!N7 -> 92114219 | I6: ='Proyección de Ventas e Incremen'!O7 -> 96839678 | J6: ='Proyección de Ventas e Incremen'!P7 -> 1.0200123e+08 | ... V6: ='Proyección de Ventas e Incremen'!AB7 -> 2.8227005e+08
B7: Devoluciones | C7: ='Proyección de Ventas e Incremen'!I8 -> 0 | D7: 0 | E7: 0 | F7: 0 | G7: 0 | H7: 0 | I7: 0 | J7: 0 | K7: 0 | L7: 0 | M7: 0 | N7: 0 | O7: 0 | P7: 0 | Q7: 0 | R7: 0 | S7: 0 | T7: 0 | U7: 0 | V7: 0
B8: Total Ventas Netas | C8: =SUM(C6:C7) -> 0 | D8: =SUM(D6:D7) -> 0 | E8: =SUM(E6:E7) -> 0 | F8: =SUM(F6:F7) -> 54691200 | G8: =SUM(G6:G7) -> 87204600 | H8: =SUM(H6:H7) -> 92114219 | I8: =SUM(I6:I7) -> 96839678 | J8: =SUM(J6:J7) -> 1.0200123e+08 | ... V8: =SUM(V6:V7) -> 2.8227005e+08
A10: UTILIDAD
B11: Inversión Inicial | C11: ='Inversión Inicial'!B9 -> 126300000 | D11: 0 | E11: 0 | F11: 0 | G11: 0 | H11: 0 | I11: 0 | J11: 0 | K11: 0 | L11: 0 | M11: 0 | N11: 0 | O11: 0 | P11: 0 | Q11: 0 | R11: 0 | S11: 0 | T11: 0 | U11: 0 | V11: 0
B12: Mano de Obra Fija | C12: ='Balance General'!C31+'Balance General'!C28 -> 150690000 | D12: ='Balance General'!D31+'Balance General'!D28 -> 150690000 | E12: ='Balance General'!E31+'Balance General'!E28 -> 150690000 | F12: ='Balance General'!F31+'Balance General'!F28 -> 97380000 | G12: ='Balance General'!G31+'Balance General'!G28 -> 44070000 | H12: ='Balance General'!H31+'Balance General'!H28 -> 44951400 | I12: ='Balance General'!I31+'Balance General'!I28 -> 45850428 | J12: ='Balance General'!J31+'Balance General'!J28 -> 46767437 | ... V12: ='Balance General'!V31+'Balance General'!V28 -> 59312418
B13: Diferidos | C13: ='Balance General'!C23 -> 0 | D13: ='Balance General'!D23 -> 0 | E13: ='Balance General'!E23 -> 0 | F13: ='Balance General'!F23 -> 0 | G13: ='Balance General'!G23 -> 0 | H13: ='Balance General'!H23 -> 0 | I13: ='Balance General'!I23 -> 0 | J13: ='Balance General'!J23 -> 0 | ... V13: ='Balance General'!V23 -> 0
B14: Depreciación | C14: ='Amortización y Depreciación'!$G$35*1/4 -> 990000 | D14: ='Amortización y Depreciación'!$G$35*1/4 -> 990000 | E14: ='Amortización y Depreciación'!$G$35*1/4 -> 990000 | F14: ='Amortización y Depreciación'!$G$35*1/4 -> 990000 | G14: ='Amortización y Depreciación'!$G$35*1/4 -> 990000 | H14: ='Amortización y Depreciación'!$G$35*1/4 -> 990000 | I14: ='Amortización y Depreciación'!$G$35*1/4 -> 990000 | J14: ='Amortización y Depreciación'!$G$35*1/4 -> 990000 | ... V14: ='Amortización y Depreciación'!$G$35*1/4 -> 990000
B15: Total Costo de Ventas | C15: =SUM(C11:C14) -> 277980000 | D15: =SUM(D11:D14) -> 151680000 | E15: =SUM(E11:E14) -> 151680000 | F15: =SUM(F11:F14) -> 98370000 | G15: =SUM(G11:G14) -> 45060000 | H15: =SUM(H11:H14) -> 45941400 | I15: =SUM(I11:I14) -> 46840428 | J15: =SUM(J11:J14) -> 47757437 | ... V15: =SUM(V11:V14) -> 60302418
B16: Utilidad Bruta (Ventas - Costo de Ventas) | C16: =C8-C15 -> -277980000 | D16: =D8-D15 -> -151680000 | E16: =E8-E15 -> -151680000 | F16: =F8-F15 -> -43678800 | G16: =G8-G15 -> 42144600 | H16: =H8-H15 -> 46172819 | I16: =I8-I15 -> 49999250 | J16: =J8-J15 -> 54243797 | ... V16: =V8-V15 -> 2.2196764e+08
A18: UTILIDAD OPERACIONAL
B19: Gastos Administrativos | C19: ='Balance General'!C30+'Balance General'!C29+'Balance General'!$C$15 -> 8579803 | D19: ='Balance General'!D30+'Balance General'!D29+'Balance General'!$C$15 -> 8579803 | E19: ='Balance General'!E30+'Balance General'!E29+'Balance General'!$C$15 -> 8579803 | F19: ='Balance General'!F30+'Balance General'!F29+'Balance General'!$C$15 -> 19739803 | G19: ='Balance General'!G30+'Balance General'!G29+'Balance General'!$C$15 -> 20409403 | H19: ='Balance General'!H30+'Balance General'!H29+'Balance General'!$C$15 -> 21119179 | I19: ='Balance General'!I30+'Balance General'!I29+'Balance General'!$C$15 -> 21871542 | J19: ='Balance General'!J30+'Balance General'!J29+'Balance General'!$C$15 -> 22669046 | ... V19: ='Balance General'!V30+'Balance General'!V29+'Balance General'!$C$15 -> 29801325
B20: Gastos de Ventas | C20: 0 | D20: 0 | E20: 0 | F20: 0 | G20: 0 | H20: 0 | I20: 0 | J20: 0 | K20: 0 | L20: 0 | M20: 0 | N20: 0 | O20: 0 | P20: 0 | Q20: 0 | R20: 0 | S20: 0 | T20: 0 | U20: 0 | V20: 0
B21: Total Utilidad Operacional | C21: =C16-SUM(C19:C20) -> -286559803 | D21: =D16-SUM(D19:D20) -> -160259803 | E21: =E16-SUM(E19:E20) -> -160259803 | F21: =F16-SUM(F19:F20) -> -63418603 | G21: =G16-SUM(G19:G20) -> 21735197 | H21: =H16-SUM(H19:H20) -> 25053640 | I21: =I16-SUM(I19:I20) -> 28127709 | J21: =J16-SUM(J19:J20) -> 31574751 | ... V21: =V16-SUM(V19:V20) -> 1.9216631e+08
A23: OTRAS UTILIDADES
B24: Otros Egresos | C24: =0 -> 0 | D24: =0 -> 0 | E24: =0 -> 0 | F24: =0 -> 0 | G24: =0 -> 0 | H24: =0 -> 0 | I24: =0 -> 0 | J24: =0 -> 0 | ... V24: =0 -> 0
B25: Gastos Financieros | C25: =0 -> 0 | D25: =0 -> 0 | E25: =0 -> 0 | F25: =0 -> 0 | G25: =0 -> 0 | H25: =0 -> 0 | I25: =0 -> 0 | J25: =0 -> 0 | ... V25: =0 -> 0
B26: Total Otras Utilidades | C26: =C21-SUM(C24:C25) -> -286559803 | D26: =D21-SUM(D24:D25) -> -160259803 | E26: =E21-SUM(E24:E25) -> -160259803 | F26: =F21-SUM(F24:F25) -> -63418603 | G26: =G21-SUM(G24:G25) -> 21735197 | H26: =H21-SUM(H24:H25) -> 25053640 | I26: =I21-SUM(I24:I25) -> 28127709 | J26: =J21-SUM(J24:J25) -> 31574751 | ... V26: =V21-SUM(V24:V25) -> 1.9216631e+08
A28: IMPUESTOS
B29: Impuestos | C29: ='Balance General'!C32 -> 1110440 | D29: ='Balance General'!D32 -> 1071420.4 | E29: ='Balance General'!E32 -> 1032406.6 | F29: ='Balance General'!F32 -> 3181046.7 | G29: ='Balance General'!G32 -> 4442580.7 | H29: ='Balance General'!H32 -> 4599969.4 | I29: ='Balance General'!I32 -> 4749997.8 | J29: ='Balance General'!J32 -> 4917476.1 | ... V29: ='Balance General'!V32 -> 11660921
B30: Total Impuestos | C30: =SUM(C29) -> 1110440 | D30: =SUM(D29) -> 1071420.4 | E30: =SUM(E29) -> 1032406.6 | F30: =SUM(F29) -> 3181046.7 | G30: =SUM(G29) -> 4442580.7 | H30: =SUM(H29) -> 4599969.4 | I30: =SUM(I29) -> 4749997.8 | J30: =SUM(J29) -> 4917476.1 | ... V30: =SUM(V29) -> 11660921
A32: UTILIDAD NETA | C32: =C26-C30 -> -287670243 | D32: =D26-D30 -> -1.6133122e+08 | E32: =E26-E30 -> -1.6129221e+08 | F32: =F26-F30 -> -66599650 | G32: =G26-G30 -> 17292616 | H32: =H26-H30 -> 20453671 | I32: =I26-I30 -> 23377711 | J32: =J26-J30 -> 26657275 | ... V32: =V26-V30 -> 1.8050539e+08

Sheet Flujo de Caja
A1: FLUJO DE CAJA
A2: EDUCAFIN S.A.S.
A4: TRIMESTRE | C4: TRIMESTRE 1 | D4: TRIMESTRE 2 | E4: TRIMESTRE 3 | F4: TRIMESTRE 4 | G4: TRIMESTRE 5 | H4: TRIMESTRE 6 | I4: TRIMESTRE 7 | J4: TRIMESTRE 8 | K4: TRIMESTRE 9 | L4: TRIMESTRE 10 | M4: TRIMESTRE 11 | N4: TRIMESTRE 12 | O4: TRIMESTRE 13 | P4: TRIMESTRE 14 | Q4: TRIMESTRE 15 | R4: TRIMESTRE 16 | S4: TRIMESTRE 17 | T4: TRIMESTRE 18 | U4: TRIMESTRE 19 | V4: TRIMESTRE 20
A5: INVERSIÓN INICIAL
B6: Equipos de Cómputo | C6: ='Inversión Inicial'!B5 -> 27300000 | D6: 0 | E6: 0 | F6: 0 | G6: 0 | H6: 0 | I6: 0 | J6: 0 | K6: 0 | L6: 0 | M6: 0 | N6: 0 | O6: 0 | P6: 0 | Q6: 0 | R6: 0 | S6: 0 | T6: 0 | U6: 0 | V6: 0
B7: Equipos de Oficina | C7: =0 -> 0 | D7: =0 -> 0 | E7: =0 -> 0 | F7: =0 -> 0 | G7: =0 -> 0 | H7: =0 -> 0 | I7: =0 -> 0 | J7: =0 -> 0 | ... V7: =0 -> 0
B8: Capital de Trabajo | C8: =0 -> 0 | D8: =0 -> 0 | E8: =0 -> 0 | F8: =0 -> 0 | G8: =0 -> 0 | H8: =0 -> 0 | I8: =0 -> 0 | J8: =0 -> 0 | ... V8: =0 -> 0
B9: Preoperativos | C9: =SUM('Inversión Inicial'!B3,'Inversión Inicial'!B4,'Inversión Inicial'!B6,'Inversión Inicial'!B7) -> 90000000 | D9: =0 -> 0 | E9: =0 -> 0 | F9: =0 -> 0 | G9: =0 -> 0 | H9: =0 -> 0 | I9: =0 -> 0 | J9: =0 -> 0 | K9: =0 -> 0 | ... V9: =0 -> 0
B10: Costos de Infraestructura Iniciales | C10: ='Inversión Inicial'!B8 -> 9000000 | D10: =0 -> 0 | E10: =0 -> 0 | F10: =0 -> 0 | G10: =0 -> 0 | H10: =0 -> 0 | I10: =0 -> 0 | J10: =0 -> 0 | K10: =0 -> 0 | ... V10: =0 -> 0
B11: Total de Inversión Inicial | C11: =SUM(C6:C10) -> 126300000 | D11: =SUM(D6:D10) -> 0 | E11: =SUM(E6:E10) -> 0 | F11: =SUM(F6:F10) -> 0 | G11: =SUM(G6:G10) -> 0 | H11: =SUM(H6:H10) -> 0 | I11: =SUM(I6:I10) -> 0 | J11: =SUM(J6:J10) -> 0 | ... V11: =SUM(V6:V10) -> 0
A13: ENTRADAS E INGRESOS
B14: Aportaciones de Socios | C14: ='Balance General'!C42 -> 44205000 | D14: =0 -> 0 | E14: =0 -> 0 | F14: =0 -> 0 | G14: =0 -> 0 | H14: =0 -> 0 | I14: =0 -> 0 | J14: =0 -> 0 | K14: =0 -> 0 | ... V14: =0 -> 0
B15: Aportes de Financiamiento | C15: ='Inversión Inicial'!B21 -> 82095000 | D15: =0 -> 0 | E15: =0 -> 0 | F15: =0 -> 0 | G15: =0 -> 0 | H15: =0 -> 0 | I15: =0 -> 0 | J15: =0 -> 0 | K15: =0 -> 0 | ... V15: =0 -> 0
B16: Ingresos | C16: ='Proyección de Ventas e Incremen'!I7 -> 0 | D16: ='Proyección de Ventas e Incremen'!J7 -> 0 | E16: ='Proyección de Ventas e Incremen'!K7 -> 0 | F16: ='Proyección de Ventas e Incremen'!L7 -> 54691200 | G16: ='Proyección de Ventas e Incremen'!M7 -> 87204600 | H16: ='Proyección de Ventas e Incremen'!N7 -> 92114219 | I16: ='Proyección de Ventas e Incremen'!O7 -> 96839678 | J16: ='Proyección de Ventas e Incremen'!P7 -> 1.0200123e+08 | ... V16: ='Proyección de Ventas e Incremen'!AB7 -> 2.8227005e+08
B17: Total de Entradas | C17: =SUM(C14:C16) -> 126300000 | D17: =SUM(D14:D16) -> 0 | E17: =SUM(E14:E16) -> 0 | F17: =SUM(F14:F16) -> 54691200 | G17: =SUM(G14:G16) -> 87204600 | H17: =SUM(H14:H16) -> 92114219 | I17: =SUM(I14:I16) -> 96839678 | J17: =SUM(J14:J16) -> 1.0200123e+08 | ... V17: =SUM(V14:V16) -> 2.8227005e+08
A19: EGRESOS
B20: Mantenimiento de Infraestructura | C20: ='Costos de Operación Gravables'!I16 -> 0 | D20: ='Costos de Operación Gravables'!J16 -> 0 | E20: ='Costos de Operación Gravables'!K16 -> 0 | F20: ='Costos de Operación Gravables'!L16 -> 11160000 | G20: ='Costos de Operación Gravables'!M16 -> 11829600 | H20: ='Costos de Operación Gravables'!N16 -> 12539376 | I20: ='Costos de Operación Gravables'!O16 -> 13291739 | J20: ='Costos de Operación Gravables'!P16 -> 14089243 | ... V20: ='Costos de Operación Gravables'!AB16 -> 28350325
B21: Amortización | C21: ='Amortización y Depreciación'!$G$4-C22 -> 3713651 | D21: ='Amortización y Depreciación'!$G$4-D22 -> 3868138.9 | E21: ='Amortización y Depreciación'!$G$4-E22 -> 4029053.5 | F21: ='Amortización y Depreciación'!$G$4-F22 -> 4196662.1 | G21: ='Amortización y Depreciación'!$G$4-G22 -> 4371243.2 | H21: ='Amortización y Depreciación'!$G$4-H22 -> 4553086.9 | I21: ='Amortización y Depreciación'!$G$4-I22 -> 4742495.4 | J21: ='Amortización y Depreciación'!$G$4-J22 -> 4939783.2 | ... R21: ='Amortización y Depreciación'!$G$4-R22 -> 6844089.1 | S21: 0 | T21: 0 | U21: 0 | V21: 0
B22: Intereses | C22: ='Amortización y Depreciación'!$F4 -> 3415152 | D22: ='Amortización y Depreciación'!$F5 -> 3260664.1 | E22: ='Amortización y Depreciación'!$F6 -> 3099749.5 | F22: ='Amortización y Depreciación'!$F7 -> 2932140.9 | G22: ='Amortización y Depreciación'!$F8 -> 2757559.8 | H22: ='Amortización y Depreciación'!$F9 -> 2575716.1 | I22: ='Amortización y Depreciación'!$F10 -> 2386307.6 | J22: ='Amortización y Depreciación'!$F11 -> 2189019.8 | K22: ='Amortización y Depreciación'!$F12 -> 1983524.9 | L22: ='Amortización y Depreciación'!$F13 -> 1769481.3 | M22: ='Amortización y Depreciación'!$F14 -> 1546533.5 | N22: ='Amortización y Depreciación'!$F15 -> 1314311.1 | O22: ='Amortización y Depreciación'!$F16 -> 1072428.2 | P22: ='Amortización y Depreciación'!$F17 -> 820483.03 | Q22: ='Amortización y Depreciación'!$F18 -> 558056.92 | R22: ='Amortización y Depreciación'!$F19 -> 284713.89 | S22: ='Amortización y Depreciación'!$F20 -> 0 | T22: =0 -> 0 | U22: =0 -> 0 | V22: =0 -> 0
B23: Nómina y Prestaciones | C23: =SUM('Costos de Operación Gravables'!I4,'Costos de Operación Gravables'!I7,'Costos de Operación Gravables'!I10,'Costos de Operación Gravables'!I13) -> 150690000 | D23: =SUM('Costos de Operación Gravables'!J4,'Costos de Operación Gravables'!J7,'Costos de Operación Gravables'!J10,'Costos de Operación Gravables'!J13) -> 150690000 | E23: =SUM('Costos de Operación Gravables'!K4,'Costos de Operación Gravables'!K7,'Costos de Operación Gravables'!K10,'Costos de Operación Gravables'!K13) -> 150690000 | F23: =SUM('Costos de Operación Gravables'!L4,'Costos de Operación Gravables'!L7,'Costos de Operación Gravables'!L10,'Costos de Operación Gravables'!L13) -> 97380000 | G23: =SUM('Costos de Operación Gravables'!M4,'Costos de Operación Gravables'!M7,'Costos de Operación Gravables'!M10,'Costos de Operación Gravables'!M13) -> 44070000 | H23: =SUM('Costos de Operación Gravables'!N4,'Costos de Operación Gravables'!N7,'Costos de Operación Gravables'!N10,'Costos de Operación Gravables'!N13) -> 44951400 | I23: =SUM('Costos de Operación Gravables'!O4,'Costos de Operación Gravables'!O7,'Costos de Operación Gravables'!O10,'Costos de Operación Gravables'!O13) -> 45850428 | J23: =SUM('Costos de Operación Gravables'!P4,'Costos de Operación Gravables'!P7,'Costos de Operación Gravables'!P10,'Costos de Operación Gravables'!P13) -> 46767437 | ... V23: =SUM('Costos de Operación Gravables'!AB4,'Costos de Operación Gravables'!AB7,'Costos de Operación Gravables'!AB10,'Costos de Operación Gravables'!AB13) -> 59312418
B24: Remuneraciones y Participaciones por Pagar | C24: =0 -> 0 | D24: =0 -> 0 | E24: =0 -> 0 | F24: =0 -> 0 | G24: =0 -> 0 | H24: =0 -> 0 | I24: =0 -> 0 | J24: =0 -> 0 | ... V24: =0 -> 0
B25: Total Utilidad Operacional | C25: =SUM(C20:C24) -> 157818803 | D25: =SUM(D20:D24) -> 157818803 | E25: =SUM(E20:E24) -> 157818803 | F25: =SUM(F20:F24) -> 115668803 | G25: =SUM(G20:G24) -> 63028403 | H25: =SUM(H20:H24) -> 64619579 | I25: =SUM(I20:I24) -> 66270970 | J25: =SUM(J20:J24) -> 67985482 | ... V25: =SUM(V20:V24) -> 87662742
A27: DEPRECIACIÓN
B28: Equipos de Cómputo | C28: ='Amortización y Depreciación'!$G$35 -> 3960000 | D28: ='Amortización y Depreciación'!$G$35 -> 3960000 | E28: ='Amortización y Depreciación'!$G$35 -> 3960000 | F28: ='Amortización y Depreciación'!$G$35 -> 3960000 | G28: ='Amortización y Depreciación'!$G$35 -> 3960000 | H28: ='Amortización y Depreciación'!$G$35 -> 3960000 | I28: ='Amortización y Depreciación'!$G$35 -> 3960000 | J28: ='Amortización y Depreciación'!$G$35 -> 3960000 | ... V28: ='Amortización y Depreciación'!$G$35 -> 3960000
B29: Total Depreciación | C29: =C28 -> 3960000 | D29: =D28 -> 3960000 | E29: =E28 -> 3960000 | F29: =F28 -> 3960000 | G29: =G28 -> 3960000 | H29: =H28 -> 3960000 | I29: =I28 -> 3960000 | J29: =J28 -> 3960000 | ... V29: =V28 -> 3960000
A31: FLUJO DE OPERACIÓN
B32: Impuestos | C32: ='Estado de Resultados'!C29 -> 1110440 | D32: ='Estado de Resultados'!D29 -> 1071420.4 | E32: ='Estado de Resultados'!E29 -> 1032406.6 | F32: ='Estado de Resultados'!F29 -> 3181046.7 | G32: ='Estado de Resultados'!G29 -> 4442580.7 | H32: ='Estado de Resultados'!H29 -> 4599969.4 | I32: ='Estado de Resultados'!I29 -> 4749997.8 | J32: ='Estado de Resultados'!J29 -> 4917476.1 | ... V32: ='Estado de Resultados'!V29 -> 11660921
B33: Total Flujo de Operación | C33: =C32 -> 1110440 | D33: =D32 -> 1071420.4 | E33: =E32 -> 1032406.6 | F33: =F32 -> 3181046.7 | G33: =G32 -> 4442580.7 | H33: =H32 -> 4599969.4 | I33: =I32 -> 4749997.8 | J33: =J32 -> 4917476.1 | ... V33: =V32 -> 11660921
A35: FLUJO DE CAJA LIBRE | C35: =C17-(SUM(C11,C25,C29,C33)) -> -162889243 | D35: =D17-(SUM(D11,D25,D29,D33)) -> -1.6285022e+08 | E35: =E17-(SUM(E11,E25,E29,E33)) -> -1.6281121e+08 | F35: =F17-(SUM(F11,F25,F29,F33)) -> -68118650 | G35: =G17-(SUM(G11,G25,G29,G33)) -> 15773616 | H35: =H17-(SUM(H11,H25,H29,H33)) -> 18934671 | I35: =I17-(SUM(I11,I25,I29,I33)) -> 21858711 | J35: =J17-(SUM(J11,J25,J29,J33)) -> 25138275 | ... V35: =V17-(SUM(V11,V25,V29,V33)) -> 1.7898639e+08

Sheet Flujo de Efectivo
A1: FLUJO DE EFECTIVO
A2: EDUCAFIN S.A.S.
A4: TRIMESTRE | C4: TRIMESTRE 1 | D4: TRIMESTRE 2 | E4: TRIMESTRE 3 | F4: TRIMESTRE 4 | G4: TRIMESTRE 5 | H4: TRIMESTRE 6 | I4: TRIMESTRE 7 | J4: TRIMESTRE 8 | K4: TRIMESTRE 9 | L4: TRIMESTRE 10 | M4: TRIMESTRE 11 | N4: TRIMESTRE 12 | O4: TRIMESTRE 13 | P4: TRIMESTRE 14 | Q4: TRIMESTRE 15 | R4: TRIMESTRE 16 | S4: TRIMESTRE 17 | T4: TRIMESTRE 18 | U4: TRIMESTRE 19 | V4: TRIMESTRE 20
A5: FLUJO DE CAJA DE OPERACIÓN
B6: Utilidad del Ejercicio | C6: ='Estado de Resultados'!C32 -> -287670243 | D6: ='Estado de Resultados'!D32 -> -1.6133122e+08 | E6: ='Estado de Resultados'!E32 -> -1.6129221e+08 | F6: ='Estado de Resultados'!F32 -> -66599650 | G6: ='Estado de Resultados'!G32 -> 17292616 | H6: ='Estado de Resultados'!H32 -> 20453671 | I6: ='Estado de Resultados'!I32 -> 23377711 | J6: ='Estado de Resultados'!J32 -> 26657275 | ... V6: ='Estado de Resultados'!V32 -> 1.8050539e+08
B7: Depreciaciones | C7: ='Flujo de Caja'!C28 -> 3960000 | D7: ='Flujo de Caja'!D28 -> 3960000 | E7: ='Flujo de Caja'!E28 -> 3960000 | F7: ='Flujo de Caja'!F28 -> 3960000 | G7: ='Flujo de Caja'!G28 -> 3960000 | H7: ='Flujo de Caja'!H28 -> 3960000 | I7: ='Flujo de Caja'!I28 -> 3960000 | J7: ='Flujo de Caja'!J28 -> 3960000 | ... V7: ='Flujo de Caja'!V28 -> 3960000
B8: Amortización | C8: ='Flujo de Caja'!C21 -> 3713651 | D8: ='Flujo de Caja'!D21 -> 3868138.9 | E8: ='Flujo de Caja'!E21 -> 4029053.5 | F8: ='Flujo de Caja'!F21 -> 4196662.1 | G8: ='Flujo de Caja'!G21 -> 4371243.2 | H8: ='Flujo de Caja'!H21 -> 4553086.9 | I8: ='Flujo de Caja'!I21 -> 4742495.4 | J8: ='Flujo de Caja'!J21 -> 4939783.2 | ... V8: ='Flujo de Caja'!V21 -> 0
B9: Intereses | C9: ='Flujo de Caja'!C22 -> 3415152 | D9: ='Flujo de Caja'!D22 -> 3260664.1 | E9: ='Flujo de Caja'!E22 -> 3099749.5 | F9: ='Flujo de Caja'!F22 -> 2932140.9 | G9: ='Flujo de Caja'!G22 -> 2757559.8 | H9: ='Flujo de Caja'!H22 -> 2575716.1 | I9: ='Flujo de Caja'!I22 -> 2386307.6 | J9: ='Flujo de Caja'!J22 -> 2189019.8 | ... V9: ='Flujo de Caja'!V22 -> 0
B10: Impuestos de la Renta | C10: ='Flujo de Caja'!C32 -> 1110440 | D10: ='Flujo de Caja'!D32 -> 1071420.4 | E10: ='Flujo de Caja'!E32 -> 1032406.6 | F10: ='Flujo de Caja'!F32 -> 3181046.7 | G10: ='Flujo de Caja'!G32 -> 4442580.7 | H10: ='Flujo de Caja'!H32 -> 4599969.4 | I10: ='Flujo de Caja'!I32 -> 4749997.8 | J10: ='Flujo de Caja'!J32 -> 4917476.1 | ... V10: ='Flujo de Caja'!V32 -> 11660921
B11: Flujo de Caja Operativo Neto | C11: =SUM(C6:C10) -> -275471000 | D11: =SUM(D6:D10) -> -149171000 | E11: =SUM(E6:E10) -> -149171000 | F11: =SUM(F6:F10) -> -52329800 | G11: =SUM(G6:G10) -> 32824000 | H11: =SUM(H6:H10) -> 36142443 | I11: =SUM(I6:I10) -> 39216512 | J11: =SUM(J6:J10) -> 42663554 | ... V11: =SUM(V6:V10) -> 1.9612631e+08
A13: FLUJO DE CAJA DE INVERSIÓN
B14: Inversión de Equipos de Computación | C14: ='Inversión Inicial'!D17 -> 27300000 | D14: =0 -> 0 | E14: =0 -> 0 | F14: =0 -> 0 | G14: =0 -> 0 | H14: =0 -> 0 | I14: =0 -> 0 | J14: =0 -> 0 | K14: =0 -> 0 | ... V14: =0 -> 0
B15: Flujo de Caja de Inversión Neto | C15: =SUM(C14:C14) -> 27300000 | D15: =SUM(D14:D14) -> 0 | E15: =SUM(E14:E14) -> 0 | F15: =SUM(F14:F14) -> 0 | G15: =SUM(G14:G14) -> 0 | H15: =SUM(H14:H14) -> 0 | I15: =SUM(I14:I14) -> 0 | J15: =SUM(J14:J14) -> 0 | ... V15: =SUM(V14:V14) -> 0
A17: FLUJO DE CAJA DE FINANCIAMIENTO
B18: Capital Social | C18: ='Balance General'!C42 -> 44205000 | D18: ='Balance General'!D42 -> 0 | E18: ='Balance General'!E42 -> 0 | F18: ='Balance General'!F42 -> 0 | G18: ='Balance General'!G42 -> 0 | H18: ='Balance General'!H42 -> 0 | I18: ='Balance General'!I42 -> 0 | J18: ='Balance General'!J42 -> 0 | ... V18: ='Balance General'!V42 -> 0
B19: Desembolso Pasivo | C19: ='Flujo de Caja'!C15 -> 82095000 | D19: ='Flujo de Caja'!D15 -> 0 | E19: ='Flujo de Caja'!E15 -> 0 | F19: ='Flujo de Caja'!F15 -> 0 | G19: ='Flujo de Caja'!G15 -> 0 | H19: ='Flujo de Caja'!H15 -> 0 | I19: ='Flujo de Caja'!I15 -> 0 | J19: ='Flujo de Caja'!J15 -> 0 | ... V19: ='Flujo de Caja'!V15 -> 0
B20: Amortizaciones | C20: =C8 -> 3713651 | D20: =D8 -> 3868138.9 | E20: =E8 -> 4029053.5 | F20: =F8 -> 4196662.1 | G20: =G8 -> 4371243.2 | H20: =H8 -> 4553086.9 | I20: =I8 -> 4742495.4 | J20: =J8 -> 4939783.2 | ... V20: =V8 -> 0
B21: Intereses | C21: =C9 -> 3415152 | D21: =D9 -> 3260664.1 | E21: =E9 -> 3099749.5 | F21: =F9 -> 2932140.9 | G21: =G9 -> 2757559.8 | H21: =H9 -> 2575716.1 | I21: =I9 -> 2386307.6 | J21: =J9 -> 2189019.8 | ... V21: =V9 -> 0
B22: Flujo de Caja de Financiamiento Neto | C22: =SUM(C18:C21) -> 133428803 | D22: =SUM(D18:D21) -> 7128803 | E22: =SUM(E18:E21) -> 7128803 | F22: =SUM(F18:F21) -> 7128803 | G22: =SUM(G18:G21) -> 7128803 | H22: =SUM(H18:H21) -> 7128803 | I22: =SUM(I18:I21) -> 7128803 | J22: =SUM(J18:J21) -> 7128803 | ... V22: =SUM(V18:V21) -> 0

Sheet Costos Fijos y ETC
B2: COSTOS FIJOS Y VARIABLES
B3: Costos y/o gastos | D3: Administración y ventas | E3: Producción
A4: Q | B4: Número de producción | D4: 0 | E4: =SUM('Balance General'!C7:V7) -> 2.4771423e+09
B5: Numero permanente (100%) | C5: =E4 -> 2.4771423e+09 | D5: 0 | E5: 0
B6: Otros gastos administrativos | D6: ='Inversión Inicial'!D17 -> 27300000 | E6: 0
B7: Depreciación de Producción | E7: =

Sheet Inversión Inicial
A1: Inversión Inicial
A2: Tipo de inversión | B2: Valor
A3: Diseño UX/UI | B3: =B29 -> 15000000
A4: Producción de contenidos interactivos | B4: =B37 -> 11000000
A5: Equipos de cómputo y hardware | B5: =D17 -> 27300000
A6: Marketing, lanzamiento y proyección | B6: =B45 -> 48000000
A7: Consultoría especializada y mentoría | B7: =B52 -> 16000000
A8: Creación de infraestructura y arquitectura de software | B8: =B60 -> 9000000
A9: SUBTOTAL | B9: =SUM(B3:B8) -> 126300000
A11: Activos Tangibles
A12: Concepto | B12: Cantidad | C12: Valor Unitario | D12: Valor Total
A13: Computadoras/Laptops | B13: 6 | C13: 3000000 | D13: =C13*B13 -> 18000000
A14: Monitores | B14: 6 | C14: 800000 | D14: =C14*B14 -> 4800000
A15: Perifericos (Mouse, Teclados, Audifonos) | B15: 6 | C15: 300000 | D15: =C15*B15 -> 1800000
A16: Accesorios (Papeleria, etc) | B16: 6 | C16: 450000 | D16: =C16*B16 -> 2700000
A17: SUBTOTAL | D17: =SUM(D13:D16) -> 27300000
A19: Capital Social
A20: Tipo de inversión | B20: Valor
A21: Financiamiento por Deuda | B21: =B9*0.65 -> 82095000
A22: Capital Social | B22: =B9*0.35 -> 44205000
A24: Inversión en Diseño UX/UI
A25: Concepto | B25: Valor
A26: Investigación UX (Tesis y Entrevistas) | B26: 4500000
A27: Diseño UI (Mockups y Prototipos) | B27: 6000000
A28: Prubeas de Usabilidad y Ajustes | B28: 4500000
A29: SUBTOTAL | B29: =SUM(B26:B28) -> 15000000
A31: Inversión en Producción de Contenidos Interactivos
A32: Concepto | B32: Valor
A33: Guión y Diseño | B33: 2750000
A34: Desarrollo de Simuladores | B34: 4125000
A35: Licencias y Recursos (Stock y Assets) | B35: 1375000
A36: Producción Multimedia (Audios y Videos) | B36: 2750000
A37: SUBTOTAL | B37: =SUM(B33:B36) -> 11000000
A39: Inversión en Marketing, Lanzamiento y Proyección
A40: Concepto | B40: Valor
A41: Estrategia y Branding (Diseño y Marca) | B41: 10667000
A42: Campañas digitales (Google Ads o RRSS) | B42: 21333000
A43: Producción Audiovisual Promocional | B43: 10667000
A44: Eventos y Demostraciones (Material Físico) | B44: 5333000
A45: SUBTOTAL | B45: =SUM(B41:B44) -> 48000000
...

Sheet Costos de Operación Gravables
A1: Costos de Operación Gravables | F1: Costos de Operación Gravables (valor trimestral)
A2: Sueldos de los Empleados | F2: Sueldos de los Empleados
A3: Tipo de inversión | B3: Unidades | C3: Valor Unitario/mes | D3: Valor Total/mes | F3: Valor de 0 | G3: Conversión Trimestral | H3: Tasa de Crecimiento | I3: 1° Trimestre | J3: 2° Trimestre | K3: 3° Trimestre | L3: 4° Trimestre | M3: 5° Trimestre | N3: 6° Trimestre | O3: 7° Trimestre | P3: 8° Trimestre | Q3: 9° Trimestre | R3: 10° Trimestre | S3: 11° Trimestre | T3: 12° Trimestre | U3: 13° Trimestre | V3: 14° Trimestre | W3: 15° Trimestre | X3: 16° Trimestre | Y3: 17° Trimestre | Z3: 18° Trimestre | AA3: 19° Trimestre | AB3: 20° Trimestre
A4: Scrum Master | B4: 1 | C4: 4000000 | D4: =C4*B4 -> 4000000 | F4: =D11 -> 37800000 | G4: =F4*3 -> 113400000 | H4: N/A | I4: =$G$4 -> 113400000 | J4: =$G$4 -> 113400000 | K4: =$G$4 -> 113400000 | L4: =$G$4*0.5 -> 56700000
A5: Desarrollador Back-End | B5: 2 | C5: 4000000 | D5: =C5*B5 -> 8000000 | F5: Sueldos de los Empleados (Pos-Lanzamiento, 10 meses)
A6: Desarrollador Front-End | B6: 2 | C6: 4000000 | D6: =C6*B6 -> 8000000 | F6: Valor de 0 | G6: Conversión Trimestral | H6: Tasa de Crecimiento | I6: 1° Trimestre | J6: 2° Trimestre | K6: 3° Trimestre | L6: 4° Trimestre | M6: 5° Trimestre | N6: 6° Trimestre | O6: 7° Trimestre | P6: 8° Trimestre | Q6: 9° Trimestre | R6: 10° Trimestre | S6: 11° Trimestre | T6: 12° Trimestre | U6: 13° Trimestre | V6: 14° Trimestre | W6: 15° Trimestre | X6: 16° Trimestre | Y6: 17° Trimestre | Z6: 18° Trimestre | AA6: 19° Trimestre | AB6: 20° Trimestre
A7: Soporte IT (Asesoría Financiera) | B7: 3 | C7: 2300000 | D7: =C7*B7 -> 6900000 | F7: =SUM(D7,D9:D10) -> 11300000 | G7: =F7*3 -> 33900000 | H7: 0.02 | L7: =$G$7*0.5 -> 16950000 | M7: =G7 -> 33900000 | N7: =M7*($H$7+1) -> 34578000 | O7: =N7*($H$7+1) -> 35269560 | P7: =O7*($H$7+1) -> 35974951 | Q7: =P7*($H$7+1) -> 36694450 | R7: =Q7*($H$7+1) -> 37428339 | S7: =R7*($H$7+1) -> 38176906 | T7: =S7*($H$7+1) -> 38940444 | U7: =T7*($H$7+1) -> 39719253 | ... AB7: =AA7*($H$7+1) -> 45624937
A8: Cloud Architect | B8: 1 | C8: 6500000 | D8: =C8*B8 -> 6500000 | F8: Prestaciones y Parafiscales
A9: Líder de Desarrollo | B9: 1 | C9: 2200000 | D9: =C9*B9 -> 2200000 | F9: Valor de 0 | G9: Conversión Trimestral | H9: Tasa de Crecimiento | I9: 1° Trimestre | J9: 2° Trimestre | K9: 3° Trimestre | L9: 4° Trimestre | M9: 5° Trimestre | N9: 6° Trimestre | O9: 7° Trimestre | P9: 8° Trimestre | Q9: 9° Trimestre | R9: 10° Trimestre | S9: 11° Trimestre | T9: 12° Trimestre | U9: 13° Trimestre | V9: 14° Trimestre | W9: 15° Trimestre | X9: 16° Trimestre | Y9: 17° Trimestre | Z9: 18° Trimestre | AA9: 19° Trimestre | AB9: 20° Trimestre
A10: Líder I+D+I | B10: 1 | C10: 2200000 | D10: =C10*B10 -> 2200000 | F10: =D22 -> 12430000 | G10: =F10*3 -> 37290000 | H10: N/A | I10: =$G$10 -> 37290000 | J10: =$G$10 -> 37290000 | K10: =$G$10 -> 37290000 | L10: =$G$10*0.5 -> 18645000
A11: Total | C11: =SUM(C4:C10) -> 25200000 | D11: =SUM(D4:D10) -> 37800000 | F11: Prestaciones y Parafiscales (Pos-Lanzamiento, 10 meses)
A12: Prestaciones y Parafiscales | F12: Valor de 0 | G12: Conversión Trimestral | H12: Tasa de Crecimiento | I12: 1° Trimestre | J12: 2° Trimestre | K12: 3° Trimestre | L12: 4° Trimestre | M12: 5° Trimestre | N12: 6° Trimestre | O12: 7° Trimestre | P12: 8° Trimestre | Q12: 9° Trimestre | R12: 10° Trimestre | S12: 11° Trimestre | T12: 12° Trimestre | U12: 13° Trimestre | V12: 14° Trimestre | W12: 15° Trimestre | X12: 16° Trimestre | Y12: 17° Trimestre | Z12: 18° Trimestre | AA12: 19° Trimestre | AB12: 20° Trimestre
A13: Tipo de inversión | B13: Unidades | C13: Valor Unitario/mes | D13: Valor Total/mes | F13: =C22*3 -> 3390000 | G13: =F13*3 -> 10170000 | H13: 0.02 | L13: =G13*0.5 -> 5085000 | M13: =G13 -> 10170000 | N13: =M13*($H$13+1) -> 10373400 | O13: =N13*($H$13+1) -> 10580868 | P13: =O13*($H$13+1) -> 10792485 | Q13: =P13*($H$13+1) -> 11008335 | R13: =Q13*($H$13+1) -> 11228502 | S13: =R13*($H$13+1) -> 11453072 | T13: =S13*($H$13+1) -> 11682133 | U13: =T13*($H$13+1) -> 11915776 | ... AB13: =AA13*($H$13+1) -> 13687481
A14: Cesantias | B14: =SUM($B$4:$B$10) -> 11 | C14: 200000 | D14: =C14*B14 -> 2200000 | F14: Infraestructuras (10 meses)
A15: Intereses sobre cesantias | B15: =SUM($B$4:$B$10) -> 11 | C15: 25000 | D15: =C15*B15 -> 275000 | F15: Valor de 0 | G15: Conversión Trimestral | H15: Tasa de Crecimiento | I15: 1° Trimestre | J15: 2° Trimestre | K15: 3° Trimestre | L15: 4° Trimestre | M15: 5° Trimestre | N15: 6° Trimestre | O15: 7° Trimestre | P15: 8° Trimestre | Q15: 9° Trimestre | R15: 10° Trimestre | S15: 11° Trimestre | T15: 12° Trimestre | U15: 13° Trimestre | V15: 14° Trimestre | W15: 15° Trimestre | X15: 16° Trimestre | Y15: 17° Trimestre | Z15: 18° Trimestre | AA15: 19° Trimestre | AB15: 20° Trimestre
A16: Primas | B16: =SUM($B$4:$B$10) -> 11 | C16: 200000 | D16: =C16*B16 -> 2200000 | F16: =D27 -> 3720000 | G16: =F16*3 -> 11160000 | H16: 0.06 | L16: =$G$16 -> 11160000 | M16: =L16*($H$16+1) -> 11829600 | N16: =M16*($H$16+1) -> 12539376 | O16: =N16*($H$16+1) -> 13291739 | P16: =O16*($H$16+1) -> 14089243 | Q16: =P16*($H$16+1) -> 14934597 | R16: =Q16*($H$16+1) -> 15830673 | S16: =R16*($H$16+1) -> 16780514 | T16: =S16*($H$16+1) -> 17787345 | ... AB16: =AA16*($H$16+1) -> 28350325
A17: Vacaciones | B17: =SUM($B$4:$B$10) -> 11 | C17: 100000 | D17: =C17*B17 -> 1100000 | F17: Otros
A18: Pensiones (AFP) | B18: =SUM($B$4:$B$10) -> 11 | C18: 300000 | D18: =C18*B18 -> 3300000 | F18: Valor de 0 | G18: Conversión Trimestral | H18: Tasa de Crecimiento | I18: 1° Trimestre | J18: 2° Trimestre | K18: 3° Trimestre | L18: 4° Trimestre | M18: 5° Trimestre | N18: 6° Trimestre | O18: 7° Trimestre | P18: 8° Trimestre | Q18: 9° Trimestre | R18: 10° Trimestre | S18: 11° Trimestre | T18: 12° Trimestre | U18: 13° Trimestre | V18: 14° Trimestre | W18: 15° Trimestre | X18: 16° Trimestre | Y18: 17° Trimestre | Z18: 18° Trimestre | AA18: 19° Trimestre | AB18: 20° Trimestre
A19: Salud (EPS) | B19: =SUM($B$4:$B$10) -> 11 | C19: 200000 | D19: =C19*B19 -> 2200000 | F19: =D31 -> 1451000 | G19: N/A | H19: N/A | I19: =$F$19 -> 1451000
A20: Riesgos Laborales (ARL) | B20: =SUM($B$4:$B$10) -> 11 | C20: 15000 | D20: =C20*B20 -> 165000 | F20: TOTAL
A21: Caja de Compensación Familiar | B21: =SUM($B$4:$B$10) -> 11 | C21: 90000 | D21: =C21*B21 -> 990000 | I21: =SUM(I4,I7,I10,I13,I16,I19) -> 152141000 | J21: =SUM(J4,J7,J10,J13,J16,J19) -> 150690000 | K21: =SUM(K4,K7,K10,K13,K16,K19) -> 150690000 | L21: =SUM(L4,L7,L10,L13,L16,L19) -> 108540000 | M21: =SUM(M4,M7,M10,M13,M16,M19) -> 55899600 | N21: =SUM(N4,N7,N10,N13,N16,N19) -> 57490776 | O21: =SUM(O4,O7,O10,O13,O16,O19) -> 59142167 | P21: =SUM(P4,P7,P10,P13,P16,P19) -> 60856679 | ... AB21: =SUM(AB4,AB7,AB10,AB13,AB16,AB19) -> 87662742
A22: Total | C22: =SUM(C14:C21) -> 1130000 | D22: =SUM(D14:D21) -> 12430000
A23: Infraestructuras
A24: Tipo de inversión | B24: Unidades | C24: Valor Unitario/mes | D24: Valor Total/mes
A25: Internet | B25: 1 | C25: 220000 | D25: =C25*B25 -> 220000
A26: Servicios de Infraestructura/Hosting | B26: 1 | C26: 3500000 | D26: =C26*B26 -> 3500000
A27: Total | C27: =SUM(C25:C26) -> 3720000 | D27: =SUM(D25:D26) -> 3720000
A28: Otros
A29: Tipo de inversión | B29: Unidades | C29: Valor Unitario/mes | D29: Valor Total/mes
A30: Registros y Estatos | B30: 1 | C30: =B41 -> 1451000 | D30: =C30*B30 -> 1451000
A31: Total | C31: =SUM(C29:C30) -> 1451000 | D31: =SUM(D29:D30) -> 1451000
A33: Activos Fijos Intangibles
A34: Concepto | B34: Valor
A35: Registro de Marca | B35: 1288000
A36: Estatutos | B36: 30000
A37: Registro Cámara de Comercio de Bogotá | B37: 69000
A38: Inscripción de Libros Contables | B38: 64000
A39: Apertura de Cuentas Bancarias | B39: N/A
A40: Formulario Único de Registro Empresarial | B40: N/A
A41: Total | B41: =SUM(B35:B38) -> 1451000
...

Sheet Proyección de Ventas e Incremen
A1: Ingresos y Proyecciones de Venta | H1: Proyección Incremento de Ventas
A2: Ingresos | H2: IPC Proyectado y Flujo de Efectivo
A3: Concepto | C3: Unidades | D3: Valor/mes | E3: Valor/trimestre | F3: Valor/año | H3: Indicador | I3: 1° Trimestre | J3: 2° Trimestre | K3: 3° Trimestre | L3: 4° Trimestre | M3: 5° Trimestre | N3: 6° Trimestre | O3: 7° Trimestre | P3: 8° Trimestre | Q3: 9° Trimestre | R3: 10° Trimestre | S3: 11° Trimestre | T3: 12° Trimestre | U3: 13° Trimestre | V3: 14° Trimestre | W3: 15° Trimestre | X3: 16° Trimestre | Y3: 17° Trimestre | Z3: 18° Trimestre | AA3: 19° Trimestre | AB3: 20° Trimestre
A4: Plan Gratuito | C4: N/A | D4: 0 | E4: =D4*3 -> 0 | F4: =D4*12 -> 0 | H4: IPC Proyectado | I4: 0.0128 | J4: 0.0128 | K4: 0.0128 | L4: 0.0128 | M4: 0.0113 | N4: 0.0113 | O4: 0.0113 | P4: 0.0113 | Q4: 0.01 | R4: 0.01 | S4: 0.01 | T4: 0.01 | U4: 0.009 | V4: 0.009 | W4: 0.009 | X4: 0.009 | Y4: 0.0081 | Z4: 0.0081 | AA4: 0.0081 | AB4: 0.0081
A5: Plan Suscriptor | C5: N/A | D5: 30000 | E5: =D5*3 -> 90000 | F5: =D5*12 -> 360000 | H5: % Crecimiento de Ventas | M5: 0.0525 | N5: 0.045 | O5: 0.04 | P5: 0.042 | Q5: 0.045 | R5: 0.048 | S5: 0.052 | T5: 0.057 | U5: 0.063 | V5: 0.07 | W5: 0.078 | X5: 0.087 | Y5: 0.097 | Z5: 0.108 | AA5: 0.12 | AB5: 0.133
A6: Publicidad de Plan Gratuito | C6: N/A | D6: 300 | E6: =D6*3 -> 900 | F6: =D6*12 -> 3600 | H6: Crecimiento de ventas indexación IPC y % crecimiento | L6: =SUM(L4:L5) -> 0.0128 | M6: =SUM(M4:M5) -> 0.0638 | N6: =SUM(N4:N5) -> 0.0563 | O6: =SUM(O4:O5) -> 0.0513 | P6: =SUM(P4:P5) -> 0.0533 | Q6: =SUM(Q4:Q5) -> 0.055 | R6: =SUM(R4:R5) -> 0.058 | S6: =SUM(S4:S5) -> 0.062 | ... AB6: =SUM(AB4:AB5) -> 0.1411
A7: Proyección de Ventas | H7: Flujo de efectivo | L7: =((E12/3)*2)*(1+L6) -> 54691200 | M7: =E12*(1+M6+L6) -> 87204600 | N7: =M7*(1+N6) -> 92114219 | O7: =N7*(1+O6) -> 96839678 | P7: =O7*(1+P6) -> 1.0200123e+08 | Q7: =P7*(1+Q6) -> 1.076113e+08 | R7: =Q7*(1+R6) -> 1.1385276e+08 | S7: =R7*(1+S6) -> 1.2091163e+08 | T7: =S7*(1+T6) -> 1.2901271e+08 | U7: =T7*(1+U6) -> 1.3830162e+08 | ... AB7: =AA7*(1+AB6) -> 2.8227005e+08
A8: Servicio | B8: Valor/mes | C8: N° Suscripción/mes | D8: Ingreso/mes | E8: Ingreso/trimestre | F8: Ingreso/anual
A9: Plan Gratuito | B9: =D4 -> 0 | C9: 9000 | D9: =B9*$C$9 -> 0 | E9: =D9*3 -> 0 | F9: =D9*12 -> 0
A10: Plan Suscriptor | B10: =D5 -> 30000 | C10: =C9*0.09 -> 810 | D10: =B10*$C$10 -> 24300000 | E10: =D10*3 -> 72900000 | F10: =D10*12 -> 291600000
A11: Publicidad de Plan Gratuito | B11: 300 | C11: =C9 -> 9000 | D11: =B11*$C$11 -> 2700000 | E11: =D11*3 -> 8100000 | F11: =D11*12 -> 32400000
A12: Total | C12: =SUM(C10:C11) -> 9810 | D12: =SUM(D9:D11) -> 27000000 | E12: =SUM(E9:E11) -> 81000000 | F12: =SUM(F9:F11) -> 324000000
A14: Tabla de Financiamiento
A15: Concepto | B15: Valor
A16: Financiamiento Externo | B16: ='Costos de Operación Gravables'!$B$47*0.65 -> 18688150
A17: Aportes Sociales | B17: ='Costos de Operación Gravables'!$B$47*0.35 -> 10062850
A18: Total | B18: =SUM(B16:B17) -> 28751000

Sheet Amortización y Depreciación
A1: Amortización y Depreciación | D1: Amortización de Crédito
A2: Préstamo (en Banco GNB Sudameris) | D2: Período | E2: Saldo | F2: Interes | G2: Amortización | H2: Pago al Crédito | I2: Saldo Final
A3: Concepto | B3: Unidades | D3: 0° Trimestre | E3: =B4 -> 82095000 | F3: 0 | G3: 0 | H3: 0 | I3: =E3 -> 82095000
A4: Valor del Préstamo | B4: ='Inversión Inicial'!B9*0.65 -> 82095000 | D4: 1° Trimestre | E4: =I3 -> 82095000 | F4: =E4*$B$7 -> 3415152 | G4: =$B$8 -> 7128803 | H4: =G4-F4 -> 3713651 | I4: =E4-H4 -> 78381349
A5: Cuota Inicial | B5: 0 | D5: 2° Trimestre | E5: =I4 -> 78381349 | F5: =E5*$B$7 -> 3260664.1 | G5: =$B$8 -> 7128803 | H5: =G5-F5 -> 3868138.9 | I5: =E5-H5 -> 74513210
A6: Plazo | B6: 16 trimestres (48 meses) | D6: 3° Trimestre | E6: =I5 -> 74513210 | F6: =E6*$B$7 -> 3099749.5 | G6: =$B$8 -> 7128803 | H6: =G6-F6 -> 4029053.5 | I6: =E6-H6 -> 70484157
A7: Tasa de Interés (trimestralmente) | B7: 0.0416 | D7: 4° Trimestre | E7: =I6 -> 70484157 | F7: =E7*$B$7 -> 2932140.9 | G7: =$B$8 -> 7128803 | H7: =G7-F7 -> 4196662.1 | I7: =E7-H7 -> 66287495
A8: Pago Mensual | B8: 7128803 | D8: 5° Trimestre | E8: =I7 -> 66287495 | F8: =E8*$B$7 -> 2757559.8 | G8: =$B$8 -> 7128803 | H8: =G8-F8 -> 4371243.2 | I8: =E8-H8 -> 61916251
D9: 6° Trimestre | E9: =I8 -> 61916251 | F9: =E9*$B$7 -> 2575716.1 | G9: =$B$8 -> 7128803 | H9: =G9-F9 -> 4553086.9 | I9: =E9-H9 -> 57363164
D10: 7° Trimestre | E10: =I9 -> 57363164 | F10: =E10*$B$7 -> 2386307.6 | G10: =$B$8 -> 7128803 | H10: =G10-F10 -> 4742495.4 | I10: =E10-H10 -> 52620669
D11: 8° Trimestre | E11: =I10 -> 52620669 | F11: =E11*$B$7 -> 2189019.8 | G11: =$B$8 -> 7128803 | H11: =G11-F11 -> 4939783.2 | I11: =E11-H11 -> 47680886
D12: 9° Trimestre | E12: =I11 -> 47680886 | F12: =E12*$B$7 -> 1983524.9 | G12: =$B$8 -> 7128803 | H12: =G12-F12 -> 5145278.1 | I12: =E12-H12 -> 42535608
D13: 10° Trimestre | E13: =I12 -> 42535608 | F13: =E13*$B$7 -> 1769481.3 | G13: =$B$8 -> 7128803 | H13: =G13-F13 -> 5359321.7 | I13: =E13-H13 -> 37176286
D14: 11° Trimestre | E14: =I13 -> 37176286 | F14: =E14*$B$7 -> 1546533.5 | G14: =$B$8 -> 7128803 | H14: =G14-F14 -> 5582269.5 | I14: =E14-H14 -> 31594017
D15: 12° Trimestre | E15: =I14 -> 31594017 | F15: =E15*$B$7 -> 1314311.1 | G15: =$B$8 -> 7128803 | H15: =G15-F15 -> 5814491.9 | I15: =E15-H15 -> 25779525
D16: 13° Trimestre | E16: =I15 -> 25779525 | F16: =E16*$B$7 -> 1072428.2 | G16: =$B$8 -> 7128803 | H16: =G16-F16 -> 6056374.8 | I16: =E16-H16 -> 19723150
D17: 14° Trimestre | E17: =I16 -> 19723150 | F17: =E17*$B$7 -> 820483.03 | G17: =$B$8 -> 7128803 | H17: =G17-F17 -> 6308320 | I17: =E17-H17 -> 13414830
D18: 15° Trimestre | E18: =I17 -> 13414830 | F18: =E18*$B$7 -> 558056.92 | G18: =$B$8 -> 7128803 | H18: =G18-F18 -> 6570746.1 | I18: =E18-H18 -> 6844083.8
D19: 16° Trimestre | E19: =I18 -> 6844083.8 | F19: =E19*$B$7 -> 284713.89 | G19: =$B$8 -> 7128803 | H19: =G19-F19 -> 6844089.1 | I19: =E19-H19 -> -5.3394999
D21: Depreciación
D22: Activos Fijos | E22: Vida Útil | F22: Valor Inicial | G22: Año 1 | H22: Año 2 | I22: Año 3 | J22: Año 4 | K22: Año 5
D23: Computador 1 | E23: 5 años | F23: ='Inversión Inicial'!$C$13 -> 3000000 | G23: =$F23*G$36 -> 600000 | H23: =$F23*H$36 -> 1200000 | I23: =$F23*I$36 -> 1800000 | J23: =$F23*J$36 -> 2400000 | K23: =$F23*K$36 -> 3000000
D24: Perifericos 1 | E24: 5 años | F24: ='Inversión Inicial'!$C$15 -> 300000 | G24: =$F24*G$36 -> 60000 | H24: =$F24*H$36 -> 120000 | I24: =$F24*I$36 -> 180000 | J24: =$F24*J$36 -> 240000 | K24: =$F24*K$36 -> 300000
D25: Computador 2 | E25: 5 años | F25: ='Inversión Inicial'!$C$13 -> 3000000 | G25: =$F25*G$36 -> 600000 | H25: =$F25*H$36 -> 1200000 | I25: =$F25*I$36 -> 1800000 | J25: =$F25*J$36 -> 2400000 | K25: =$F25*K$36 -> 3000000
D26: Perifericos 2 | E26: 5 años | F26: ='Inversión Inicial'!$C$15 -> 300000 | G26: =$F26*G$36 -> 60000 | H26: =$F26*H$36 -> 120000 | I26: =$F26*I$36 -> 180000 | J26: =$F26*J$36 -> 240000 | K26: =$F26*K$36 -> 300000
D27: Computador 3 | E27: 5 años | F27: ='Inversión Inicial'!$C$13 -> 3000000 | G27: =$F27*G$36 -> 600000 | H27: =$F27*H$36 -> 1200000 | I27: =$F27*I$36 -> 1800000 | J27: =$F27*J$36 -> 2400000 | K27: =$F27*K$36 -> 3000000
D28: Perifericos 3 | E28: 5 años | F28: ='Inversión Inicial'!$C$15 -> 300000 | G28: =$F28*G$36 -> 60000 | H28: =$F28*H$36 -> 120000 | I28: =$F28*I$36 -> 180000 | J28: =$F28*J$36 -> 240000 | K28: =$F28*K$36 -> 300000
D29: Computador 4 | E29: 5 años | F29: ='Inversión Inicial'!$C$13 -> 3000000 | G29: =$F29*G$36 -> 600000 | H29: =$F29*H$36 -> 1200000 | I29: =$F29*I$36 -> 1800000 | J29: =$F29*J$36 -> 2400000 | K29: =$F29*K$36 -> 3000000
D30: Perifericos 4 | E30: 5 años | F30: ='Inversión Inicial'!$C$15 -> 300000 | G30: =$F30*G$36 -> 60000 | H30: =$F30*H$36 -> 120000 | I30: =$F30*I$36 -> 180000 | J30: =$F30*J$36 -> 240000 | K30: =$F30*K$36 -> 300000
D31: Computador 5 | E31: 5 años | F31: ='Inversión Inicial'!$C$13 -> 3000000 | G31: =$F31*G$36 -> 600000 | H31: =$F31*H$36 -> 1200000 | I31: =$F31*I$36 -> 1800000 | J31: =$F31*J$36 -> 2400000 | K31: =$F31*K$36 -> 3000000
D32: Perifericos 5 | E32: 5 años | F32: ='Inversión Inicial'!$C$15 -> 300000 | G32: =$F32*G$36 -> 60000 | H32: =$F32*H$36 -> 120000 | I32: =$F32*I$36 -> 180000 | J32: =$F32*J$36 -> 240000 | K32: =$F32*K$36 -> 300000
D33: Computador 6 | E33: 5 años | F33: ='Inversión Inicial'!$C$13 -> 3000000 | G33: =$F33*G$36 -> 600000 | H33: =$F33*H$36 -> 1200000 | I33: =$F33*I$36 -> 1800000 | J33: =$F33*J$36 -> 2400000 | K33: =$F33*K$36 -> 3000000
D34: Perifericos 6 | E34: 5 años | F34: ='Inversión Inicial'!$C$15 -> 300000 | G34: =$F34*G$36 -> 60000 | H34: =$F34*H$36 -> 120000 | I34: =$F34*I$36 -> 180000 | J34: =$F34*J$36 -> 240000 | K34: =$F34*K$36 -> 300000
D35: Depreciación Total | G35: =SUM(G23:G34) -> 3960000 | H35: =SUM(H23:H34) -> 7920000 | I35: =SUM(I23:I34) -> 11880000 | J35: =SUM(J23:J34) -> 15840000 | K35: =SUM(K23:K34) -> 19800000
D36: Tasa de Depreciación Total | G36: 0.2 | H36: 0.4 | I36: 0.6 | J36: 0.8 | K36: 1
D38: Depreciación
D39: Activos Fijos | E39: Vida Útil | F39: Valor Inicial | G39: Año 1 | H39: Año 2 | I39: Año 3 | J39: Año 4 | K39: Año 5
D40: Computador 1 | E40: 5 años | F40: ='Inversión Inicial'!$C$13 -> 3000000 | G40: =$F40-($F40*G$53) -> 2400000 | H40: =$F40-($F40*H$53) -> 1800000 | I40: =$F40-($F40*I$53) -> 1200000 | J40: =$F40-($F40*J$53) -> 600000 | K40: =$F40-($F40*K$53) -> 0
D41: Perifericos 1 | E41: 5 años | F41: ='Inversión Inicial'!$C$15 -> 300000 | G41: =$F41-($F41*G$53) -> 240000 | H41: =$F41-($F41*H$53) -> 180000 | I41: =$F41-($F41*I$53) -> 120000 | J41: =$F41-($F41*J$53) -> 60000 | K41: =$F41-($F41*K$53) -> 0
D42: Computador 2 | E42: 5 años | F42: ='Inversión Inicial'!$C$13 -> 3000000 | G42: =$F42-($F42*G$53) -> 2400000 | H42: =$F42-($F42*H$53) -> 1800000 | I42: =$F42-($F42*I$53) -> 1200000 | J42: =$F42-($F42*J$53) -> 600000 | K42: =$F42-($F42*K$53) -> 0
...
