Workbook

Sheet Inversión Inicial
A1: Inversión Inicial
A2: Tipo de inversión | B2: Valor
A3: Planeación y diseño UX/UI | B3: =B23 -> 5000000
A4: Producción y creación de contenidos interactivos | B4: =B31 -> 3740000
A5: Equipos de cómputo y hardware | B5: =D16 -> 8200000
A6: Planeación de marketing, lanzamiento y proyección | B6: =B37 -> 7000000
A7: Consultoría especializada y mentoría | B7: =B44 -> 6000000
A8: Creación de infraestructura y arquitectura de software | B8: =B52 -> 3700000
A9: TOTAL | B9: =SUM(B3:B8) -> 33640000
A11: Recursos Físicos (Activos Fijos Tangibles)
A12: Concepto | B12: Cantidad | C12: Valor Unitario | D12: Valor Total
A13: Computadoras o laptops | B13: 2 | C13: 3000000 | D13: =C13*B13 -> 6000000
A14: Monitores | B14: 2 | C14: 800000 | D14: =C14*B14 -> 1600000
A15: Perifericos (mouse, teclados, audífonos) | B15: 2 | C15: 300000 | D15: =C15*B15 -> 600000
A16: SUBTOTAL | D16: =SUM(D13:D15) -> 8200000
A18: Inversión en Planeación y Diseño UX/UI
A19: Concepto | B19: Valor
A20: Investigación UX (tesis y entrevistas) | B20: 1500000
A21: Diseño UI (mockups y prototipos) | B21: 2000000
A22: Prubeas de Usabilidad y Ajustes | B22: 1500000
A23: SUBTOTAL | B23: =SUM(B20:B22) -> 5000000
A25: Inversión en Producción y Creación de Contenidos Interactivos
A26: Concepto | B26: Valor
A27: Guión y diseño | B27: 920000
A28: Desarrollo de simuladores | B28: 1300000
A29: Licencias y recursos (stock y assets) | B29: 600000
A30: Producción multimedia (audios y videos) | B30: 920000
A31: SUBTOTAL | B31: =SUM(B27:B30) -> 3740000
A33: Planeación en Marketing, Lanzamiento y Proyección
A34: Concepto | B34: Valor
A35: Estrategia y branding (Diseño y marca) | B35: 3500000
A36: Producción audiovisual promocional | B36: 3500000
A37: SUBTOTAL | B37: =SUM(B35:B36) -> 7000000
A39: Inversión en Consultoría Especializada
A40: Concepto | B40: Valor
A41: Asesoría legal y cumplimiento | B41: 2000000
A42: Seguridad de la información / datos | B42: 2000000
A43: Mentoría estratégica y producto | B43: 2000000
A44: SUBTOTAL | B44: =SUM(B41:B43) -> 6000000
A46: Inversión en Creación de Infraestructura y Arquitectura de Software
...

Sheet Proyección de Ventas e Incremen
A1: Ingresos y Proyecciones de Venta | H1: Proyección Incremento de Ventas
A2: Ingresos | H2: IPC Proyectado y Flujo de Efectivo
A3: Concepto | C3: Unidades | D3: Valor/mes | E3: Valor/trimestre | F3: Valor/año | H3: Indicador | I3: Año 0 | J3: Año 1 (2027) | K3: Año 2 (2028) | L3: Año 3 (2029) | M3: Año 4 (2030) | N3: Año 5 (2031)
A4: Plan Gratuito | C4: N/A | D4: 0 | E4: =D4*3 -> 0 | F4: =D4*12 -> 0 | H4: IPC Proyectado | J4: 0.046 | K4: 0.039 | L4: 0.037 | M4: 0.035 | N4: 0.034
A5: Plan Suscriptor | C5: N/A | D5: 30000 | E5: =D5*3 -> 90000 | F5: =D5*12 -> 360000 | H5: % Crecimiento de Ventas | J5: 0.25 | K5: 0.22 | L5: 0.25 | M5: 0.29 | N5: 0.34
A6: Publicidad de Plan Gratuito | C6: N/A | D6: 300 | E6: =D6*3 -> 900 | F6: =D6*12 -> 3600 | H6: Crecimiento de ventas indexación IPC y % crecimiento | J6: =SUM(J4:J5) -> 0.296 | K6: =SUM(K4:K5) -> 0.259 | L6: =SUM(L4:L5) -> 0.287 | M6: =SUM(M4:M5) -> 0.325 | N6: =SUM(N4:N5) -> 0.374
A7: Proyección de Ventas | H7: Flujo de efectivo | J7: =F12*(1+J6) -> 163296000 | K7: =J7*(1+K6) -> 2.0558966e+08 | L7: =K7*(1+L6) -> 2.645939e+08 | M7: =L7*(1+M6) -> 3.5058691e+08 | N7: =M7*(1+N6) -> 4.8170642e+08
A8: Servicio | B8: Valor/mes | C8: N° Suscripción/mes | D8: Ingreso/mes | E8: Ingreso/trimestre | F8: Ingreso/anual
A9: Plan Gratuito | B9: =D4 -> 0 | C9: 3500 | D9: =B9*$C$9 -> 0 | E9: =D9*3 -> 0 | F9: =D9*12 -> 0 | H9: Especificaciones del dinero generado y de los planes existentes
A10: Plan Suscriptor | B10: =D5 -> 30000 | C10: =C9*0.09 -> 315 | D10: =B10*$C$10 -> 9450000 | E10: =D10*3 -> 28350000 | F10: =D10*12 -> 113400000 | H10: Indicador | J10: Año 1 (2027) | K10: Año 2 (2028) | L10: Año 3 (2029) | M10: Año 4 (2030) | N10: Año 5 (2031)
A11: Publicidad de Plan Gratuito | B11: 300 | C11: =C9 -> 3500 | D11: =B11*$C$11 -> 1050000 | E11: =D11*3 -> 3150000 | F11: =D11*12 -> 12600000 | H11: Valor de cada plan contando con el IPC
A12: Total | C12: =SUM(C10:C11) -> 3815 | D12: =SUM(D9:D11) -> 10500000 | E12: =SUM(E9:E11) -> 31500000 | F12: =SUM(F9:F11) -> 126000000 | H12: Valor del plan de pago | J12: =$B10 -> 30000 | K12: =J12*(1+J4) -> 31380 | L12: =K12*(1+K4) -> 32603.82 | M12: =L12*(1+L4) -> 33810.161 | N12: =M12*(1+M4) -> 34993.517
H13: Valor del plan gratuito | J13: =$B11 -> 300 | K13: =J13*(1+J4) -> 313.8 | L13: =K13*(1+K4) -> 326.0382 | M13: =L13*(1+L4) -> 338.10161 | N13: =M13*(1+M4) -> 349.93517
A14: Tabla de Financiamiento | H14: Dinero generado por cada apartado anualmente
A15: Concepto | B15: Valor | H15: Dinero aportado por suscripciones | I15: 0.9 | J15: =J$7*$I15 -> 146966400 | K15: =K$7*$I15 -> 1.850307e+08 | L15: =L$7*$I15 -> 2.3813451e+08 | M15: =M$7*$I15 -> 3.1552822e+08 | N15: =N$7*$I15 -> 4.3353578e+08
A16: Financiamiento externo | B16: ='Costos de Operación Gravables'!$B$50*0.45 -> 15790950 | H16: Dinero aportado por publicidad | I16: 0.1 | J16: =J$7*$I16 -> 16329600 | K16: =K$7*$I16 -> 20558966 | L16: =L$7*$I16 -> 26459390 | M16: =M$7*$I16 -> 35058691 | N16: =N$7*$I16 -> 48170642
A17: Aportes sociales (Fin. por socios) | B17: ='Costos de Operación Gravables'!$B$50*0.55 -> 19300050 | H17: Personas que pertenecen a cada plan anualmente
A18: Total | B18: =SUM(B16:B17) -> 35091000 | H18: Personas que pertenecen al plan de suscripciones | J18: =J15/(12*J12) -> 408.24 | K18: =K15/(12*K12) -> 491.37109 | L18: =L15/(12*L12) -> 608.65697 | M18: =M15/(12*M12) -> 777.69574 | N18: =N15/(12*N12) -> 1032.4193
H19: Personas que pertenecen al plan gratuito (publicidad) | J19: =J16/(12*J13) -> 4536 | K19: =K16/(12*K13) -> 5459.6788 | L19: =L16/(12*L13) -> 6762.8552 | M19: =M16/(12*M13) -> 8641.0638 | N19: =N16/(12*N13) -> 11471.325
A20: Contribución de los Socios | H20: Efectivo generado por cada persona que entre en el negocio (sin importar su plan) | O20: Promedio total
A21: Concepto | B21: Participación | C21: Valor | H21: Dinero generado por cada cliente en promedio al mes | J21: =(SUM(J15:J16)/12)/SUM(J18:J19) -> 2752.2936 | K21: =(SUM(K15:K16)/12)/SUM(K18:K19) -> 2878.8991 | L21: =(SUM(L15:L16)/12)/SUM(L18:L19) -> 2991.1761 | M21: =(SUM(M15:M16)/12)/SUM(M18:M19) -> 3101.8497 | N21: =(SUM(N15:N16)/12)/SUM(N18:N19) -> 3210.4144 | O21: =AVERAGE(J21:N21) -> 2986.9266
A22: David Rincón | B22: 0.5 | C22: =$B$17*B22 -> 9650025 | H22: Dinero generado por cada cliente en promedio al año | J22: =J21*12 -> 33027.523 | K22: =K21*12 -> 34546.789 | L22: =L21*12 -> 35894.114 | M22: =M21*12 -> 37222.196 | N22: =N21*12 -> 38524.973 | O22: =AVERAGE(J22:N22) -> 35843.119
A23: Leidy Marcela | B23: 0.5 | C23: =$B$17*B23 -> 9650025 | H23: Total de planes existentes anualmente sin importar su plan
A24: Total | B24: =SUM(B22:B23) -> 1 | C24: =SUM(C22:C23) -> 19300050 | H24: Total de planes existentes anualmente | J24: =SUM(J18:J19)*12 -> 59330.88 | K24: =SUM(K18:K19)*12 -> 71412.598 | L24: =SUM(L18:L19)*12 -> 88458.146 | M24: =SUM(M18:M19)*12 -> 113025.11 | N24: =SUM(N18:N19)*12 -> 150044.93
H25: Total de personas que se encuentran dentro del aplicativo en total anualmente (sin importar su plan)
H26: Total de personas dentro del aplicativo anualmente | J26: =SUM(J18:J19) -> 4944.24 | K26: =SUM(K18:K19) -> 5951.0499 | L26: =SUM(L18:L19) -> 7371.5122 | M26: =SUM(M18:M19) -> 9418.7596 | N26: =SUM(N18:N19) -> 12503.745

Sheet Costos de Operación Gravables
A1: Costos de Operación Gravables | F1: Costos de Operación Gravables
A2: Sueldos de los Empleados | F2: Sueldos de los Empleados
A3: Tipo de inversión | B3: Unidades | C3: Valor Unitario/mes | D3: Valor Total/mes | F3: Valor de 0 | G3: Conversión Anual | H3: Tasa de Crecimiento | I3: Año 0 | J3: Año 1 | K3: Año 2 | L3: Año 3 | M3: Año 4 | N3: Año 5
A4: Líder de Desarrollo | B4: 1 | C4: 3000000 | D4: =C4*B4 -> 3000000 | F4: =D6 -> 6000000 | G4: =F4*12 -> 72000000 | H4: 0.1 | I4: 0 | J4: =G4 -> 72000000 | K4: =J$4*($H$4+1) -> 79200000 | L4: =K$4*($H$4+1) -> 87120000 | M4: =L$4*($H$4+1) -> 95832000 | N4: =M$4*($H$4+1) -> 1.054152e+08
A5: Líder I+D+I | B5: 1 | C5: 3000000 | D5: =C5*B5 -> 3000000 | F5: Prestaciones y Parafiscales
A6: Total | C6: =SUM(C4:C5) -> 6000000 | D6: =SUM(D4:D5) -> 6000000 | F6: Valor de 0 | G6: Conversión Anual | H6: Tasa de Crecimiento | I6: Año 0 | J6: Año 1 | K6: Año 2 | L6: Año 3 | M6: Año 4 | N6: Año 5
A7: Prestaciones y Parafiscales | F7: =D17 -> 1788578 | G7: =F7*12 -> 21462936 | H7: 0.1 | I7: 0 | J7: =G7 -> 21462936 | K7: =J7*($H$7+1) -> 23609230 | L7: =K7*($H$7+1) -> 25970153 | M7: =L7*($H$7+1) -> 28567168 | N7: =M7*($H$7+1) -> 31423885
A8: Tipo de inversión | B8: Unidades | C8: Valor Unitario/mes | D8: Valor Total/mes | F8: Servicios e Infraestructuras
A9: Cesantias | B9: =SUM($B$4:$B$6) -> 2 | C9: 166600 | D9: =C9*B9 -> 333200 | F9: Valor de 0 | G9: Conversión Anual | H9: Tasa de Crecimiento | I9: Año 0 | J9: Año 1 | K9: Año 2 | L9: Año 3 | M9: Año 4 | N9: Año 5
A10: Intereses sobre cesantias | B10: =SUM($B$4:$B$6) -> 2 | C10: 20000 | D10: =C10*B10 -> 40000 | F10: =D23 -> 3790000 | G10: =F10*12 -> 45480000 | H10: 0.06 | I10: 0 | J10: =G10 -> 45480000 | K10: =J10*($H$10+1) -> 48208800 | L10: =K10*($H$7+1) -> 53029680 | M10: =L10*($H$7+1) -> 58332648 | N10: =M10*($H$7+1) -> 64165913
A11: Primas | B11: =SUM($B$4:$B$6) -> 2 | C11: 166600 | D11: =C11*B11 -> 333200 | F11: Otros Gastos
A12: Vacaciones | B12: =SUM($B$4:$B$6) -> 2 | C12: 73013 | D12: =C12*B12 -> 146026 | F12: Valor de 0 | G12: Conversión Anual | H12: Tasa de Crecimiento | I12: Año 0 | J12: Año 1 | K12: Año 2 | L12: Año 3 | M12: Año 4 | N12: Año 5
A13: Pensiones (AFP) | B13: =SUM($B$4:$B$6) -> 2 | C13: 210109 | D13: =C13*B13 -> 420218 | F13: 0 | G13: =F13*12 -> 0 | H13: N/A | I13: 0 | J13: 1451000
A14: Salud (EPS) | B14: =SUM($B$4:$B$6) -> 2 | C14: 148827 | D14: =C14*B14 -> 297654 | F14: SUBTOTAL
A15: Riesgos Laborales (ARL) | B15: =SUM($B$4:$B$6) -> 2 | C15: 9140 | D15: =C15*B15 -> 18280 | I15: =SUM(I4,I7,I10,I13) -> 0 | J15: =SUM(J4,J7,J10,J13) -> 140393936 | K15: =SUM(K4,K7,K10,K13) -> 1.5101803e+08 | L15: =SUM(L4,L7,L10,L13) -> 1.6611983e+08 | M15: =SUM(M4,M7,M10,M13) -> 1.8273182e+08 | N15: =SUM(N4,N7,N10,N13) -> 2.01005e+08
A16: Caja de Compensación Familiar | B16: =SUM($B$4:$B$6) -> 2 | C16: 100000 | D16: =C16*B16 -> 200000
A17: Total | C17: =SUM(C9:C16) -> 894289 | D17: =SUM(D9:D16) -> 1788578 | F17: Costos Indirectos de Fabricación
A18: Servicios e Infraestructura | F18: Papelería y Accesorios
A19: Tipo de inversión | B19: Unidades | C19: Valor Unitario/mes | D19: Valor Total/mes | F19: Valor de 0 | G19: Conversión Anual | H19: Tasa de Crecimiento | I19: Año 0 | J19: Año 1 | K19: Año 2 | L19: Año 3 | M19: Año 4 | N19: Año 5
A20: Servicio de Internet y Electricidad | B20: 1 | C20: 220000 | D20: =C20*B20 -> 220000 | F20: 13000 | G20: =F20*12 -> 156000 | H20: 0.06 | I20: 0 | J20: =G20 -> 156000 | K20: =J$20*($H$20+1) -> 165360 | L20: =K$20*($H$20+1) -> 175281.6 | M20: =L$20*($H$20+1) -> 185798.5 | N20: =M$20*($H$20+1) -> 196946.41
A21: Valor de ParqueSoft | B21: 1 | C21: 70000 | D21: =C21*B21 -> 70000
A22: Servicios de Infraestructura de TI/Hosting del Sitio | B22: 1 | C22: 3500000 | D22: =C22*B22 -> 3500000 | F22: Campañas de Marketing y Demostraciones
A23: Total | C23: =SUM(C20:C22) -> 3790000 | D23: =SUM(D20:D22) -> 3790000 | F23: Valor de 0 | G23: Conversión Anual | H23: Tasa de Crecimiento | I23: Año 0 | J23: Año 1 | K23: Año 2 | L23: Año 3 | M23: Año 4 | N23: Año 5
A24: Registros y Estatutos | F24: 120000 | G24: =F24*12 -> 1440000 | H24: 0.06 | I24: 0 | J24: =G24 -> 1440000 | K24: =J$24*($H$24+1) -> 1526400 | L24: =K$24*($H$24+1) -> 1617984 | M24: =L$24*($H$24+1) -> 1715063 | N24: =M$24*($H$24+1) -> 1817966.8 | P24: materia prima
A25: Tipo de inversión | B25: Unidades | C25: Valor Unitario/mes | D25: Valor Total/mes | F25: SUBTOTAL | P25: costos de opera. / mano de obra
A26: Registros y Estatutos | B26: 1 | C26: =B43 -> 1451000 | D26: =C26*B26 -> 1451000 | I26: =SUM(I24,I20) -> 0 | J26: =SUM(J24,J20) -> 1596000 | K26: =SUM(K24,K20) -> 1691760 | L26: =SUM(L24,L20) -> 1793265.6 | M26: =SUM(M24,M20) -> 1900861.5 | N26: =SUM(N24,N20) -> 2014913.2 | P26: costos indirectos
A27: Total | C27: =SUM(C26) -> 1451000 | D27: =SUM(D26) -> 1451000
F28: Total Costos de Fabricación y Operación
I29: =SUM(I15,I26) -> 0 | J29: =SUM(J15,J26) -> 141989936 | K29: =SUM(K15,K26) -> 1.5270979e+08 | L29: =SUM(L15,L26) -> 1.679131e+08 | M29: =SUM(M15,M26) -> 1.8463268e+08 | N29: =SUM(N15,N26) -> 2.0301991e+08
F31: Depreciación
J32: ='Amortización y Depreciación'!G18 -> 1640000 | K32: =J32 -> 1640000 | L32: =K32 -> 1640000 | M32: =L32 -> 1640000 | N32: =M32 -> 1640000
F34: TOTAL COSTOS DE FABRIACIÓN, OPERACIÓN Y DEPRECIACIÓN
J35: =SUM(J29,J32) -> 143629936 | K35: =SUM(K29,K32) -> 1.5434979e+08 | L35: =SUM(L29,L32) -> 1.695531e+08 | M35: =SUM(M29,M32) -> 1.8627268e+08 | N35: =SUM(N29,N32) -> 2.0465991e+08
A36: Activos Intangibles
A37: Registro de Marca | B37: 1288000 | F37: Especificaciones del costo de ventas por cada cliente
A38: Estatutos | B38: 30000 | F38: Cantidad de planes anualmente y costos de operación y gastos
A39: Registro Cámara de Comercio de Bogotá | B39: 69000 | F39: Indicador | I39: Año 0 | J39: Año 1 | K39: Año 2 | L39: Año 3 | M39: Año 4 | N39: Año 5
A40: Inscripción de Libros Contables | B40: 64000 | F40: Total de planes existentes anualmente | J40: ='Proyección de Ventas e Incremen'!J24 -> 59330.88 | K40: ='Proyección de Ventas e Incremen'!K24 -> 71412.598 | L40: ='Proyección de Ventas e Incremen'!L24 -> 88458.146 | M40: ='Proyección de Ventas e Incremen'!M24 -> 113025.11 | N40: ='Proyección de Ventas e Incremen'!N24 -> 150044.93
A41: Apertura de Cuentas Bancarias | B41: N/A | F41: Costos de mano de obra, indirectos y depreciación | J41: =J35 -> 143629936 | K41: =K35 -> 1.5434979e+08 | L41: =L35 -> 1.695531e+08 | M41: =M35 -> 1.8627268e+08 | N41: =N35 -> 2.0465991e+08
A42: Formulario Único de Registro Empresarial | B42: N/A | F42: Costos de operación por cada cliente
...

Sheet Amortización y Depreciación
A1: Amortización y Depreciación | D1: Amortización del Crédito
A2: Préstamo (en Banco GNB Sudameris) | D2: Período | E2: Saldo | F2: Interés | G2: Pago al crédito | H2: Abono al capital | I2: Saldo final
A3: Concepto | B3: Unidades | D3: 0 (Año 0) | E3: =B4 -> 15790950 | F3: 0 | G3: 0 | H3: 0 | I3: =E3 -> 15790950
A4: Valor del préstamo | B4: ='Proyección de Ventas e Incremen'!B16 -> 15790950 | D4: 1 (Año 1) | E4: =I3 -> 15790950 | F4: =E4*$B$7 -> 2627614.1 | G4: =$B$8 -> 5715545.4 | H4: =G4-F4 -> 3087931.3 | I4: =E4-H4 -> 12703019
A5: Cuota inicial | B5: 0 | D5: 2 (Año 2) | E5: =I4 -> 12703019 | F5: =E5*$B$7 -> 2113782.3 | G5: =$B$8 -> 5715545.4 | H5: =G5-F5 -> 3601763.1 | I5: =E5-H5 -> 9101255.6
A6: Plazo de meses/períodos | B6: 48 meses | D6: 3 (Año 3) | E6: =I5 -> 9101255.6 | F6: =E6*$B$7 -> 1514448.9 | G6: =$B$8 -> 5715545.4 | H6: =G6-F6 -> 4201096.4 | I6: =E6-H6 -> 4900159.2
A7: Tasa de interés (anualmente) | B7: 0.1664 | D7: 4 (Año 4) | E7: =I6 -> 4900159.2 | F7: =E7*$B$7 -> 815386.49 | G7: =$B$8 -> 5715545.4 | H7: =G7-F7 -> 4900158.9 | I7: =E7-H7 -> 0.33650471
A8: Pago anual | B8: =((B4*1.44780279145524)/4) -> 5715545.4 | D8: 5 (Año 5) | E8: =I7 -> 0.33650471 | F8: =E8*$B$7 -> 0.055994384 | G8: 0 | H8: =G8-F8 -> -0.055994384 | I8: =E8-H8 -> 0.3924991 | K8: =SUM(G4:G7) -> 22862181
A9: Pago mensual | B9: =B8/12 -> 476295.45
D10: Depreciación (acumulada)
D11: Activos Fijos | E11: Vida Útil | F11: Valor Inicial | G11: Año 1 | H11: Año 2 | I11: Año 3 | J11: Año 4 | K11: Año 5
D12: Computador 1 | E12: 5 años | F12: ='Inversión Inicial'!$C$13 -> 3000000 | G12: =$F12*G$19 -> 600000 | H12: =$F12*H$19 -> 1200000 | I12: =$F12*I$19 -> 1800000 | J12: =$F12*J$19 -> 2400000 | K12: =$F12*K$19 -> 3000000
D13: Perifericos 1 | E13: 5 años | F13: ='Inversión Inicial'!$C$15 -> 300000 | G13: =$F13*G$19 -> 60000 | H13: =$F13*H$19 -> 120000 | I13: =$F13*I$19 -> 180000 | J13: =$F13*J$19 -> 240000 | K13: =$F13*K$19 -> 300000
D14: Monitor 1 | E14: 5 años | F14: ='Inversión Inicial'!C14 -> 800000 | G14: =$F14*G$19 -> 160000 | H14: =$F14*H$19 -> 320000 | I14: =$F14*I$19 -> 480000 | J14: =$F14*J$19 -> 640000 | K14: =$F14*K$19 -> 800000
D15: Computador 2 | E15: 5 años | F15: ='Inversión Inicial'!$C$13 -> 3000000 | G15: =$F15*G$19 -> 600000 | H15: =$F15*H$19 -> 1200000 | I15: =$F15*I$19 -> 1800000 | J15: =$F15*J$19 -> 2400000 | K15: =$F15*K$19 -> 3000000
D16: Perifericos 2 | E16: 5 años | F16: ='Inversión Inicial'!$C$15 -> 300000 | G16: =$F16*G$19 -> 60000 | H16: =$F16*H$19 -> 120000 | I16: =$F16*I$19 -> 180000 | J16: =$F16*J$19 -> 240000 | K16: =$F16*K$19 -> 300000
D17: Monitor 2 | E17: 5 años | F17: ='Inversión Inicial'!C14 -> 800000 | G17: =$F17*G$19 -> 160000 | H17: =$F17*H$19 -> 320000 | I17: =$F17*I$19 -> 480000 | J17: =$F17*J$19 -> 640000 | K17: =$F17*K$19 -> 800000
D18: Depreciación Total | G18: =SUM(G12:G17) -> 1640000 | H18: =SUM(H12:H17) -> 3280000 | I18: =SUM(I12:I17) -> 4920000 | J18: =SUM(J12:J17) -> 6560000 | K18: =SUM(K12:K17) -> 8200000
D19: Tasa de Depreciación Total | G19: 0.2 | H19: 0.4 | I19: 0.6 | J19: 0.8 | K19: 1
D21: Depreciación
D22: Activos Fijos | E22: Vida Útil | F22: Valor Inicial | G22: Año 1 | H22: Año 2 | I22: Año 3 | J22: Año 4 | K22: Año 5
D23: Computador 1 | E23: 5 años | F23: ='Inversión Inicial'!$C$13 -> 3000000 | G23: =$F23-($F23*G$30) -> 2400000 | H23: =$F23-($F23*H$30) -> 1800000 | I23: =$F23-($F23*I$30) -> 1200000 | J23: =$F23-($F23*J$30) -> 600000 | K23: =$F23-($F23*K$30) -> 0
D24: Perifericos 1 | E24: 5 años | F24: ='Inversión Inicial'!$C$15 -> 300000 | G24: =$F24-($F24*G$30) -> 240000 | H24: =$F24-($F24*H$30) -> 180000 | I24: =$F24-($F24*I$30) -> 120000 | J24: =$F24-($F24*J$30) -> 60000 | K24: =$F24-($F24*K$30) -> 0
D25: Monitor 1 | E25: 5 años | F25: ='Inversión Inicial'!C14 -> 800000 | G25: =$F25-($F25*G$30) -> 640000 | H25: =$F25-($F25*H$30) -> 480000 | I25: =$F25-($F25*I$30) -> 320000 | J25: =$F25-($F25*J$30) -> 160000 | K25: =$F25-($F25*K$30) -> 0
D26: Computador 2 | E26: 5 años | F26: ='Inversión Inicial'!$C$13 -> 3000000 | G26: =$F26-($F26*G$30) -> 2400000 | H26: =$F26-($F26*H$30) -> 1800000 | I26: =$F26-($F26*I$30) -> 1200000 | J26: =$F26-($F26*J$30) -> 600000 | K26: =$F26-($F26*K$30) -> 0
D27: Perifericos 2 | E27: 5 años | F27: ='Inversión Inicial'!$C$15 -> 300000 | G27: =$F27-($F27*G$30) -> 240000 | H27: =$F27-($F27*H$30) -> 180000 | I27: =$F27-($F27*I$30) -> 120000 | J27: =$F27-($F27*J$30) -> 60000 | K27: =$F27-($F27*K$30) -> 0
D28: Monitor 2 | E28: 5 años | F28: ='Inversión Inicial'!$C$14 -> 800000 | G28: =$F28-($F28*G$30) -> 640000 | H28: =$F28-($F28*H$30) -> 480000 | I28: =$F28-($F28*I$30) -> 320000 | J28: =$F28-($F28*J$30) -> 160000 | K28: =$F28-($F28*K$30) -> 0
D29: Depreciación Total | G29: =SUM(G23:G28) -> 6560000 | H29: =SUM(H23:H28) -> 4920000 | I29: =SUM(I23:I28) -> 3280000 | J29: =SUM(J23:J28) -> 1640000 | K29: =SUM(K23:K28) -> 0
D30: Tasa de Depreciación Total | G30: 0.2 | H30: 0.4 | I30: 0.6 | J30: 0.8 | K30: 1

Sheet Balance General
A1: BALANCE GENERAL PROYECTADO
A2: EDUFINANZAS S.A.S.
A4: AÑOS | C4: AÑO 0 | D4: AÑO 1 | E4: AÑO 2 | F4: AÑO 3 | G4: AÑO 4 | H4: AÑO 5
A5: ACTIVOS
A6: ACTIVOS CORRIENTES
B7: Efectivo y equivalente de efectivo | C7: ='Proyección de Ventas e Incremen'!B18 -> 35091000 | D7: ='Proyección de Ventas e Incremen'!J7 -> 163296000 | E7: ='Proyección de Ventas e Incremen'!K7 -> 2.0558966e+08 | F7: ='Proyección de Ventas e Incremen'!L7 -> 2.645939e+08 | G7: ='Proyección de Ventas e Incremen'!M7 -> 3.5058691e+08 | H7: ='Proyección de Ventas e Incremen'!N7 -> 4.8170642e+08
B8: Total Activos Corrientes | C8: =SUM(C7:C7) -> 35091000 | D8: =SUM(D7:D7) -> 163296000 | E8: =SUM(E7:E7) -> 2.0558966e+08 | F8: =SUM(F7:F7) -> 2.645939e+08 | G8: =SUM(G7:G7) -> 3.5058691e+08 | H8: =SUM(H7:H7) -> 4.8170642e+08
A10: ACTIVOS NO CORRIENTES
B11: Propiedad, planta y Equipos | C11: 0 | D11: 8200000 | E11: 8200000 | F11: 8200000 | G11: 8200000 | H11: 8200000
B12: Depreciación | C12: 0 | D12: =-'Flujo de Caja'!D25 -> -1640000 | E12: =-'Flujo de Caja'!E25 -> -1640000 | F12: =-'Flujo de Caja'!F25 -> -1640000 | G12: =-'Flujo de Caja'!G25 -> -1640000 | H12: =-'Flujo de Caja'!H25 -> -1640000
B13: Intangibles | C13: 0 | D13: 1451000 | E13: =D13 -> 1451000 | F13: =E13 -> 1451000 | G13: =F13 -> 1451000 | H13: =G13 -> 1451000
B14: Total Activos No Corrientes | C14: =C11+C13 -> 0 | D14: =SUM(D11:D13) -> 8011000 | E14: =SUM(E11:E13) -> 8011000 | F14: =SUM(F11:F13) -> 8011000 | G14: =SUM(G11:G13) -> 8011000 | H14: =SUM(H11:H13) -> 8011000
A16: TOTAL ACTIVO | C16: =C8+C14 -> 35091000 | D16: =D8+D14 -> 171307000 | E16: =E8+E14 -> 2.1360066e+08 | F16: =F8+F14 -> 2.726049e+08 | G16: =G8+G14 -> 3.5859791e+08 | H16: =H8+H14 -> 4.8971742e+08
A17: PASIVOS
A18: PASIVOS CORRIENTES
B19: Acreedores comerciales y otras cuentas por pagar | C19: 0 | D19: ='Costos de Operación Gravables'!J10+'Costos de Operación Gravables'!J26+'Costos de Operación Gravables'!J13 -> 48527000 | E19: ='Costos de Operación Gravables'!K10+'Costos de Operación Gravables'!K26+'Costos de Operación Gravables'!K13 -> 49900560 | F19: ='Costos de Operación Gravables'!L10+'Costos de Operación Gravables'!L26+'Costos de Operación Gravables'!L13 -> 54822946 | G19: ='Costos de Operación Gravables'!M10+'Costos de Operación Gravables'!M26+'Costos de Operación Gravables'!M13 -> 60233510 | H19: ='Costos de Operación Gravables'!N10+'Costos de Operación Gravables'!N26+'Costos de Operación Gravables'!N13 -> 66180826
B20: Salarios y beneficios a empleados | C20: ='Costos de Operación Gravables'!I4 -> 0 | D20: ='Costos de Operación Gravables'!J4+'Costos de Operación Gravables'!J7 -> 93462936 | E20: ='Costos de Operación Gravables'!K4+'Costos de Operación Gravables'!K7 -> 1.0280923e+08 | F20: ='Costos de Operación Gravables'!L4+'Costos de Operación Gravables'!L7 -> 1.1309015e+08 | G20: ='Costos de Operación Gravables'!M4+'Costos de Operación Gravables'!M7 -> 1.2439917e+08 | H20: ='Costos de Operación Gravables'!N4+'Costos de Operación Gravables'!N7 -> 1.3683908e+08
B21: Total Pasivos Corrientes | C21: =SUM(C19:C20) -> 0 | D21: =SUM(D19:D20) -> 141989936 | E21: =SUM(E19:E20) -> 1.5270979e+08 | F21: =SUM(F19:F20) -> 1.679131e+08 | G21: =SUM(G19:G20) -> 1.8463268e+08 | H21: =SUM(H19:H20) -> 2.0301991e+08
A23: PASIVOS NO CORRIENTES
B24: Préstamo | C24: ='Estado de Resultados'!C18 -> 0 | D24: ='Estado de Resultados'!D18 -> 5715545.4 | E24: ='Estado de Resultados'!E18 -> 5715545.4 | F24: ='Estado de Resultados'!F18 -> 5715545.4 | G24: ='Estado de Resultados'!G18 -> 5715545.4 | H24: ='Estado de Resultados'!H18 -> 0
B25: Total Pasivos No Corrientes | C25: =SUM(C24) -> 0 | D25: =SUM(D24) -> 5715545.4 | E25: =SUM(E24) -> 5715545.4 | F25: =SUM(F24) -> 5715545.4 | G25: =SUM(G24) -> 5715545.4 | H25: =SUM(H24) -> 0
A27: TOTAL PASIVOS | C27: =C21+C25 -> 0 | D27: =D21+D25 -> 1.4770548e+08 | E27: =E21+E25 -> 1.5842533e+08 | F27: =F21+F25 -> 1.7362864e+08 | G27: =G21+G25 -> 1.9034822e+08 | H27: =H21+H25 -> 2.0301991e+08
A29: CAPITAL
B30: Capital Social | C30: ='Proyección de Ventas e Incremen'!B18 -> 35091000 | D30: =C30 -> 35091000 | E30: =D30 -> 35091000 | F30: =E30 -> 35091000 | G30: =F30 -> 35091000 | H30: =G30 -> 35091000
B31: Resultados acumulados/dividendos | C31: 0 | D31: -22566468 | E31: -11564645 | F31: 3706150 | G31: 27888751 | H31: 69278600
B32: Utilidad o Pérdida del Ejercicio | C32: 0 | D32: ='Estado de Resultados'!D24 -> 11076987 | E32: ='Estado de Resultados'!E24 -> 31648974 | F32: ='Estado de Resultados'!F24 -> 60179105 | G32: ='Estado de Resultados'!G24 -> 1.0526994e+08 | H32: ='Estado de Resultados'!H24 -> 1.8232791e+08
A34: TOTAL CAPITAL | C34: =SUM(C30:C32) -> 35091000 | D34: =SUM(D30:D32) -> 23601519 | E34: =SUM(E30:E32) -> 55175329 | F34: =SUM(F30:F32) -> 98976255 | G34: =SUM(G30:G32) -> 1.6824969e+08 | H34: =SUM(H30:H32) -> 2.8669751e+08
A36: SUMA PASIVOS + CAPITAL | C36: =C27+C34 -> 35091000 | D36: =D27+D34 -> 1.71307e+08 | E36: =E27+E34 -> 2.1360066e+08 | F36: =F27+F34 -> 2.726049e+08 | G36: =G27+G34 -> 3.5859791e+08 | H36: =H27+H34 -> 4.8971742e+08

Sheet Estado de Resultados
A1: ESTADO DE RESULTADOS PROYECTADOS
A2: EDUFINANZAS S.A.S.
A4: TRIMESTRE | C4: AÑO 0 | D4: AÑO 1 | E4: AÑO 2 | F4: AÑO 3 | G4: AÑO 4 | H4: AÑO 5
A5: UTILIDAD BRUTA
B6: Ingresos obtenidos por actividades cotidianas | D6: ='Proyección de Ventas e Incremen'!J7 -> 163296000 | E6: ='Proyección de Ventas e Incremen'!K7 -> 2.0558966e+08 | F6: ='Proyección de Ventas e Incremen'!L7 -> 2.645939e+08 | G6: ='Proyección de Ventas e Incremen'!M7 -> 3.5058691e+08 | H6: ='Proyección de Ventas e Incremen'!N7 -> 4.8170642e+08
B7: Costo de ventas (mantenimiento de infraestructura de TI) | D7: ='Costos de Operación Gravables'!J10 -> 45480000 | E7: ='Costos de Operación Gravables'!K10 -> 48208800 | F7: ='Costos de Operación Gravables'!L10 -> 53029680 | G7: ='Costos de Operación Gravables'!M10 -> 58332648 | H7: ='Costos de Operación Gravables'!N10 -> 64165913
B8: Total de Utilidad Bruta | C8: =SUM(C6:C7) -> 0 | D8: =D6-D7 -> 117816000 | E8: =E6-E7 -> 1.5738086e+08 | F8: =F6-F7 -> 2.1156422e+08 | G8: =G6-G7 -> 2.9225427e+08 | H8: =H6-H7 -> 4.1754051e+08
A10: UTILIDAD OPERATIVA
B11: Gastos de mano obra fija | D11: ='Costos de Operación Gravables'!J4 -> 72000000 | E11: ='Costos de Operación Gravables'!K4 -> 79200000 | F11: ='Costos de Operación Gravables'!L4 -> 87120000 | G11: ='Costos de Operación Gravables'!M4 -> 95832000 | H11: ='Costos de Operación Gravables'!N4 -> 1.054152e+08
B12: Gastos en beneficios (prestaciones y parafiscales) | D12: ='Costos de Operación Gravables'!J7 -> 21462936 | E12: ='Costos de Operación Gravables'!K7 -> 23609230 | F12: ='Costos de Operación Gravables'!L7 -> 25970153 | G12: ='Costos de Operación Gravables'!M7 -> 28567168 | H12: ='Costos de Operación Gravables'!N7 -> 31423885
B13: Gastos de administración (papelería) | D13: ='Costos de Operación Gravables'!J20 -> 156000 | E13: ='Costos de Operación Gravables'!K20 -> 165360 | F13: ='Costos de Operación Gravables'!L20 -> 175281.6 | G13: ='Costos de Operación Gravables'!M20 -> 185798.5 | H13: ='Costos de Operación Gravables'!N20 -> 196946.41
B14: Gastos de marketing | D14: ='Costos de Operación Gravables'!J24 -> 1440000 | E14: ='Costos de Operación Gravables'!K24 -> 1526400 | F14: ='Costos de Operación Gravables'!L24 -> 1617984 | G14: ='Costos de Operación Gravables'!M24 -> 1715063 | H14: ='Costos de Operación Gravables'!N24 -> 1817966.8
B15: Total de Utilidad Operativa | C15: =C8-C13 -> 0 | D15: =D8-SUM(D11:D14) -> 22757064 | E15: =E8-SUM(E11:E13) -> 54406274 | F15: =F8-SUM(F11:F13) -> 98298783 | G15: =G8-SUM(G11:G13) -> 1.676693e+08 | H15: =H8-SUM(H11:H13) -> 2.8050448e+08
A17: RESULTADO ANTES DE IMPUESTOS
B18: Gastos financieros (cuotas de préstamo) | D18: ='Amortización y Depreciación'!G4 -> 5715545.4 | E18: ='Amortización y Depreciación'!G5 -> 5715545.4 | F18: ='Amortización y Depreciación'!G6 -> 5715545.4 | G18: ='Amortización y Depreciación'!G7 -> 5715545.4
B19: Total de Utilidad antes de Impuestos | C19: =C15-C18 -> 0 | D19: =D15-D18 -> 17041519 | E19: =E15-E18 -> 48690729 | F19: =F15-F18 -> 92583238 | G19: =G15-G18 -> 1.6195375e+08 | H19: =H15-H18 -> 2.8050448e+08
A21: IMPUESTOS
B22: Impuestos | D22: =D19*0.35 -> 5964531.5 | E22: =E19*0.35 -> 17041755 | F22: =F19*0.35 -> 32404133 | G22: =G19*0.35 -> 56683814 | H22: =H19*0.35 -> 98176567
A24: UTILIDAD NETA | C24: =C19-C22 -> 0 | D24: =D19-D22 -> 11076987 | E24: =E19-E22 -> 31648974 | F24: =F19-F22 -> 60179105 | G24: =G19-G22 -> 1.0526994e+08 | H24: =H19-H22 -> 1.8232791e+08

Sheet Flujo de Caja
A1: FLUJO DE CAJA PROYECTADO
A2: EDUFINANZAS S.A.S.
A4: TRIMESTRE | C4: AÑO 0 | D4: AÑO 1 | E4: AÑO 2 | F4: AÑO 3 | G4: AÑO 4 | H4: AÑO 5
A5: ENTRADAS
B6: Aportaciones de socios | C6: ='Proyección de Ventas e Incremen'!B17 -> 19300050
B7: Aportaciones de financiamiento bancario | C7: ='Proyección de Ventas e Incremen'!B16 -> 15790950
B8: Ingresos obtenidos del negocio | D8: ='Proyección de Ventas e Incremen'!J7 -> 163296000 | E8: ='Proyección de Ventas e Incremen'!K7 -> 2.0558966e+08 | F8: ='Proyección de Ventas e Incremen'!L7 -> 2.645939e+08 | G8: ='Proyección de Ventas e Incremen'!M7 -> 3.5058691e+08 | H8: ='Proyección de Ventas e Incremen'!N7 -> 4.8170642e+08
B9: Total Entradas/Ingresos | C9: =SUM(C6:C8) -> 35091000 | D9: =SUM(D6:D8) -> 163296000 | E9: =SUM(E6:E8) -> 2.0558966e+08 | F9: =SUM(F6:F8) -> 2.645939e+08 | G9: =SUM(G6:G8) -> 3.5058691e+08 | H9: =SUM(H6:H8) -> 4.8170642e+08
A11: SALIDAS
B12: Inversiones hacia activos fijos | C12: =SUM('Costos de Operación Gravables'!B47:B49) -> 35091000
B13: Inversiones hacia servicios e infraestructura TI | D13: ='Costos de Operación Gravables'!J10 -> 45480000 | E13: ='Costos de Operación Gravables'!K10 -> 48208800 | F13: ='Costos de Operación Gravables'!L10 -> 53029680 | G13: ='Costos de Operación Gravables'!M10 -> 58332648 | H13: ='Costos de Operación Gravables'!N10 -> 64165913
B14: Papelería y accesorios | D14: ='Costos de Operación Gravables'!J20 -> 156000 | E14: ='Costos de Operación Gravables'!K20 -> 165360 | F14: ='Costos de Operación Gravables'!L20 -> 175281.6 | G14: ='Costos de Operación Gravables'!M20 -> 185798.5 | H14: ='Costos de Operación Gravables'!N20 -> 196946.41
B15: Gastos en marketing | D15: ='Costos de Operación Gravables'!J24 -> 1440000 | E15: ='Costos de Operación Gravables'!K24 -> 1526400 | F15: ='Costos de Operación Gravables'!L24 -> 1617984 | G15: ='Costos de Operación Gravables'!M24 -> 1715063 | H15: ='Costos de Operación Gravables'!N24 -> 1817966.8
B16: Depreciación anual | D16: ='Amortización y Depreciación'!G18 -> 1640000 | E16: =D16 -> 1640000 | F16: =E16 -> 1640000 | G16: =F16 -> 1640000 | H16: =G16 -> 1640000
B17: Salarios a empleados | D17: ='Costos de Operación Gravables'!J4 -> 72000000 | E17: ='Costos de Operación Gravables'!K4 -> 79200000 | F17: ='Costos de Operación Gravables'!L4 -> 87120000 | G17: ='Costos de Operación Gravables'!M4 -> 95832000 | H17: ='Costos de Operación Gravables'!N4 -> 1.054152e+08
B18: Prestaciones sociales y parafiscales | D18: ='Costos de Operación Gravables'!J7 -> 21462936 | E18: ='Costos de Operación Gravables'!K7 -> 23609230 | F18: ='Costos de Operación Gravables'!L7 -> 25970153 | G18: ='Costos de Operación Gravables'!M7 -> 28567168 | H18: ='Costos de Operación Gravables'!N7 -> 31423885
B19: Pago de cuotas de préstamo | D19: ='Amortización y Depreciación'!G4 -> 5715545.4 | E19: ='Amortización y Depreciación'!G5 -> 5715545.4 | F19: ='Amortización y Depreciación'!G6 -> 5715545.4 | G19: ='Amortización y Depreciación'!G7 -> 5715545.4
B20: Impuestos | D20: ='Estado de Resultados'!D22 -> 5964531.5 | E20: ='Estado de Resultados'!E22 -> 17041755 | F20: ='Estado de Resultados'!F22 -> 32404133 | G20: ='Estado de Resultados'!G22 -> 56683814 | H20: ='Estado de Resultados'!H22 -> 98176567
B21: Total Salidas | C21: =SUM(C12:C20) -> 35091000 | D21: =SUM(D12:D20) -> 1.5385901e+08 | E21: =SUM(E12:E20) -> 1.7710709e+08 | F21: =SUM(F12:F20) -> 2.0767278e+08 | G21: =SUM(G12:G20) -> 2.4867204e+08 | H21: =SUM(H12:H20) -> 3.0283648e+08
A23: Disponibilidad de efectivo | C23: =-C21 -> -35091000 | D23: =D9-D21 -> 9436987.1 | E23: =E9-E21 -> 28482574 | F23: =F9-F21 -> 56921121 | G23: =G9-G21 -> 1.0191488e+08 | H23: =H9-H21 -> 1.7886994e+08
B25: Depreciaciones | D25: =D16 -> 1640000 | E25: =D25 -> 1640000 | F25: =E25 -> 1640000 | G25: =F25 -> 1640000 | H25: =G25 -> 1640000
A27: FLUJOS DE EFECTIVO | C27: =C23 -> -35091000 | D27: =D23+D25 -> 11076987 | E27: =E23+E25 -> 30122574 | F27: =F23+F25 -> 58561121 | G27: =G23+G25 -> 1.0355488e+08 | H27: =H23+H25 -> 1.8050994e+08

Sheet Flujo de Efectivo
A1: FLUJO DE EFECTIVO
A2: EDUFINANZAS S.A.S.
A4: TRIMESTRE | C4: AÑO 0 | D4: AÑO 1 | E4: AÑO 2 | F4: AÑO 3 | G4: AÑO 4 | H4: AÑO 5
A5: FLUJO DE CAJA DE OPERACIÓN
B6: Utilidad del ejercicio | C6: ='Flujo de Caja'!C27 -> -35091000 | D6: ='Flujo de Caja'!D27 -> 11076987 | E6: ='Flujo de Caja'!E27 -> 30122574 | F6: ='Flujo de Caja'!F27 -> 58561121 | G6: ='Flujo de Caja'!G27 -> 1.0355488e+08 | H6: ='Flujo de Caja'!H27 -> 1.8050994e+08
B7: Depreciaciones de equipos | C7: 0 | D7: ='Flujo de Caja'!D16 -> 1640000 | E7: ='Flujo de Caja'!E16 -> 1640000 | F7: ='Flujo de Caja'!F16 -> 1640000 | G7: ='Flujo de Caja'!G16 -> 1640000 | H7: ='Flujo de Caja'!H16 -> 1640000
B8: Cuotas de pago del préstamo | C8: 0 | D8: ='Amortización y Depreciación'!H4 -> 3087931.3 | E8: ='Amortización y Depreciación'!H5 -> 3601763.1 | F8: ='Amortización y Depreciación'!H6 -> 4201096.4 | G8: ='Amortización y Depreciación'!H7 -> 4900158.9 | H8: ='Amortización y Depreciación'!H8 -> -0.055994384
B9: Intereses del préstamo | C9: 0 | D9: ='Amortización y Depreciación'!F4 -> 2627614.1 | E9: ='Amortización y Depreciación'!F5 -> 2113782.3 | F9: ='Amortización y Depreciación'!F6 -> 1514448.9 | G9: ='Amortización y Depreciación'!F7 -> 815386.49 | H9: ='Amortización y Depreciación'!F8 -> 0.055994384
B10: Impuestos de la renta | C10: ='Flujo de Caja'!C20 -> 0 | D10: ='Flujo de Caja'!D20 -> 5964531.5 | E10: ='Flujo de Caja'!E20 -> 17041755 | F10: ='Flujo de Caja'!F20 -> 32404133 | G10: ='Flujo de Caja'!G20 -> 56683814 | H10: ='Flujo de Caja'!H20 -> 98176567
B11: Gastos de utiles y papelería | C11: 0 | D11: ='Costos de Operación Gravables'!J20 -> 156000 | E11: ='Costos de Operación Gravables'!K20 -> 165360 | F11: ='Costos de Operación Gravables'!L20 -> 175281.6 | G11: ='Costos de Operación Gravables'!M20 -> 185798.5 | H11: ='Costos de Operación Gravables'!N20 -> 196946.41
B12: Gastos en marketing | C12: 0 | D12: ='Costos de Operación Gravables'!J24 -> 1440000 | E12: ='Costos de Operación Gravables'!K24 -> 1526400 | F12: ='Costos de Operación Gravables'!L24 -> 1617984 | G12: ='Costos de Operación Gravables'!M24 -> 1715063 | H12: ='Costos de Operación Gravables'!N24 -> 1817966.8
B13: Flujo de Caja Operativo Neto | C13: =SUM(C6:C12) -> -35091000 | D13: =SUM(D6:D12) -> 25993064 | E13: =SUM(E6:E12) -> 56211634 | F13: =SUM(F6:F12) -> 1.0011407e+08 | G13: =SUM(G6:G12) -> 1.694951e+08 | H13: =SUM(H6:H12) -> 2.8234142e+08
A15: FLUJO DE CAJA DE INVERSIÓN
B16: Inversión de equipos de computación | C16: ='Inversión Inicial'!B5 -> 8200000 | D16: =0 -> 0 | E16: =0 -> 0 | F16: =0 -> 0 | G16: =0 -> 0 | H16: =0 -> 0
B17: Flujo de Caja de Inversión Neto | C17: =SUM(C16:C16) -> 8200000 | D17: =SUM(D16:D16) -> 0 | E17: =SUM(E16:E16) -> 0 | F17: =SUM(F16:F16) -> 0 | G17: =SUM(G16:G16) -> 0 | H17: =SUM(H16:H16) -> 0
A19: FLUJO DE CAJA DE FINANCIAMIENTO
B20: Capital social | C20: ='Proyección de Ventas e Incremen'!B17 -> 19300050 | D20: =0 -> 0 | E20: =0 -> 0 | F20: =0 -> 0 | G20: =0 -> 0 | H20: =0 -> 0
B21: Desembolso pasivos a largo plazo | C21: ='Proyección de Ventas e Incremen'!B16 -> 15790950 | D21: =0 -> 0 | E21: =0 -> 0 | F21: =0 -> 0 | G21: =0 -> 0 | H21: =0 -> 0
B22: Amortizaciones | C22: =C8 -> 0 | D22: =D8 -> 3087931.3 | E22: =E8 -> 3601763.1 | F22: =F8 -> 4201096.4 | G22: =G8 -> 4900158.9 | H22: =H8 -> -0.055994384
B23: Intereses | C23: =C9 -> 0 | D23: =D9 -> 2627614.1 | E23: =E9 -> 2113782.3 | F23: =F9 -> 1514448.9 | G23: =G9 -> 815386.49 | H23: =H9 -> 0.055994384
B24: Pago de dividendos | C24: 0 | D24: =ABS('Balance General'!$D$31-'Balance General'!D31) -> 0 | E24: =ABS('Balance General'!$D$31-'Balance General'!E31) -> 11001823 | F24: =ABS('Balance General'!$D$31-'Balance General'!F31) -> 26272618 | G24: =ABS('Balance General'!$D$31-'Balance General'!G31) -> 50455219 | H24: =ABS('Balance General'!$D$31-'Balance General'!H31) -> 91845068
B25: Flujo de Caja de Financiamiento Neto | C25: =SUM(C20:C24) -> 35091000 | D25: =SUM(D20:D24) -> 5715545.4 | E25: =SUM(E20:E24) -> 16717368 | F25: =SUM(F20:F24) -> 31988163 | G25: =SUM(G20:G24) -> 56170764 | H25: =SUM(H20:H24) -> 91845068

Sheet Costos Fijos y Punto de Equil.
B2: Estimaciones del Punto de Equilibrio | G2: Costos Fijos y Variables
B3: Ventas Iniciales Planteadas (anual) | C3: =SUM('Proyección de Ventas e Incremen'!J18:J19) -> 4944.24 | G3: Costos y/o gastos | I3: Administración y ventas | J3: Producción
B4: Costo de producción por unidad | C4: =J11/C3 -> 31599.868 | G4: Número de producción | I4: 0 | J4: ='Costos de Operación Gravables'!J15 -> 140393936
B5: Costo por unidad | C5: =SUM(I11:J11)/C3 -> 31954.947 | G5: Numero permanente (100%) | H5: =J4 -> 140393936 | I5: 0 | J5: 0
G6: Otros gastos administrativos | I6: ='Costos de Operación Gravables'!J26 -> 1596000 | J6: 0
B7: Unidad de suscripcion (1 unidad = 33.027 COP por año) | G7: Depreciación de producción | I7: 0 | J7: ='Amortización y Depreciación'!G18 -> 1640000
B8: Valores | C8: Precios netos COP | D8: Conversion | G8: Depreciación de administración | I8: 0 | J8: 0
B9: Total Costos | C9: =SUM(I11:J11) -> 1.5799293e+08 | D9: =C9/4944 -> 31956.499 | G9: Subtotal | I9: =SUM(I4:I8) -> 1596000 | J9: =SUM(J4:J8) -> 142033936
B10: Total Ingresos | C10: ='Proyección de Ventas e Incremen'!J7 -> 163296000 | D10: =C10/4944 -> 33029.126 | G10: Imprevistos | H10: 0.1 | I10: =I9*$H$10 -> 159600 | J10: =J9*$H$10 -> 14203394
G11: Total | I11: =I9+I10 -> 1755600 | J11: =J9+J10 -> 1.5623733e+08
B12: Punto de Equilibrio
B13: Costo por Unidad | C13: =C9/C3 -> 31954.947
B14: Unidades mínimas vendidas | C14: 4784
B15: Ventas anuales mínimas | C15: =33027*C14 -> 158001168

Sheet Grafica Punto de Equilibrio
D2: 33027
C3: Costos | D3: Ventas
B4: 0 | C4: =SUM('Costos Fijos y Punto de Equil.'!I11:J11) -> 1.5799293e+08 | D4: =$D$2*B4 -> 0
B5: 1 | C5: =$C4 -> 1.5799293e+08 | D5: =$D$2*B5 -> 33027
B6: 2 | C6: =$C5 -> 1.5799293e+08 | D6: =$D$2*B6 -> 66054
B7: 3 | C7: =$C6 -> 1.5799293e+08 | D7: =$D$2*B7 -> 99081
B8: 4 | C8: =$C7 -> 1.5799293e+08 | D8: =$D$2*B8 -> 132108
B9: 5 | C9: =$C8 -> 1.5799293e+08 | D9: =$D$2*B9 -> 165135
B10: 6 | C10: =$C9 -> 1.5799293e+08 | D10: =$D$2*B10 -> 198162
B11: 7 | C11: =$C10 -> 1.5799293e+08 | D11: =$D$2*B11 -> 231189
B12: 8 | C12: =$C11 -> 1.5799293e+08 | D12: =$D$2*B12 -> 264216
B13: 9 | C13: =$C12 -> 1.5799293e+08 | D13: =$D$2*B13 -> 297243
B14: 10 | C14: =$C13 -> 1.5799293e+08 | D14: =$D$2*B14 -> 330270
B15: 11 | C15: =$C14 -> 1.5799293e+08 | D15: =$D$2*B15 -> 363297
B16: 12 | C16: =$C15 -> 1.5799293e+08 | D16: =$D$2*B16 -> 396324
... B6004: 6000 | C6004: =$C6003 -> 1.5799293e+08 | D6004: =$D$2*B6004 -> 198162000

Sheet Indicadores Financieros
B2: Indicadores financieros | I2: Flujo de caja libre | L2: VAN, TIR y RBC
B3: Período | C3: Año 1 | D3: Año 2 | E3: Año 3 | F3: Año 4 | G3: Año 5 | I3: Período | J3: Flujo de efectivo | L3: Tipo | M3: Valor
B4: Liquidez - razón corriente | C4: ='Balance General'!D8/'Balance General'!D21 -> 1.1500533 | D4: ='Balance General'!E8/'Balance General'!E21 -> 1.3462769 | E4: ='Balance General'!F8/'Balance General'!F21 -> 1.5757788 | F4: ='Balance General'!G8/'Balance General'!G21 -> 1.8988346 | G4: ='Balance General'!H8/'Balance General'!H21 -> 2.3727053 | I4: Año 0 | J4: ='Flujo de Caja'!C27 -> -35091000 | L4: TIO | M4: 0.15
B5: Nivel de endeudamiento total | C5: ='Balance General'!D27/'Balance General'!D16 -> 0.86222677 | D5: ='Balance General'!E27/'Balance General'!E16 -> 0.74168934 | E5: ='Balance General'!F27/'Balance General'!F16 -> 0.63692415 | F5: ='Balance General'!G27/'Balance General'!G16 -> 0.53081241 | G5: ='Balance General'!H27/'Balance General'!H16 -> 0.41456543 | I5: Año 1 | J5: ='Flujo de Caja'!D27 -> 11076987 | L5: VAN | M5: =NPV(M4,J5:J9) -> 2.1986722e+08
B6: Rentabilidad operacional | C6: ='Estado de Resultados'!D15/'Estado de Resultados'!D6 -> 0.13936082 | D6: ='Estado de Resultados'!E15/'Estado de Resultados'!E6 -> 0.26463526 | E6: ='Estado de Resultados'!F15/'Estado de Resultados'!F6 -> 0.37150813 | F6: ='Estado de Resultados'!G15/'Estado de Resultados'!G6 -> 0.47825316 | G6: ='Estado de Resultados'!H15/'Estado de Resultados'!H6 -> 0.58231417 | I6: Año 2 | J6: ='Flujo de Caja'!E27 -> 30122574 | L6: TIR | M6: =IRR(J4:J9) -> 0.94950712
B7: Rentabilidad neta | C7: ='Estado de Resultados'!D24/'Estado de Resultados'!D6 -> 0.067833793 | D7: ='Estado de Resultados'!E24/'Estado de Resultados'!E6 -> 0.15394244 | E7: ='Estado de Resultados'!F24/'Estado de Resultados'!F6 -> 0.2274395 | F7: ='Estado de Resultados'!G24/'Estado de Resultados'!G6 -> 0.30026774 | G7: ='Estado de Resultados'!H24/'Estado de Resultados'!H6 -> 0.37850421 | I7: Año 3 | J7: ='Flujo de Caja'!F27 -> 58561121 | L7: RBC | M7: =-NPV(M4,J5:J9)/J4 -> 6.2656301
B8: Rentabilidad de patriominio | C8: ='Estado de Resultados'!D24/'Balance General'!C36 -> 0.31566462 | D8: ='Estado de Resultados'!E24/'Balance General'!D36 -> 0.18475003 | E8: ='Estado de Resultados'!F24/'Balance General'!E36 -> 0.28173651 | F8: ='Estado de Resultados'!G24/'Balance General'!F36 -> 0.38616306 | G8: ='Estado de Resultados'!H24/'Balance General'!G36 -> 0.50844665 | I8: Año 4 | J8: ='Flujo de Caja'!G27 -> 1.0355488e+08
I9: Año 5 | J9: ='Flujo de Caja'!H27 -> 1.8050994e+08
