Workbook

Sheet Inversión Inicial
A1: Inversión Inicial
A2: Tipo de inversión | B2: Valor
A3: Planeación y diseño UX/UI | B3: =B24 -> 5000000
A4: Producción y creación de contenidos interactivos | B4: =B32 -> 3740000
A5: Equipos de cómputo y hardware | B5: =D17 -> 8200000
A6: Planeación de marketing, lanzamiento y proyección | B6: =B38 -> 7000000
A7: Consultoría especializada y mentoría | B7: =B45 -> 6000000
A8: Creación de infraestructura y arquitectura de software | B8: =B53 -> 3700000
A9: Capital de trabajo | B9: =B57 -> 1000000
A10: TOTAL | B10: =SUM(B3:B9) -> 34640000
A12: Recursos Físicos (Activos Fijos Tangibles)
A13: Concepto | B13: Cantidad | C13: Valor Unitario | D13: Valor Total
A14: Computadoras o laptops | B14: 2 | C14: 3000000 | D14: =C14*B14 -> 6000000
A15: Monitores | B15: 2 | C15: 800000 | D15: =C15*B15 -> 1600000
A16: Perifericos (mouse, teclados, audífonos) | B16: 2 | C16: 300000 | D16: =C16*B16 -> 600000
A17: SUBTOTAL | D17: =SUM(D14:D16) -> 8200000
A19: Inversión en Planeación y Diseño UX/UI
A20: Concepto | B20: Valor
A21: Investigación UX (tesis y entrevistas) | B21: 1500000
A22: Diseño UI (mockups y prototipos) | B22: 2000000
A23: Prubeas de Usabilidad y Ajustes | B23: 1500000
A24: SUBTOTAL | B24: =SUM(B21:B23) -> 5000000
A26: Inversión en Producción y Creación de Contenidos Interactivos
A27: Concepto | B27: Valor
A28: Guión y diseño | B28: 920000
A29: Desarrollo de simuladores | B29: 1300000
A30: Licencias y recursos (stock y assets) | B30: 600000
A31: Producción multimedia (audios y videos) | B31: 920000
A32: SUBTOTAL | B32: =SUM(B28:B31) -> 3740000
A34: Planeación en Marketing, Lanzamiento y Proyección
A35: Concepto | B35: Valor
A36: Estrategia y branding (Diseño y marca) | B36: 3500000
A37: Producción audiovisual promocional | B37: 3500000
A38: SUBTOTAL | B38: =SUM(B36:B37) -> 7000000
A40: Inversión en Consultoría Especializada
A41: Concepto | B41: Valor
A42: Asesoría legal y cumplimiento | B42: 2000000
A43: Seguridad de la información / datos | B43: 2000000
A44: Mentoría estratégica y producto | B44: 2000000
A45: SUBTOTAL | B45: =SUM(B42:B44) -> 6000000
...

Sheet Proyección de Ventas e Incremen
A1: Ingresos y Proyecciones de Venta | H1: Proyección Incremento de Ventas
A2: Ingresos | H2: IPC Proyectado y Flujo de Efectivo
A3: Concepto | C3: Unidades | D3: Valor/mes | E3: Valor/trimestre | F3: Valor/año | H3: Indicador | I3: Año 0 | J3: Año 1 (2027) | K3: Año 2 (2028) | L3: Año 3 (2029) | M3: Año 4 (2030) | N3: Año 5 (2031)
A4: Plan Gratuito | C4: N/A | D4: 0 | E4: =D4*3 -> 0 | F4: =D4*12 -> 0 | H4: IPC Proyectado | J4: 0.046 | K4: 0.039 | L4: 0.037 | M4: 0.035 | N4: 0.034
A5: Plan Suscriptor | C5: N/A | D5: 30000 | E5: =D5*3 -> 90000 | F5: =D5*12 -> 360000 | H5: % Crecimiento de Ventas | J5: 0.25 | K5: 0.22 | L5: 0.25 | M5: 0.29 | N5: 0.34
A6: Publicidad de Plan Gratuito | C6: N/A | D6: 300 | E6: =D6*3 -> 900 | F6: =D6*12 -> 3600 | H6: Crecimiento de ventas indexación IPC y % crecimiento | J6: =SUM(J4:J5) -> 0.296 | K6: =SUM(K4:K5) -> 0.259 | L6: =SUM(L4:L5) -> 0.287 | M6: =SUM(M4:M5) -> 0.325 | N6: =SUM(N4:N5) -> 0.374
A7: Proyección de Ventas | H7: Flujo de efectivo | J7: =F12*(1+J6) -> 163296000 | K7: =J7*(1+K6) -> 2.0558966e+08 | L7: =K7*(1+L6) -> 2.645939e+08 | M7: =L7*(1+M6) -> 3.5058691e+08 | N7: =M7*(1+N6) -> 4.8170642e+08
A8: Servicio | B8: Valor/mes | C8: N° Suscripción/mes | D8: Ingreso/mes | E8: Ingreso/trimestre | F8: Ingreso/anual
A9: Plan Gratuito | B9: =D4 -> 0 | C9: 3500 | D9: =B9*$C$9 -> 0 | E9: =D9*3 -> 0 | F9: =D9*12 -> 0 | H9: Especificaciones del dinero generado y de los planes existentes
A10: Plan Suscriptor | B10: =D5 -> 30000 | C10: =C9*0.09 -> 315 | D10: =B10*$C$10 -> 9450000 | E10: =D10*3 -> 28350000 | F10: =D10*12 -> 113400000 | H10: Indicador | J10: Año 1 (2027) | K10: Año 2 (2028) | L10: Año 3 (2029) | M10: Año 4 (2030) | N10: Año 5 (2031)
A11: Publicidad de Plan Gratuito | B11: 300 | C11: =C9 -> 3500 | D11: =B11*$C$11 -> 1050000 | E11: =D11*3 -> 3150000 | F11: =D11*12 -> 12600000 | H11: Valor de cada plan contando con el IPC
A12: Total | C12: =SUM(C10:C11) -> 3815 | D12: =SUM(D9:D11) -> 10500000 | E12: =SUM(E9:E11) -> 31500000 | F12: =SUM(F9:F11) -> 126000000 | H12: Valor del plan de pago | J12: =$B10 -> 30000 | K12: =J12*(1+J4) -> 31380 | L12: =K12*(1+K4) -> 32603.82 | M12: =L12*(1+L4) -> 33810.161 | N12: =M12*(1+M4) -> 34993.517
H13: Valor del plan gratuito | J13: =$B11 -> 300 | K13: =J13*(1+J4) -> 313.8 | L13: =K13*(1+K4) -> 326.0382 | M13: =L13*(1+L4) -> 338.10161 | N13: =M13*(1+M4) -> 349.93517
A14: Tabla de Financiamiento | H14: Dinero generado por cada apartado anualmente
A15: Concepto | B15: Valor | H15: Dinero aportado por suscripciones | I15: 0.9 | J15: =J$7*$I15 -> 146966400 | K15: =K$7*$I15 -> 1.850307e+08 | L15: =L$7*$I15 -> 2.3813451e+08 | M15: =M$7*$I15 -> 3.1552822e+08 | N15: =N$7*$I15 -> 4.3353578e+08
A16: Financiamiento externo | B16: ='Costos de Operación Gravables'!$B$54*0.45 -> 16240950 | H16: Dinero aportado por publicidad | I16: 0.1 | J16: =J$7*$I16 -> 16329600 | K16: =K$7*$I16 -> 20558966 | L16: =L$7*$I16 -> 26459390 | M16: =M$7*$I16 -> 35058691 | N16: =N$7*$I16 -> 48170642
A17: Aportes sociales (Fin. por socios) | B17: ='Costos de Operación Gravables'!$B$54*0.55 -> 19850050 | H17: Personas que pertenecen a cada plan por mes
A18: Total | B18: =SUM(B16:B17) -> 36091000 | H18: Personas que pertenecen al plan de suscripciones | J18: =J15/(12*J12) -> 408.24 | K18: =K15/(12*K12) -> 491.37109 | L18: =L15/(12*L12) -> 608.65697 | M18: =M15/(12*M12) -> 777.69574 | N18: =N15/(12*N12) -> 1032.4193
H19: Personas que pertenecen al plan gratuito (publicidad) | J19: =J16/(12*J13) -> 4536 | K19: =K16/(12*K13) -> 5459.6788 | L19: =L16/(12*L13) -> 6762.8552 | M19: =M16/(12*M13) -> 8641.0638 | N19: =N16/(12*N13) -> 11471.325
A20: Contribución de los Socios | H20: Efectivo generado por cada persona que entre en el negocio (sin importar su plan) al mes | O20: Promedio total
A21: Concepto | B21: Participación | C21: Valor | H21: Dinero generado por cada cliente en promedio al mes | J21: =(SUM(J15:J16)/12)/SUM(J18:J19) -> 2752.2936 | K21: =(SUM(K15:K16)/12)/SUM(K18:K19) -> 2878.8991 | L21: =(SUM(L15:L16)/12)/SUM(L18:L19) -> 2991.1761 | M21: =(SUM(M15:M16)/12)/SUM(M18:M19) -> 3101.8497 | N21: =(SUM(N15:N16)/12)/SUM(N18:N19) -> 3210.4144 | O21: =AVERAGE(J21:N21) -> 2986.9266
A22: David Rincón | B22: 0.5 | C22: =$B$17*B22 -> 9925025 | H22: Dinero generado por cada cliente en promedio al año | J22: =J21*12 -> 33027.523 | K22: =K21*12 -> 34546.789 | L22: =L21*12 -> 35894.114 | M22: =M21*12 -> 37222.196 | N22: =N21*12 -> 38524.973 | O22: =AVERAGE(J22:N22) -> 35843.119
A23: Leidy Marcela | B23: 0.5 | C23: =$B$17*B23 -> 9925025 | H23: Total de planes existentes anualmente sin importar su plan
A24: Total | B24: =SUM(B22:B23) -> 1 | C24: =SUM(C22:C23) -> 19850050 | H24: Total de planes existentes anualmente | J24: =SUM(J18:J19)*12 -> 59330.88 | K24: =SUM(K18:K19)*12 -> 71412.598 | L24: =SUM(L18:L19)*12 -> 88458.146 | M24: =SUM(M18:M19)*12 -> 113025.11 | N24: =SUM(N18:N19)*12 -> 150044.93

Sheet Costos de Operación Gravables
A1: Costos de Operación Gravables | F1: Costos de Operación Gravables
A2: Sueldos de los Empleados | F2: Sueldos de los Empleados
A3: Tipo de inversión | B3: Unidades | C3: Valor Unitario/mes | D3: Valor Total/mes | F3: Valor de 0 | G3: Conversión Anual | H3: Tasa de Crecimiento | I3: Año 0 | J3: Año 1 | K3: Año 2 | L3: Año 3 | M3: Año 4 | N3: Año 5
A4: Líder de Desarrollo | B4: 1 | C4: 3000000 | D4: =C4*B4 -> 3000000 | F4: =D6 -> 6000000 | G4: =F4*12 -> 72000000 | H4: 0.1 | I4: 0 | J4: =G4 -> 72000000 | K4: =J$4*($H$4+1) -> 79200000 | L4: =K$4*($H$4+1) -> 87120000 | M4: =L$4*($H$4+1) -> 95832000 | N4: =M$4*($H$4+1) -> 1.054152e+08
A5: Líder I+D+I | B5: 1 | C5: 3000000 | D5: =C5*B5 -> 3000000 | F5: Prestaciones y Parafiscales
A6: Total | C6: =SUM(C4:C5) -> 6000000 | D6: =SUM(D4:D5) -> 6000000 | F6: Valor de 0 | G6: Conversión Anual | H6: Tasa de Crecimiento | I6: Año 0 | J6: Año 1 | K6: Año 2 | L6: Año 3 | M6: Año 4 | N6: Año 5
A7: Prestaciones y Parafiscales | F7: =D17 -> 1788578 | G7: =F7*12 -> 21462936 | H7: 0.1 | I7: 0 | J7: =G7 -> 21462936 | K7: =J7*($H$7+1) -> 23609230 | L7: =K7*($H$7+1) -> 25970153 | M7: =L7*($H$7+1) -> 28567168 | N7: =M7*($H$7+1) -> 31423885
A8: Tipo de inversión | B8: Unidades | C8: Valor Unitario/mes | D8: Valor Total/mes | F8: Servicios e Infraestructuras
A9: Cesantias | B9: =SUM($B$4:$B$6) -> 2 | C9: 166600 | D9: =C9*B9 -> 333200 | F9: Valor de 0 | G9: Conversión Anual | H9: Tasa de Crecimiento | I9: Año 0 | J9: Año 1 | K9: Año 2 | L9: Año 3 | M9: Año 4 | N9: Año 5
A10: Intereses sobre cesantias | B10: =SUM($B$4:$B$6) -> 2 | C10: 20000 | D10: =C10*B10 -> 40000 | F10: =D22 -> 3720000 | G10: =F10*12 -> 44640000 | H10: 0.06 | I10: 0 | J10: =G10 -> 44640000 | K10: =J10*($H$10+1) -> 47318400 | L10: =K10*($H$7+1) -> 52050240 | M10: =L10*($H$7+1) -> 57255264 | N10: =M10*($H$7+1) -> 62980790
A11: Primas | B11: =SUM($B$4:$B$6) -> 2 | C11: 166600 | D11: =C11*B11 -> 333200 | F11: Registros y Estatutos
A12: Vacaciones | B12: =SUM($B$4:$B$6) -> 2 | C12: 73013 | D12: =C12*B12 -> 146026 | F12: Valor de 0 | G12: Conversión Anual | H12: Tasa de Crecimiento | I12: Año 0 | J12: Año 1 | K12: Año 2 | L12: Año 3 | M12: Año 4 | N12: Año 5
A13: Pensiones (AFP) | B13: =SUM($B$4:$B$6) -> 2 | C13: 210109 | D13: =C13*B13 -> 420218 | F13: =D26 -> 1451000 | G13: N/A | H13: N/A | I13: =F13 -> 1451000
A14: Salud (EPS) | B14: =SUM($B$4:$B$6) -> 2 | C14: 148827 | D14: =C14*B14 -> 297654 | F14: SUBTOTAL
A15: Riesgos Laborales (ARL) | B15: =SUM($B$4:$B$6) -> 2 | C15: 9140 | D15: =C15*B15 -> 18280 | I15: =SUM(I4,I7,I10,I13) -> 1451000 | J15: =SUM(J4,J7,J10,J13) -> 138102936 | K15: =SUM(K4,K7,K10,K13) -> 1.5012763e+08 | L15: =SUM(L4,L7,L10,L13) -> 1.6514039e+08 | M15: =SUM(M4,M7,M10,M13) -> 1.8165443e+08 | N15: =SUM(N4,N7,N10,N13) -> 1.9981987e+08
A16: Caja de Compensación Familiar | B16: =SUM($B$4:$B$6) -> 2 | C16: 100000 | D16: =C16*B16 -> 200000
A17: Total | C17: =SUM(C9:C16) -> 894289 | D17: =SUM(D9:D16) -> 1788578 | F17: Costos Indirectos de Fabricación
A18: Servicios e Infraestructura | F18: Papelería y Accesorios
A19: Tipo de inversión | B19: Unidades | C19: Valor Unitario/mes | D19: Valor Total/mes | F19: Valor de 0 | G19: Conversión Anual | H19: Tasa de Crecimiento | I19: Año 0 | J19: Año 1 | K19: Año 2 | L19: Año 3 | M19: Año 4 | N19: Año 5
A20: Servicio de Internet | B20: 1 | C20: 220000 | D20: =C20*B20 -> 220000 | F20: 13000 | G20: =F20*12 -> 156000 | H20: 0.06 | I20: 0 | J20: =G20 -> 156000 | K20: =J$20*($H$20+1) -> 165360 | L20: =K$20*($H$20+1) -> 175281.6 | M20: =L$20*($H$20+1) -> 185798.5 | N20: =M$20*($H$20+1) -> 196946.41
A21: Servicios de Infraestructura de TI/Hosting del Sitio | B21: 1 | C21: 3500000 | D21: =C21*B21 -> 3500000 | F21: Campañas de Marketing y Demostraciones
A22: Total | C22: =SUM(C20:C21) -> 3720000 | D22: =SUM(D20:D21) -> 3720000 | F22: Valor de 0 | G22: Conversión Anual | H22: Tasa de Crecimiento | I22: Año 0 | J22: Año 1 | K22: Año 2 | L22: Año 3 | M22: Año 4 | N22: Año 5
A23: Registros y Estatutos | F23: 120000 | G23: =F23*12 -> 1440000 | H23: 0.06 | I23: 0 | J23: =G23 -> 1440000 | K23: =J$23*($H$23+1) -> 1526400 | L23: =K$23*($H$23+1) -> 1617984 | M23: =L$23*($H$23+1) -> 1715063 | N23: =M$23*($H$23+1) -> 1817966.8 | P23: materia prima
A24: Tipo de inversión | B24: Unidades | C24: Valor Unitario/mes | D24: Valor Total/mes | F24: SUBTOTAL | P24: costos de opera. / mano de obra
A25: Registros y Estatutos | B25: 1 | C25: =B42 -> 1451000 | D25: =C25*B25 -> 1451000 | I25: =SUM(I23,I20) -> 0 | J25: =SUM(J23,J20) -> 1596000 | K25: =SUM(K23,K20) -> 1691760 | L25: =SUM(L23,L20) -> 1793265.6 | M25: =SUM(M23,M20) -> 1900861.5 | N25: =SUM(N23,N20) -> 2014913.2 | P25: costos indirectos
A26: Total | C26: =SUM(C25) -> 1451000 | D26: =SUM(D25) -> 1451000
F27: Total Costos de Fabricación y Operación
I28: =SUM(I15,I25) -> 1451000 | J28: =SUM(J15,J25) -> 139698936 | K28: =SUM(K15,K25) -> 1.5181939e+08 | L28: =SUM(L15,L25) -> 1.6693366e+08 | M28: =SUM(M15,M25) -> 1.8355529e+08 | N28: =SUM(N15,N25) -> 2.0183479e+08
F30: Depreciación
J31: ='Amortización y Depreciación'!G18 -> 1640000 | K31: =J31 -> 1640000 | L31: =K31 -> 1640000 | M31: =L31 -> 1640000 | N31: =M31 -> 1640000
F33: TOTAL COSTOS DE FABRIACIÓN, OPERACIÓN Y DEPRECIACIÓN
J34: =SUM(J28,J31) -> 141338936 | K34: =SUM(K28,K31) -> 1.5345939e+08 | L34: =SUM(L28,L31) -> 1.6857366e+08 | M34: =SUM(M28,M31) -> 1.8519529e+08 | N34: =SUM(N28,N31) -> 2.0347479e+08
A35: Activos Fijos Intangibles
A36: Registro de Marca | B36: 1288000 | F36: Especificaciones del costo de ventas por cada cliente
A37: Estatutos | B37: 30000 | F37: Cantidad de planes anualmente y costos de operación y gastos (planes gratuitos y suscriptores)
A38: Registro Cámara de Comercio de Bogotá | B38: 69000 | F38: Indicador | I38: Año 0 | J38: Año 1 | K38: Año 2 | L38: Año 3 | M38: Año 4 | N38: Año 5
A39: Inscripción de Libros Contables | B39: 64000 | F39: Total de planes existentes anualmente | J39: ='Proyección de Ventas e Incremen'!J24 -> 59330.88 | K39: ='Proyección de Ventas e Incremen'!K24 -> 71412.598 | L39: ='Proyección de Ventas e Incremen'!L24 -> 88458.146 | M39: ='Proyección de Ventas e Incremen'!M24 -> 113025.11 | N39: ='Proyección de Ventas e Incremen'!N24 -> 150044.93
A40: Apertura de Cuentas Bancarias | B40: N/A | F40: Costos de mano de obra, indirectos y depreciación | J40: =J34 -> 141338936 | K40: =K34 -> 1.5345939e+08 | L40: =L34 -> 1.6857366e+08 | M40: =M34 -> 1.8519529e+08 | N40: =N34 -> 2.0347479e+08
A41: Formulario Único de Registro Empresarial | B41: N/A | F41: Costos de operación por cada cliente
A42: Total | B42: =SUM(B36:B39) -> 1451000 | F42: Indicador | I42: Año 0 | J42: Año 1 | K42: Año 2 | L42: Año 3 | M42: Año 4 | N42: Año 5 | O42: Promedio total
...

Sheet Amortización y Depreciación
A1: Amortización y Depreciación | D1: Amortización del Crédito
A2: Préstamo (en Banco GNB Sudameris) | D2: Período | E2: Saldo | F2: Interés | G2: Pago al crédito | H2: Amortización | I2: Saldo final
A3: Concepto | B3: Unidades | D3: 0 (Año 0) | E3: =B4 -> 16240950 | F3: 0 | G3: 0 | H3: 0 | I3: =E3 -> 16240950
A4: Valor del préstamo | B4: ='Proyección de Ventas e Incremen'!B16 -> 16240950 | D4: 1 (Año 1) | E4: =I3 -> 16240950 | F4: =E4*$B$7 -> 2702494.1 | G4: =$B$8 -> 5878423.2 | H4: =G4-F4 -> 3175929.1 | I4: =E4-H4 -> 13065021
A5: Cuota inicial | B5: 0 | D5: 2 (Año 2) | E5: =I4 -> 13065021 | F5: =E5*$B$7 -> 2174019.5 | G5: =$B$8 -> 5878423.2 | H5: =G5-F5 -> 3704403.7 | I5: =E5-H5 -> 9360617.2
A6: Plazo de meses/períodos | B6: 48 meses | D6: 3 (Año 3) | E6: =I5 -> 9360617.2 | F6: =E6*$B$7 -> 1557606.7 | G6: =$B$8 -> 5878423.2 | H6: =G6-F6 -> 4320816.5 | I6: =E6-H6 -> 5039800.7
A7: Tasa de interés (anualmente) | B7: 0.1664 | D7: 4 (Año 4) | E7: =I6 -> 5039800.7 | F7: =E7*$B$7 -> 838622.84 | G7: =$B$8 -> 5878423.2 | H7: =G7-F7 -> 5039800.4 | I7: =E7-H7 -> 0.3460942
A8: Pago anual | B8: =((B4*1.44780279145524)/4) -> 5878423.2 | D8: 5 (Año 5) | E8: =I7 -> 0.3460942 | F8: =E8*$B$7 -> 0.057590075 | G8: 0 | H8: =G8-F8 -> -0.057590075 | I8: =E8-H8 -> 0.40368428 | K8: =SUM(G4:G7) -> 23513693
A9: Pago mensual | B9: =B8/12 -> 489868.6
D10: Depreciación
D11: Activos Fijos | E11: Vida Útil | F11: Valor Inicial | G11: Año 1 | H11: Año 2 | I11: Año 3 | J11: Año 4 | K11: Año 5
D12: Computador 1 | E12: 5 años | F12: ='Inversión Inicial'!$C$14 -> 3000000 | G12: =$F12*G$19 -> 600000 | H12: =$F12*H$19 -> 1200000 | I12: =$F12*I$19 -> 1800000 | J12: =$F12*J$19 -> 2400000 | K12: =$F12*K$19 -> 3000000
D13: Perifericos 1 | E13: 5 años | F13: ='Inversión Inicial'!$C$16 -> 300000 | G13: =$F13*G$19 -> 60000 | H13: =$F13*H$19 -> 120000 | I13: =$F13*I$19 -> 180000 | J13: =$F13*J$19 -> 240000 | K13: =$F13*K$19 -> 300000
D14: Monitor 1 | E14: 5 años | F14: ='Inversión Inicial'!C15 -> 800000 | G14: =$F14*G$19 -> 160000 | H14: =$F14*H$19 -> 320000 | I14: =$F14*I$19 -> 480000 | J14: =$F14*J$19 -> 640000 | K14: =$F14*K$19 -> 800000
D15: Computador 2 | E15: 5 años | F15: ='Inversión Inicial'!$C$14 -> 3000000 | G15: =$F15*G$19 -> 600000 | H15: =$F15*H$19 -> 1200000 | I15: =$F15*I$19 -> 1800000 | J15: =$F15*J$19 -> 2400000 | K15: =$F15*K$19 -> 3000000
D16: Perifericos 2 | E16: 5 años | F16: ='Inversión Inicial'!$C$16 -> 300000 | G16: =$F16*G$19 -> 60000 | H16: =$F16*H$19 -> 120000 | I16: =$F16*I$19 -> 180000 | J16: =$F16*J$19 -> 240000 | K16: =$F16*K$19 -> 300000
D17: Monitor 2 | E17: 5 años | F17: ='Inversión Inicial'!C15 -> 800000 | G17: =$F17*G$19 -> 160000 | H17: =$F17*H$19 -> 320000 | I17: =$F17*I$19 -> 480000 | J17: =$F17*J$19 -> 640000 | K17: =$F17*K$19 -> 800000
D18: Depreciación Total | G18: =SUM(G12:G17) -> 1640000 | H18: =SUM(H12:H17) -> 3280000 | I18: =SUM(I12:I17) -> 4920000 | J18: =SUM(J12:J17) -> 6560000 | K18: =SUM(K12:K17) -> 8200000
D19: Tasa de Depreciación Total | G19: 0.2 | H19: 0.4 | I19: 0.6 | J19: 0.8 | K19: 1
D21: Depreciación
D22: Activos Fijos | E22: Vida Útil | F22: Valor Inicial | G22: Año 1 | H22: Año 2 | I22: Año 3 | J22: Año 4 | K22: Año 5
D23: Computador 1 | E23: 5 años | F23: ='Inversión Inicial'!$C$14 -> 3000000 | G23: =$F23-($F23*G$30) -> 2400000 | H23: =$F23-($F23*H$30) -> 1800000 | I23: =$F23-($F23*I$30) -> 1200000 | J23: =$F23-($F23*J$30) -> 600000 | K23: =$F23-($F23*K$30) -> 0
D24: Perifericos 1 | E24: 5 años | F24: ='Inversión Inicial'!$C$16 -> 300000 | G24: =$F24-($F24*G$30) -> 240000 | H24: =$F24-($F24*H$30) -> 180000 | I24: =$F24-($F24*I$30) -> 120000 | J24: =$F24-($F24*J$30) -> 60000 | K24: =$F24-($F24*K$30) -> 0
D25: Monitor 1 | E25: 5 años | F25: ='Inversión Inicial'!C15 -> 800000 | G25: =$F25-($F25*G$30) -> 640000 | H25: =$F25-($F25*H$30) -> 480000 | I25: =$F25-($F25*I$30) -> 320000 | J25: =$F25-($F25*J$30) -> 160000 | K25: =$F25-($F25*K$30) -> 0
D26: Computador 2 | E26: 5 años | F26: ='Inversión Inicial'!$C$14 -> 3000000 | G26: =$F26-($F26*G$30) -> 2400000 | H26: =$F26-($F26*H$30) -> 1800000 | I26: =$F26-($F26*I$30) -> 1200000 | J26: =$F26-($F26*J$30) -> 600000 | K26: =$F26-($F26*K$30) -> 0
D27: Perifericos 2 | E27: 5 años | F27: ='Inversión Inicial'!$C$16 -> 300000 | G27: =$F27-($F27*G$30) -> 240000 | H27: =$F27-($F27*H$30) -> 180000 | I27: =$F27-($F27*I$30) -> 120000 | J27: =$F27-($F27*J$30) -> 60000 | K27: =$F27-($F27*K$30) -> 0
D28: Monitor 2 | E28: 5 años | F28: ='Inversión Inicial'!$C$15 -> 800000 | G28: =$F28-($F28*G$30) -> 640000 | H28: =$F28-($F28*H$30) -> 480000 | I28: =$F28-($F28*I$30) -> 320000 | J28: =$F28-($F28*J$30) -> 160000 | K28: =$F28-($F28*K$30) -> 0
D29: Depreciación Total | G29: =SUM(G23:G28) -> 6560000 | H29: =SUM(H23:H28) -> 4920000 | I29: =SUM(I23:I28) -> 3280000 | J29: =SUM(J23:J28) -> 1640000 | K29: =SUM(K23:K28) -> 0
D30: Tasa de Depreciación Total | G30: 0.2 | H30: 0.4 | I30: 0.6 | J30: 0.8 | K30: 1

Sheet Balance General
A1: BALANCE GENERAL PROYECTADO
A2: EDUFINANZAS S.A.S.
A4: TRIMESTRE | C4: AÑO 0 | D4: AÑO 1 | E4: AÑO 2 | F4: AÑO 3 | G4: AÑO 4 | H4: AÑO 5
A5: ACTIVOS
A6: ACTIVOS CORRIENTES
B7: Efectivo y Equivalente de Efectivo | C7: ='Proyección de Ventas e Incremen'!B18 -> 36091000 | D7: ='Proyección de Ventas e Incremen'!J7 -> 163296000 | E7: ='Proyección de Ventas e Incremen'!K7 -> 2.0558966e+08 | F7: ='Proyección de Ventas e Incremen'!L7 -> 2.645939e+08 | G7: ='Proyección de Ventas e Incremen'!M7 -> 3.5058691e+08 | H7: ='Proyección de Ventas e Incremen'!N7 -> 4.8170642e+08
B8: Total Activos Corrientes | C8: =SUM(C7:C7) -> 36091000 | D8: =SUM(D7:D7) -> 163296000 | E8: =SUM(E7:E7) -> 2.0558966e+08 | F8: =SUM(F7:F7) -> 2.645939e+08 | G8: =SUM(G7:G7) -> 3.5058691e+08 | H8: =SUM(H7:H7) -> 4.8170642e+08
A10: ACTIVOS NO CORRIENTES
B11: Equipos | C11: 0 | D11: =8200000-D12 -> 6560000 | E11: =D11-E12 -> 4920000 | F11: =E11-E12 -> 3280000 | G11: =F11-F12 -> 1640000 | H11: =G11-G12 -> 0
B12: Depreciación de Equipos | C12: 0 | D12: ='Amortización y Depreciación'!G18 -> 1640000 | E12: 1640000 | F12: 1640000 | G12: 1640000 | H12: 1640000
B13: Intangibles | C13: 0 | D13: 1451000 | E13: =D13 -> 1451000 | F13: =E13 -> 1451000 | G13: =F13 -> 1451000 | H13: =G13 -> 1451000
B14: Total Activos No Corrientes | C14: =C11+C13 -> 0 | D14: =SUM(D11:D13) -> 9651000 | E14: =SUM(E11:E13) -> 8011000 | F14: =SUM(F11:F13) -> 6371000 | G14: =SUM(G11:G13) -> 4731000 | H14: =SUM(H11:H13) -> 3091000
A16: TOTAL ACTIVO | C16: =C8+C14 -> 36091000 | D16: =D8+D14 -> 172947000 | E16: =E8+E14 -> 2.1360066e+08 | F16: =F8+F14 -> 2.709649e+08 | G16: =G8+G14 -> 3.5531791e+08 | H16: =H8+H14 -> 4.8479742e+08
A17: PASIVOS
A18: PASIVOS CORRIENTES
B19: Acreedores comerciales y otras cuentas por pagar | C19: ='Amortización y Depreciación'!B4 -> 16240950 | D19: ='Costos de Operación Gravables'!J10 -> 44640000 | E19: ='Costos de Operación Gravables'!K10 -> 47318400 | F19: ='Costos de Operación Gravables'!L10 -> 52050240 | G19: ='Costos de Operación Gravables'!M10 -> 57255264 | H19: ='Costos de Operación Gravables'!N10 -> 62980790
B20: Salarios y beneficios a empleados | C20: ='Costos de Operación Gravables'!I4 -> 0 | D20: ='Costos de Operación Gravables'!J4+'Costos de Operación Gravables'!J7 -> 93462936 | E20: ='Costos de Operación Gravables'!K4+'Costos de Operación Gravables'!K7 -> 1.0280923e+08 | F20: ='Costos de Operación Gravables'!L4+'Costos de Operación Gravables'!L7 -> 1.1309015e+08 | G20: ='Costos de Operación Gravables'!M4+'Costos de Operación Gravables'!M7 -> 1.2439917e+08 | H20: ='Costos de Operación Gravables'!N4+'Costos de Operación Gravables'!N7 -> 1.3683908e+08
B21: Tributos (impuestos) por pagar | C21: ='Estado de Resultados'!C20 -> 0 | D21: ='Estado de Resultados'!D20 -> 3382274.3 | E21: ='Estado de Resultados'!E20 -> 14550414 | F21: ='Estado de Resultados'!F20 -> 30521429 | G21: ='Estado de Resultados'!G20 -> 55413071 | H21: ='Estado de Resultados'!H20 -> 97578441
B22: Total Pasivos Corrientes | C22: =SUM(C19:C21) -> 16240950 | D22: =SUM(D19:D21) -> 1.4148521e+08 | E22: =SUM(E19:E21) -> 1.6467804e+08 | F22: =SUM(F19:F21) -> 1.9566182e+08 | G22: =SUM(G19:G21) -> 2.370675e+08 | H22: =SUM(H19:H21) -> 2.9739832e+08
A24: PASIVOS NO CORRIENTES
B25: Préstamo | C25: ='Estado de Resultados'!C15 -> 0 | D25: ='Estado de Resultados'!D15 -> 5878423.2 | E25: ='Estado de Resultados'!E15 -> 5878423.2 | F25: ='Estado de Resultados'!F15 -> 5878423.2 | G25: ='Estado de Resultados'!G15 -> 5878423.2 | H25: ='Estado de Resultados'!H15 -> 0
B26: Total Pasivos No Corrientes | C26: =SUM(C25) -> 0 | D26: =SUM(D25) -> 5878423.2 | E26: =SUM(E25) -> 5878423.2 | F26: =SUM(F25) -> 5878423.2 | G26: =SUM(G25) -> 5878423.2 | H26: =SUM(H25) -> 0
A28: TOTAL PASIVOS | C28: =C22+C26 -> 16240950 | D28: =D22+D26 -> 1.4736363e+08 | E28: =E22+E26 -> 1.7055647e+08 | F28: =F22+F26 -> 2.0154024e+08 | G28: =G22+G26 -> 2.4294593e+08 | H28: =H22+H26 -> 2.9739832e+08
A30: CAPITAL
B31: Capital Social | C31: ='Proyección de Ventas e Incremen'!B17 -> 19850050 | D31: =C31 -> 19850050 | E31: =D31 -> 19850050 | F31: =E31 -> 19850050 | G31: =F31 -> 19850050 | H31: =G31 -> 19850050
B32: Resultados acumulados | C32: 0 | D32: 0 | E32: 0 | F32: 0 | G32: 0 | H32: 0
B33: Utilidad o Pérdida del Ejercicio | C33: 0 | D33: ='Estado de Resultados'!D22 -> 6281366.5 | E33: ='Estado de Resultados'!E22 -> 27022197 | F33: ='Estado de Resultados'!F22 -> 56682653 | G33: ='Estado de Resultados'!G22 -> 1.0290999e+08 | H33: ='Estado de Resultados'!H22 -> 1.812171e+08
A35: TOTAL CAPITAL | C35: =SUM(C31:C33) -> 19850050 | D35: =SUM(D31:D33) -> 26131417 | E35: =SUM(E31:E33) -> 46872247 | F35: =SUM(F31:F33) -> 76532703 | G35: =SUM(G31:G33) -> 1.2276004e+08 | H35: =SUM(H31:H33) -> 2.0106715e+08
A37: SUMA PASIVOS + CAPITAL | C37: =C28+C35 -> 36091000 | D37: =D28+D35 -> 173495050 | E37: =E28+E35 -> 2.1742871e+08 | F37: =F28+F35 -> 2.7807295e+08 | G37: =G28+G35 -> 3.6570596e+08 | H37: =H28+H35 -> 4.9846547e+08

Sheet Estado de Resultados
A1: ESTADO DE RESULTADOS PROYECTADOS
A2: EDUFINANZAS S.A.S.
A4: TRIMESTRE | C4: AÑO 0 | D4: AÑO 1 | E4: AÑO 2 | F4: AÑO 3 | G4: AÑO 4 | H4: AÑO 5
A5: UTILIDAD BRUTA
B6: Ingresos obtenidos por actividades cotidianas | D6: ='Proyección de Ventas e Incremen'!J7 -> 163296000 | E6: ='Proyección de Ventas e Incremen'!K7 -> 2.0558966e+08 | F6: ='Proyección de Ventas e Incremen'!L7 -> 2.645939e+08 | G6: ='Proyección de Ventas e Incremen'!M7 -> 3.5058691e+08 | H6: ='Proyección de Ventas e Incremen'!N7 -> 4.8170642e+08
B7: Costo de ventas | D7: ='Costos de Operación Gravables'!J15 -> 138102936 | E7: ='Costos de Operación Gravables'!K15 -> 1.5012763e+08 | F7: ='Costos de Operación Gravables'!L15 -> 1.6514039e+08 | G7: ='Costos de Operación Gravables'!M15 -> 1.8165443e+08 | H7: ='Costos de Operación Gravables'!N15 -> 1.9981987e+08
B8: Total de Utilidad Bruta | C8: =SUM(C6:C7) -> 0 | D8: =D6-D7 -> 25193064 | E8: =E6-E7 -> 55462034 | F8: =F6-F7 -> 99453505 | G8: =G6-G7 -> 1.6893248e+08 | H8: =H6-H7 -> 2.8188655e+08
A10: UTILIDAD OPERATIVA
B11: Gastos de administración | D11: 9651000 | E11: 8011000 | F11: 6371000 | G11: 4731000 | H11: 3091000
B12: Total de Utilidad Operativa | C12: =C8-C11 -> 0 | D12: =D8-D11 -> 15542064 | E12: =E8-E11 -> 47451034 | F12: =F8-F11 -> 93082505 | G12: =G8-G11 -> 1.6420148e+08 | H12: =H8-H11 -> 2.7879555e+08
A14: RESULTADO ANTES DE IMPUESTOS
B15: Gastos financieros | D15: ='Amortización y Depreciación'!G4 -> 5878423.2 | E15: ='Amortización y Depreciación'!G5 -> 5878423.2 | F15: ='Amortización y Depreciación'!G6 -> 5878423.2 | G15: ='Amortización y Depreciación'!G7 -> 5878423.2
B16: Otros ingresos (préstamo) | C16: 0
B17: Total de Utilidad antes de Impuestos | C17: =C12-C15+C16 -> 0 | D17: =D12-D15+D16 -> 9663640.8 | E17: =E12-E15+E16 -> 41572611 | F17: =F12-F15+F16 -> 87204082 | G17: =G12-G15+G16 -> 1.5832306e+08 | H17: =H12-H15+H16 -> 2.7879555e+08
A19: IMPUESTOS
B20: Impuestos | D20: =D17*0.35 -> 3382274.3 | E20: =E17*0.35 -> 14550414 | F20: =F17*0.35 -> 30521429 | G20: =G17*0.35 -> 55413071 | H20: =H17*0.35 -> 97578441
A22: UTILIDAD NETA | C22: =C17-C20 -> 0 | D22: =D17-D20 -> 6281366.5 | E22: =E17-E20 -> 27022197 | F22: =F17-F20 -> 56682653 | G22: =G17-G20 -> 1.0290999e+08 | H22: =H17-H20 -> 1.812171e+08

Sheet Flujo de Caja
A1: FLUJO DE CAJA PROYECTADO
A2: EDUFINANZAS S.A.S.
A4: TRIMESTRE | C4: AÑO 0 | D4: AÑO 1 | E4: AÑO 2 | F4: AÑO 3 | G4: AÑO 4 | H4: AÑO 5
A5: ENTRADAS
B6: Aportaciones de socios | C6: ='Proyección de Ventas e Incremen'!B17 -> 19850050
B7: Aportaciones de financiamiento bancario | C7: ='Proyección de Ventas e Incremen'!B16 -> 16240950
B8: Ingresos obtenidos del negocio | D8: ='Proyección de Ventas e Incremen'!J7 -> 163296000 | E8: ='Proyección de Ventas e Incremen'!K7 -> 2.0558966e+08 | F8: ='Proyección de Ventas e Incremen'!L7 -> 2.645939e+08 | G8: ='Proyección de Ventas e Incremen'!M7 -> 3.5058691e+08 | H8: ='Proyección de Ventas e Incremen'!N7 -> 4.8170642e+08
B9: Total Entradas/Ingresos | C9: =SUM(C6:C8) -> 36091000 | D9: =SUM(D6:D8) -> 163296000 | E9: =SUM(E6:E8) -> 2.0558966e+08 | F9: =SUM(F6:F8) -> 2.645939e+08 | G9: =SUM(G6:G8) -> 3.5058691e+08 | H9: =SUM(H6:H8) -> 4.8170642e+08
A11: SALIDAS
B12: Inversiones hacia activos fijos | C12: =SUM('Costos de Operación Gravables'!B46:B52) -> 35091000
B13: Gastos generales | D13: ='Costos de Operación Gravables'!J25+'Costos de Operación Gravables'!J10 -> 46236000 | E13: ='Costos de Operación Gravables'!K25+'Costos de Operación Gravables'!K10 -> 49010160 | F13: ='Costos de Operación Gravables'!L25+'Costos de Operación Gravables'!L10 -> 53843506 | G13: ='Costos de Operación Gravables'!M25+'Costos de Operación Gravables'!M10 -> 59156126 | H13: ='Costos de Operación Gravables'!N25+'Costos de Operación Gravables'!N10 -> 64995704
B14: Depreciación anual | D14: ='Amortización y Depreciación'!G18 -> 1640000 | E14: =D14 -> 1640000 | F14: =E14 -> 1640000 | G14: =F14 -> 1640000 | H14: =G14 -> 1640000
B15: Salarios y beneficios a empleados | D15: ='Costos de Operación Gravables'!J4+'Costos de Operación Gravables'!J7 -> 93462936 | E15: ='Costos de Operación Gravables'!K4+'Costos de Operación Gravables'!K7 -> 1.0280923e+08 | F15: ='Costos de Operación Gravables'!L4+'Costos de Operación Gravables'!L7 -> 1.1309015e+08 | G15: ='Costos de Operación Gravables'!M4+'Costos de Operación Gravables'!M7 -> 1.2439917e+08 | H15: ='Costos de Operación Gravables'!N4+'Costos de Operación Gravables'!N7 -> 1.3683908e+08
B16: Capital de trabajo | C16: ='Inversión Inicial'!B9 -> 1000000
B17: Intereses del financiamiento | D17: ='Amortización y Depreciación'!F4 -> 2702494.1 | E17: ='Amortización y Depreciación'!F5 -> 2174019.5 | F17: ='Amortización y Depreciación'!F6 -> 1557606.7 | G17: ='Amortización y Depreciación'!F7 -> 838622.84
B18: Impuestos | D18: ='Estado de Resultados'!D20 -> 3382274.3 | E18: ='Estado de Resultados'!E20 -> 14550414 | F18: ='Estado de Resultados'!F20 -> 30521429 | G18: ='Estado de Resultados'!G20 -> 55413071 | H18: ='Estado de Resultados'!H20 -> 97578441
B19: Total Salidas | C19: =SUM(C12:C18) -> 36091000 | D19: =SUM(D12:D18) -> 1.474237e+08 | E19: =SUM(E12:E18) -> 1.7018382e+08 | F19: =SUM(F12:F18) -> 2.0065269e+08 | G19: =SUM(G12:G18) -> 2.4144699e+08 | H19: =SUM(H12:H18) -> 3.0105323e+08
A21: Disponibilidad de efectivo | C21: =-C19 -> -36091000 | D21: =D9-D19 -> 15872296 | E21: =E9-E19 -> 35405841 | F21: =F9-F19 -> 63941204 | G21: =G9-G19 -> 1.0913993e+08 | H21: =H9-H19 -> 1.8065319e+08
B23: Depreciaciones | D23: =D14 -> 1640000 | E23: =D23 -> 1640000 | F23: =E23 -> 1640000 | G23: =F23 -> 1640000 | H23: =G23 -> 1640000
A25: FLUJOS DE EFECTIVO | C25: =C21 -> -36091000 | D25: =D21+D23 -> 17512296 | E25: =E21+E23 -> 37045841 | F25: =F21+F23 -> 65581204 | G25: =G21+G23 -> 1.1077993e+08 | H25: =H21+H23 -> 1.8229319e+08

Sheet Flujo de Efectivo
A1: FLUJO DE EFECTIVO
A2: EDUFINANZAS S.A.S.
A4: TRIMESTRE | C4: AÑO 0 | D4: AÑO 1 | E4: AÑO 2 | F4: AÑO 3 | G4: AÑO 4 | H4: AÑO 5
A5: FLUJO DE CAJA DE OPERACIÓN
B6: Utilidad del ejercicio | C6: ='Estado de Resultados'!C22 -> 0 | D6: ='Estado de Resultados'!D22 -> 6281366.5 | E6: ='Estado de Resultados'!E22 -> 27022197 | F6: ='Estado de Resultados'!F22 -> 56682653 | G6: ='Estado de Resultados'!G22 -> 1.0290999e+08 | H6: ='Estado de Resultados'!H22 -> 1.812171e+08
B7: Depreciaciones | C7: 0 | D7: ='Flujo de Caja'!D14 -> 1640000 | E7: =D7*2 -> 3280000 | F7: =D7*3 -> 4920000 | G7: =D7*4 -> 6560000 | H7: =D7*5 -> 8200000
B8: Cuotas de deuda | C8: 0 | D8: ='Amortización y Depreciación'!H4 -> 3175929.1 | E8: ='Amortización y Depreciación'!H5 -> 3704403.7 | F8: ='Amortización y Depreciación'!H6 -> 4320816.5 | G8: ='Amortización y Depreciación'!H7 -> 5039800.4 | H8: ='Amortización y Depreciación'!H8 -> -0.057590075
B9: Intereses del préstamo | C9: 0 | D9: ='Amortización y Depreciación'!F4 -> 2702494.1 | E9: ='Amortización y Depreciación'!F5 -> 2174019.5 | F9: ='Amortización y Depreciación'!F6 -> 1557606.7 | G9: ='Amortización y Depreciación'!F7 -> 838622.84 | H9: ='Amortización y Depreciación'!F8 -> 0.057590075
B10: Impuestos | C10: ='Flujo de Caja'!C18 -> 0 | D10: ='Flujo de Caja'!D18 -> 3382274.3 | E10: ='Flujo de Caja'!E18 -> 14550414 | F10: ='Flujo de Caja'!F18 -> 30521429 | G10: ='Flujo de Caja'!G18 -> 55413071 | H10: ='Flujo de Caja'!H18 -> 97578441
B11: Flujo de Caja Operativo Neto | C11: =SUM(C6:C10) -> 0 | D11: =SUM(D6:D10) -> 17182064 | E11: =SUM(E6:E10) -> 50731034 | F11: =SUM(F6:F10) -> 98002505 | G11: =SUM(G6:G10) -> 1.7076148e+08 | H11: =SUM(H6:H10) -> 2.8699555e+08
A13: FLUJO DE CAJA DE INVERSIÓN
B14: Inversión de equipos de computación | C14: ='Inversión Inicial'!B5 -> 8200000 | D14: =0 -> 0 | E14: =0 -> 0 | F14: =0 -> 0 | G14: =0 -> 0 | H14: =0 -> 0
B15: Flujo de Caja de Inversión Neto | C15: =SUM(C14:C14) -> 8200000 | D15: =SUM(D14:D14) -> 0 | E15: =SUM(E14:E14) -> 0 | F15: =SUM(F14:F14) -> 0 | G15: =SUM(G14:G14) -> 0 | H15: =SUM(H14:H14) -> 0
A17: FLUJO DE CAJA DE FINANCIAMIENTO
B18: Capital social | C18: ='Proyección de Ventas e Incremen'!B17 -> 19850050 | D18: =0 -> 0 | E18: =0 -> 0 | F18: =0 -> 0 | G18: =0 -> 0 | H18: =0 -> 0
B19: Desembolso pasivos a largo plazo
B20: Amortizaciones | C20: =C8 -> 0 | D20: =D8 -> 3175929.1 | E20: =E8 -> 3704403.7 | F20: =F8 -> 4320816.5 | G20: =G8 -> 5039800.4 | H20: =H8 -> -0.057590075
B21: Intereses | C21: =C9 -> 0 | D21: =D9 -> 2702494.1 | E21: =E9 -> 2174019.5 | F21: =F9 -> 1557606.7 | G21: =G9 -> 838622.84 | H21: =H9 -> 0.057590075
B22: Pago de dividendos
B23: Flujo de Caja de Financiamiento Neto | C23: =SUM(C18:C21) -> 19850050 | D23: =SUM(D18:D21) -> 5878423.2 | E23: =SUM(E18:E21) -> 5878423.2 | F23: =SUM(F18:F21) -> 5878423.2 | G23: =SUM(G18:G21) -> 5878423.2 | H23: =SUM(H18:H21) -> 0

Sheet Costos Fijos y Punto de Equil.
B2: Punto de equilibrio | G2: Costos Fijos y Variables
B3: Precio de venta unitario promedio | C3: ='Proyección de Ventas e Incremen'!J21 -> 2752.2936 | G3: Costos y/o gastos | I3: Administración y ventas | J3: Producción
B4: Unidades a producir y vender al año | C4: =SUM('Proyección de Ventas e Incremen'!J18:J19)*12 -> 59330.88 | G4: Número de producción | I4: 0 | J4: ='[1]Costos de Operación Gravables'!J15 -> 138102936
B5: Ingresos por venta total anual | C5: =C3*C4 -> 163296000 | G5: Numero permanente (100%) | H5: =J4 -> 138102936 | I5: 0 | J5: 0
B6: Costo de producción | C6: ='Costos de Operación Gravables'!J28 -> 139698936 | G6: Otros gastos administrativos | I6: ='[1]Costos de Operación Gravables'!J25 -> 1596000 | J6: 0
B7: Costo unitario promedio ponderado | C7: =C6/C4 -> 2354.5738 | G7: Depreciación de producción | I7: 0 | J7: ='[1]Balance General'!D12 -> 1640000
B8: Costos de produccion total | G8: Depreciación de administración | I8: 0 | J8: 0
B9: Costos fijos (Gasto general anual) | G9: Subtotal | I9: =SUM(I4:I8) -> 1596000 | J9: =SUM(J4:J8) -> 139742936
G10: Imprevistos | H10: 0.1 | I10: =I9*$H$10 -> 159600 | J10: =J9*$H$10 -> 13974294
G11: Total | I11: =I9+I10 -> 1755600 | J11: =J9+J10 -> 1.5371723e+08
B17: Estimaciones del Punto de Equilibrio | G17: Estimaciones del Punto de Equilibrio
B18: Ventas Iniciales Planteadas | C18: =C4 -> 59330.88 | G18: Ventas Iniciales Planteadas | H18: ='Proyección de Ventas e Incremen'!J18 -> 408.24
B19: Costo de producción por unidad | C19: =J11/C18 -> 2590.847 | G19: Costo de producción por unidad | H19: =J11/H18 -> 376536.42
B20: Costo por unidad | C20: =SUM(I11:J11)/C18 -> 2620.4369 | G20: Costo por unidad | H20: =SUM(I11:J11)/H18 -> 380836.84
B21: Valor agregado (19%) | C21: =C20*0.19 -> 497.88302 | G21: Valor agregado (19%) | H21: =H20*0.19 -> 72358.999
B22: Precio por unidad | C22: =SUM(C20:C21) -> 3118.32 | G22: Precio por unidad | H22: =SUM(H20:H21) -> 453195.83
B23: Punto de equilibrio | C23: =((C20-C19)*C18)/(C22-C20) -> 3526.1295 | G23: Punto de equilibrio | H23: =((H20-H19)*H18)/(H22-H20) -> 24.262359
B25: Punto de Equilibrio | G25: Punto de Equilibrio
B26: Costo de referencia | C26: =C22 -> 3118.32 | G26: Costo de referencia | H26: =H22 -> 453195.83
B27: Unidades mínimas vendidas | C27: =C18 -> 59330.88 | G27: Unidades mínimas vendidas | H27: =H18 -> 408.24
B28: Ventas anuales mínimas | C28: =C26*C27 -> 1.8501267e+08 | G28: Ventas anuales mínimas | H28: =H26*H27 -> 1.8501267e+08

Sheet Grafica Punto de Equilibrio
C1: ='Costos Fijos y Punto de Equil.'!I11 -> 1755600
C2: ='Costos Fijos y Punto de Equil.'!C20 -> 2620.4369 | D2: ='Costos Fijos y Punto de Equil.'!C22 -> 3118.32
C3: Costos | D3: Ventas
B4: 0 | C4: =($C$2*B4)+$C$1 -> 1755600 | D4: =$D$2*B4 -> 0
B5: 1 | C5: =($C$2*B5)+$C$1 -> 1758220.4 | D5: =$D$2*B5 -> 3118.32
B6: 2 | C6: =($C$2*B6)+$C$1 -> 1760840.9 | D6: =$D$2*B6 -> 6236.6399
B7: 3 | C7: =($C$2*B7)+$C$1 -> 1763461.3 | D7: =$D$2*B7 -> 9354.9599
B8: 4 | C8: =($C$2*B8)+$C$1 -> 1766081.7 | D8: =$D$2*B8 -> 12473.28
B9: 5 | C9: =($C$2*B9)+$C$1 -> 1768702.2 | D9: =$D$2*B9 -> 15591.6
B10: 6 | C10: =($C$2*B10)+$C$1 -> 1771322.6 | D10: =$D$2*B10 -> 18709.92
B11: 7 | C11: =($C$2*B11)+$C$1 -> 1773943.1 | D11: =$D$2*B11 -> 21828.24
B12: 8 | C12: =($C$2*B12)+$C$1 -> 1776563.5 | D12: =$D$2*B12 -> 24946.56
B13: 9 | C13: =($C$2*B13)+$C$1 -> 1779183.9 | D13: =$D$2*B13 -> 28064.88
B14: 10 | C14: =($C$2*B14)+$C$1 -> 1781804.4 | D14: =$D$2*B14 -> 31183.2
B15: 11 | C15: =($C$2*B15)+$C$1 -> 1784424.8 | D15: =$D$2*B15 -> 34301.52
... B5004: 5000 | C5004: =($C$2*B5004)+$C$1 -> 14857785 | D5004: =$D$2*B5004 -> 15591600

Sheet Indicadores Financieros
B2: Indicadores financieros | I2: Flujo de caja libre | L2: VAN, TIR y RBC
B3: Período | C3: Año 1 | D3: Año 2 | E3: Año 3 | F3: Año 4 | G3: Año 5 | I3: Período | J3: Flujo de efectivo | L3: Tipo | M3: Valor
B4: Liquidez - razón corriente | C4: ='Balance General'!D8/'Balance General'!D22 -> 1.154156 | D4: ='Balance General'!E8/'Balance General'!E22 -> 1.248434 | E4: ='Balance General'!F8/'Balance General'!F22 -> 1.3523021 | F4: ='Balance General'!G8/'Balance General'!G22 -> 1.4788485 | G4: ='Balance General'!H8/'Balance General'!H22 -> 1.6197349 | I4: Año 0 | J4: ='Flujo de Caja'!#REF! -> #REF! | L4: TIO | M4: 0.15
B5: Nivel de endeudamiento total | C5: ='Balance General'!D28/'Balance General'!D16 -> 0.85207395 | D5: ='Balance General'!E28/'Balance General'!E16 -> 0.79848285 | E5: ='Balance General'!F28/'Balance General'!F16 -> 0.74378728 | F5: ='Balance General'!G28/'Balance General'!G16 -> 0.68374241 | G5: ='Balance General'!H28/'Balance General'!H16 -> 0.61344864 | I5: Año 1 | J5: ='Flujo de Caja'!#REF! -> #REF! | L5: VPN | M5: =M6+J4 -> #REF!
B6: Rentabilidad operacional | C6: ='Estado de Resultados'!#REF!/'Estado de Resultados'!#REF! -> #REF! | D6: ='Estado de Resultados'!#REF!/'Estado de Resultados'!#REF! -> #REF! | E6: ='Estado de Resultados'!#REF!/'Estado de Resultados'!#REF! -> #REF! | F6: ='Estado de Resultados'!#REF!/'Estado de Resultados'!#REF! -> #REF! | G6: ='Estado de Resultados'!#REF!/'Estado de Resultados'!#REF! -> #REF! | I6: Año 2 | J6: ='Flujo de Caja'!#REF! -> #REF! | L6: VAN | M6: =NPV(M4,J5:J9) -> #REF!
B7: Rentabilidad neta | C7: ='Estado de Resultados'!#REF!/'Estado de Resultados'!#REF! -> #REF! | D7: ='Estado de Resultados'!#REF!/'Estado de Resultados'!#REF! -> #REF! | E7: ='Estado de Resultados'!#REF!/'Estado de Resultados'!#REF! -> #REF! | F7: ='Estado de Resultados'!#REF!/'Estado de Resultados'!#REF! -> #REF! | G7: ='Estado de Resultados'!#REF!/'Estado de Resultados'!#REF! -> #REF! | I7: Año 3 | J7: ='Flujo de Caja'!#REF! -> #REF! | L7: TIR | M7: =IRR(J4:J9) -> #VALUE!
B8: Rentabilidad de patriominio | C8: ='Estado de Resultados'!#REF!/'Balance General'!#REF! -> #REF! | D8: ='Estado de Resultados'!#REF!/'Balance General'!#REF! -> #REF! | E8: ='Estado de Resultados'!#REF!/'Balance General'!#REF! -> #REF! | F8: ='Estado de Resultados'!#REF!/'Balance General'!#REF! -> #REF! | G8: ='Estado de Resultados'!#REF!/'Balance General'!#REF! -> #REF! | I8: Año 4 | J8: ='Flujo de Caja'!#REF! -> #REF! | L8: RBC | M8: =-NPV(M4,J5:J9)/J4 -> #REF!
I9: Año 5 | J9: ='Flujo de Caja'!#REF! -> #REF!
