Workbook

Sheet Inversión Inicial
A1: Inversión Inicial
A2: Tipo de inversión | B2: Valor
A3: Planeación y diseño UX/UI | B3: =B25 -> 5000000
A4: Producción y creación de contenidos interactivos | B4: =B33 -> 3740000
A5: Equipos de cómputo y hardware | B5: =D18 -> 9100000
A6: Marketing, lanzamiento y proyección | B6: =B41 -> 16000000
A7: Consultoría especializada y mentoría | B7: =B48 -> 6000000
A8: Creación de infraestructura y arquitectura de software | B8: =B56 -> 3700000
A9: Capital de trabajo | B9: =B60 -> 1000000
A10: TOTAL | B10: =SUM(B3:B8) -> 43540000
A12: Recursos Físicos (Activos Fijos Tangibles)
A13: Concepto | B13: Cantidad | C13: Valor Unitario | D13: Valor Total
A14: Computadoras o laptops | B14: 2 | C14: 3000000 | D14: =C14*B14 -> 6000000
A15: Monitores | B15: 2 | C15: 800000 | D15: =C15*B15 -> 1600000
A16: Perifericos (mouse, teclados, audífonos) | B16: 2 | C16: 300000 | D16: =C16*B16 -> 600000
A17: Accesorios (Papelería, etc) | B17: 2 | C17: 450000 | D17: =C17*B17 -> 900000
A18: SUBTOTAL | D18: =SUM(D14:D17) -> 9100000
A20: Inversión en Planeación y Diseño UX/UI
A21: Concepto | B21: Valor
A22: Investigación UX (tesis y entrevistas) | B22: 1500000
A23: Diseño UI (mockups y prototipos) | B23: 2000000
A24: Prubeas de Usabilidad y Ajustes | B24: 1500000
A25: SUBTOTAL | B25: =SUM(B22:B24) -> 5000000
A27: Inversión en Producción y Creación de Contenidos Interactivos
A28: Concepto | B28: Valor
A29: Guión y diseño | B29: 920000
A30: Desarrollo de simuladores | B30: 1300000
A31: Licencias y recursos (stock y assets) | B31: 600000
A32: Producción multimedia (audios y videos) | B32: 920000
A33: SUBTOTAL | B33: =SUM(B29:B32) -> 3740000
A35: Inversión en Marketing, Lanzamiento y Proyección
A36: Concepto | B36: Valor
A37: Estrategia y branding (Diseño y marca) | B37: 3500000
A38: Campañas digitales (Google Ads o RRSS) | B38: 7000000
A39: Producción audiovisual promocional | B39: 3500000
A40: Eventos y demostraciones (Material físico) | B40: 2000000
A41: SUBTOTAL | B41: =SUM(B37:B40) -> 16000000
A43: Inversión en Consultoría Especializada
A44: Concepto | B44: Valor
A45: Asesoría legal y cumplimiento | B45: 2000000
...

Sheet Costos de Operación Gravables
A1: Costos de Operación Gravables | F1: Costos de Operación Gravables (valor trimestral)
A2: Sueldos de los Empleados | F2: Sueldos de los Empleados
A3: Tipo de inversión | B3: Unidades | C3: Valor Unitario/mes | D3: Valor Total/mes | F3: Valor de 0 | G3: Conversión Anual | H3: Tasa de Crecimiento | I3: Año 0 | J3: Año 1 | K3: Año 2 | L3: Año 3 | M3: Año 4 | N3: Año 5
A4: Líder de Desarrollo | B4: 1 | C4: 3000000 | D4: =C4*B4 -> 3000000 | F4: =D6 -> 6000000 | G4: =F4*12 -> 72000000 | H4: 0.1 | I4: 0 | J4: =G4 -> 72000000 | K4: =J$4*($H$4+1) -> 79200000 | L4: =K$4*($H$4+1) -> 87120000 | M4: =L$4*($H$4+1) -> 95832000 | N4: =M$4*($H$4+1) -> 1.054152e+08
A5: Líder I+D+I | B5: 1 | C5: 3000000 | D5: =C5*B5 -> 3000000 | F5: Prestaciones y Parafiscales
A6: Total | C6: =SUM(C4:C5) -> 6000000 | D6: =SUM(D4:D5) -> 6000000 | F6: Valor de 0 | G6: Conversión Anual | H6: Tasa de Crecimiento | I6: Año 0 | J6: Año 1 | K6: Año 2 | L6: Año 3 | M6: Año 4 | N6: Año 5
A7: Prestaciones y Parafiscales | F7: =D17 -> 1788578 | G7: =F7*12 -> 21462936 | H7: 0.1 | I7: 0 | J7: =G7 -> 21462936 | K7: =J7*($H$7+1) -> 23609230 | L7: =K7*($H$7+1) -> 25970153 | M7: =L7*($H$7+1) -> 28567168 | N7: =M7*($H$7+1) -> 31423885
A8: Tipo de inversión | B8: Unidades | C8: Valor Unitario/mes | D8: Valor Total/mes | F8: Servicios e Infraestructuras
A9: Cesantias | B9: =SUM($B$4:$B$6) -> 2 | C9: 166600 | D9: =C9*B9 -> 333200 | F9: Valor de 0 | G9: Conversión Anual | H9: Tasa de Crecimiento | I9: Año 0 | J9: Año 1 | K9: Año 2 | L9: Año 3 | M9: Año 4 | N9: Año 5
A10: Intereses sobre cesantias | B10: =SUM($B$4:$B$6) -> 2 | C10: 20000 | D10: =C10*B10 -> 40000 | F10: =D22 -> 3720000 | G10: =F10*12 -> 44640000 | H10: 0.06 | I10: 0 | J10: =G10 -> 44640000 | K10: =J10*($H$10+1) -> 47318400 | L10: =K10*($H$7+1) -> 52050240 | M10: =L10*($H$7+1) -> 57255264 | N10: =M10*($H$7+1) -> 62980790
A11: Primas | B11: =SUM($B$4:$B$6) -> 2 | C11: 166600 | D11: =C11*B11 -> 333200 | F11: Otros
A12: Vacaciones | B12: =SUM($B$4:$B$6) -> 2 | C12: 73013 | D12: =C12*B12 -> 146026 | F12: Valor de 0 | G12: Conversión Anual | H12: Tasa de Crecimiento | I12: Año 0 | J12: Año 1 | K12: Año 2 | L12: Año 3 | M12: Año 4 | N12: Año 5
A13: Pensiones (AFP) | B13: =SUM($B$4:$B$6) -> 2 | C13: 210109 | D13: =C13*B13 -> 420218 | F13: =D26 -> 1451000 | G13: N/A | H13: N/A | I13: =F13 -> 1451000
A14: Salud (EPS) | B14: =SUM($B$4:$B$6) -> 2 | C14: 148827 | D14: =C14*B14 -> 297654 | F14: TOTAL
A15: Riesgos Laborales (ARL) | B15: =SUM($B$4:$B$6) -> 2 | C15: 9140 | D15: =C15*B15 -> 18280 | I15: =SUM(I4,I7,I10,I13) -> 1451000 | J15: =SUM(J4,J7,J10,J13) -> 138102936 | K15: =SUM(K4,K7,K10,K13) -> 1.5012763e+08 | L15: =SUM(L4,L7,L10,L13) -> 1.6514039e+08 | M15: =SUM(M4,M7,M10,M13) -> 1.8165443e+08 | N15: =SUM(N4,N7,N10,N13) -> 1.9981987e+08
A16: Caja de Compensación Familiar | B16: =SUM($B$4:$B$6) -> 2 | C16: 100000 | D16: =C16*B16 -> 200000
A17: Total | C17: =SUM(C9:C16) -> 894289 | D17: =SUM(D9:D16) -> 1788578 | J17: =J15/J18 -> 2327.6738 | K17: =K15/K18 -> 2009.8059 | L17: =L15/L18 -> 1717.7828 | M17: =M15/M18 -> 1426.0838 | N17: =N15/N18 -> 1141.6974 | P17: =SUM(J17:N17)/5 -> 1724.6087
A18: Servicios e Infraestructura | J18: ='Proyección de Ventas e Incremen'!J18 -> 59330.88 | K18: ='Proyección de Ventas e Incremen'!K18 -> 74697.578 | L18: ='Proyección de Ventas e Incremen'!L18 -> 96135.783 | M18: ='Proyección de Ventas e Incremen'!M18 -> 127379.91 | N18: ='Proyección de Ventas e Incremen'!N18 -> 175020
A19: Tipo de inversión | B19: Unidades | C19: Valor Unitario/mes | D19: Valor Total/mes
A20: Servicio de Internet | B20: 1 | C20: 220000 | D20: =C20*B20 -> 220000
A21: Servicios de Infraestructura de TI/Hosting del Sitio | B21: 1 | C21: 3500000 | D21: =C21*B21 -> 3500000
A22: Total | C22: =SUM(C20:C21) -> 3720000 | D22: =SUM(D20:D21) -> 3720000
A23: Otros
A24: Tipo de inversión | B24: Unidades | C24: Valor Unitario/mes | D24: Valor Total/mes
A25: Registros y Estatutos | B25: 1 | C25: =B36 -> 1451000 | D25: =C25*B25 -> 1451000
A26: Total | C26: =SUM(C25) -> 1451000 | D26: =SUM(D25) -> 1451000
A28: Activos Fijos Intangibles
A29: Concepto | B29: Valor
A30: Registro de Marca | B30: 1288000
A31: Estatutos | B31: 30000
A32: Registro Cámara de Comercio de Bogotá | B32: 69000
A33: Inscripción de Libros Contables | B33: 64000
A34: Apertura de Cuentas Bancarias | B34: N/A
A35: Formulario Único de Registro Empresarial | B35: N/A
A36: Total | B36: =SUM(B30:B33) -> 1451000
A38: Suma de Activos Fijos
A39: Concepto | B39: Valor
A40: Activos fijos tangibles | B40: ='Inversión Inicial'!D18 -> 9100000
A41: Activos fijos intangibles | B41: =B36 -> 1451000
A42: Planeación y diseño UX/UI | B42: ='Inversión Inicial'!B3 -> 5000000
...

Sheet Proyección de Ventas e Incremen
A1: Ingresos y Proyecciones de Venta | H1: Proyección Incremento de Ventas
A2: Ingresos | H2: IPC Proyectado y Flujo de Efectivo
A3: Concepto | C3: Unidades | D3: Valor/mes | E3: Valor/trimestre | F3: Valor/año | H3: Indicador | I3: Año 0 | J3: Año 1 (2027) | K3: Año 2 (2028) | L3: Año 3 (2029) | M3: Año 4 (2030) | N3: Año 5 (2031)
A4: Plan Gratuito | C4: N/A | D4: 0 | E4: =D4*3 -> 0 | F4: =D4*12 -> 0 | H4: IPC Proyectado | J4: 0.046 | K4: 0.039 | L4: 0.037 | M4: 0.035 | N4: 0.034
A5: Plan Suscriptor | C5: N/A | D5: 30000 | E5: =D5*3 -> 90000 | F5: =D5*12 -> 360000 | H5: % Crecimiento de Ventas | J5: 0.25 | K5: 0.22 | L5: 0.25 | M5: 0.29 | N5: 0.34
A6: Publicidad de Plan Gratuito | C6: N/A | D6: 300 | E6: =D6*3 -> 900 | F6: =D6*12 -> 3600 | H6: Crecimiento de ventas indexación IPC y % crecimiento | J6: =SUM(J4:J5) -> 0.296 | K6: =SUM(K4:K5) -> 0.259 | L6: =SUM(L4:L5) -> 0.287 | M6: =SUM(M4:M5) -> 0.325 | N6: =SUM(N4:N5) -> 0.374
A7: Proyección de Ventas | H7: Flujo de efectivo | J7: =F12*(1+J6) -> 163296000 | K7: =J7*(1+K6) -> 2.0558966e+08 | L7: =K7*(1+L6) -> 2.645939e+08 | M7: =L7*(1+M6) -> 3.5058691e+08 | N7: =M7*(1+N6) -> 4.8170642e+08
A8: Servicio | B8: Valor/mes | C8: N° Suscripción/mes | D8: Ingreso/mes | E8: Ingreso/trimestre | F8: Ingreso/anual
A9: Plan Gratuito | B9: =D4 -> 0 | C9: 3500 | D9: =B9*$C$9 -> 0 | E9: =D9*3 -> 0 | F9: =D9*12 -> 0
A10: Plan Suscriptor | B10: =D5 -> 30000 | C10: =C9*0.09 -> 315 | D10: =B10*$C$10 -> 9450000 | E10: =D10*3 -> 28350000 | F10: =D10*12 -> 113400000 | G10: 0.9 | I10: =F10 -> 113400000 | J10: =J$7*$G10 -> 146966400 | K10: =K$7*$G10 -> 1.850307e+08 | L10: =L$7*$G10 -> 2.3813451e+08 | M10: =M$7*$G10 -> 3.1552822e+08 | N10: =N$7*$G10 -> 4.3353578e+08
A11: Publicidad de Plan Gratuito | B11: 300 | C11: =C9 -> 3500 | D11: =B11*$C$11 -> 1050000 | E11: =D11*3 -> 3150000 | F11: =D11*12 -> 12600000 | G11: 0.1 | I11: =F11 -> 12600000 | J11: =J$7*$G11 -> 16329600 | K11: =K$7*$G11 -> 20558966 | L11: =L$7*$G11 -> 26459390 | M11: =M$7*$G11 -> 35058691 | N11: =N$7*$G11 -> 48170642
A12: Total | C12: =SUM(C10:C11) -> 3815 | D12: =SUM(D9:D11) -> 10500000 | E12: =SUM(E9:E11) -> 31500000 | F12: =SUM(F9:F11) -> 126000000
I13: =I10/(12*30000) -> 315 | J13: =J10/(12*30000) -> 408.24 | K13: =K10/(12*30000) -> 513.97416 | L13: =L10/(12*30000) -> 661.48474 | M13: =M10/(12*30000) -> 876.46729 | N13: =N10/(12*30000) -> 1204.2661
A14: Tabla de Financiamiento | I14: =I11/(12*300) -> 3500 | J14: =J11/(12*300) -> 4536 | K14: =K11/(12*300) -> 5710.824 | L14: =L11/(12*300) -> 7349.8305 | M14: =M11/(12*300) -> 9738.5254 | N14: =N11/(12*300) -> 13380.734
A15: Concepto | B15: Valor
A16: Financiamiento externo | B16: ='Costos de Operación Gravables'!$B$48*0.55 -> 25295050 | J16: =(SUM(J10:J12)/12)/SUM(J13:J14) -> 2752.2936 | K16: =(SUM(K10:K12)/12)/SUM(K13:K14) -> 2752.2936 | L16: =(SUM(L10:L12)/12)/SUM(L13:L14) -> 2752.2936 | M16: =(SUM(M10:M12)/12)/SUM(M13:M14) -> 2752.2936 | N16: =(SUM(N10:N12)/12)/SUM(N13:N14) -> 2752.2936
A17: Aportes sociales (Fin. por socios) | B17: ='Costos de Operación Gravables'!$B$48*0.45 -> 20695950
A18: Total | B18: =SUM(B16:B17) -> 45991000 | J18: =SUM(J13:J14)*12 -> 59330.88 | K18: =SUM(K13:K14)*12 -> 74697.578 | L18: =SUM(L13:L14)*12 -> 96135.783 | M18: =SUM(M13:M14)*12 -> 127379.91 | N18: =SUM(N13:N14)*12 -> 175020
A20: Contribución de los Socios
A21: Concepto | B21: Participación | C21: Valor
A22: David Rincón | B22: 0.5 | C22: =$B$17*B22 -> 10347975
A23: Leidy Marcela | B23: 0.5 | C23: =$B$17*B23 -> 10347975
A24: Total | B24: =SUM(B22:B23) -> 1 | C24: =SUM(C22:C23) -> 20695950

Sheet Amortización y Depreciación
A1: Amortización y Depreciación | D1: Amortización del Crédito
A2: Préstamo (en Banco GNB Sudameris) | D2: Período | E2: Saldo | F2: Interés | G2: Pago al crédito | H2: Amortización | I2: Saldo final
A3: Concepto | B3: Unidades | D3: 0 (Año 0) | E3: =B4 -> 25295050 | F3: 0 | G3: 0 | H3: 0 | I3: =E3 -> 25295050
A4: Valor del préstamo | B4: ='Proyección de Ventas e Incremen'!B16 -> 25295050 | D4: 1 (Año 1) | E4: =I3 -> 25295050 | F4: =E4*$B$7 -> 4209096.3 | G4: =$B$8 -> 9155561.1 | H4: =G4-F4 -> 4946464.8 | I4: =E4-H4 -> 20348585
A5: Cuota inicial | B5: 0 | D5: 2 (Año 2) | E5: =I4 -> 20348585 | F5: =E5*$B$7 -> 3386004.6 | G5: =$B$8 -> 9155561.1 | H5: =G5-F5 -> 5769556.5 | I5: =E5-H5 -> 14579029
A6: Plazo de meses/períodos | B6: 48 meses | D6: 3 (Año 3) | E6: =I5 -> 14579029 | F6: =E6*$B$7 -> 2425950.4 | G6: =$B$8 -> 9155561.1 | H6: =G6-F6 -> 6729610.7 | I6: =E6-H6 -> 7849418
A7: Tasa de interés (anualmente) | B7: 0.1664 | D7: 4 (Año 4) | E7: =I6 -> 7849418 | F7: =E7*$B$7 -> 1306143.2 | G7: =$B$8 -> 9155561.1 | H7: =G7-F7 -> 7849417.9 | I7: =E7-H7 -> 0.0276605
A8: Pago anual | B8: =((B4*1.44780279145524)/4)+0.1 -> 9155561.1 | D8: 5 (Año 5) | E8: =I7 -> 0.0276605 | F8: =E8*$B$7 -> 0.0046027072 | G8: 0 | H8: =G8-F8 -> -0.0046027072 | I8: =E8-H8 -> 0.032263208 | K8: =SUM(G4:G7) -> 36622244
A9: Pago mensual | B9: =B8/12 -> 762963.42
D10: Depreciación
D11: Activos Fijos | E11: Vida Útil | F11: Valor Inicial | G11: Año 1 | H11: Año 2 | I11: Año 3 | J11: Año 4 | K11: Año 5
D12: Computador 1 | E12: 5 años | F12: ='Inversión Inicial'!$C$14 -> 3000000 | G12: =$F12*G$17 -> 600000 | H12: =$F12*H$17 -> 1200000 | I12: =$F12*I$17 -> 1800000 | J12: =$F12*J$17 -> 2400000 | K12: =$F12*K$17 -> 3000000
D13: Perifericos 1 | E13: 5 años | F13: ='Inversión Inicial'!$C$16 -> 300000 | G13: =$F13*G$17 -> 60000 | H13: =$F13*H$17 -> 120000 | I13: =$F13*I$17 -> 180000 | J13: =$F13*J$17 -> 240000 | K13: =$F13*K$17 -> 300000
D14: Computador 2 | E14: 5 años | F14: ='Inversión Inicial'!$C$14 -> 3000000 | G14: =$F14*G$17 -> 600000 | H14: =$F14*H$17 -> 1200000 | I14: =$F14*I$17 -> 1800000 | J14: =$F14*J$17 -> 2400000 | K14: =$F14*K$17 -> 3000000
D15: Perifericos 2 | E15: 5 años | F15: ='Inversión Inicial'!$C$16 -> 300000 | G15: =$F15*G$17 -> 60000 | H15: =$F15*H$17 -> 120000 | I15: =$F15*I$17 -> 180000 | J15: =$F15*J$17 -> 240000 | K15: =$F15*K$17 -> 300000
D16: Depreciación Total | G16: =SUM(G12:G15) -> 1320000 | H16: =SUM(H12:H15) -> 2640000 | I16: =SUM(I12:I15) -> 3960000 | J16: =SUM(J12:J15) -> 5280000 | K16: =SUM(K12:K15) -> 6600000
D17: Tasa de Depreciación Total | G17: 0.2 | H17: 0.4 | I17: 0.6 | J17: 0.8 | K17: 1
D19: Depreciación
D20: Activos Fijos | E20: Vida Útil | F20: Valor Inicial | G20: Año 1 | H20: Año 2 | I20: Año 3 | J20: Año 4 | K20: Año 5
D21: Computador 1 | E21: 5 años | F21: ='Inversión Inicial'!$C$14 -> 3000000 | G21: =$F21-($F21*G$26) -> 2400000 | H21: =$F21-($F21*H$26) -> 1800000 | I21: =$F21-($F21*I$26) -> 1200000 | J21: =$F21-($F21*J$26) -> 600000 | K21: =$F21-($F21*K$26) -> 0
D22: Perifericos 1 | E22: 5 años | F22: ='Inversión Inicial'!$C$16 -> 300000 | G22: =$F22-($F22*G$26) -> 240000 | H22: =$F22-($F22*H$26) -> 180000 | I22: =$F22-($F22*I$26) -> 120000 | J22: =$F22-($F22*J$26) -> 60000 | K22: =$F22-($F22*K$26) -> 0
D23: Computador 2 | E23: 5 años | F23: ='Inversión Inicial'!$C$14 -> 3000000 | G23: =$F23-($F23*G$26) -> 2400000 | H23: =$F23-($F23*H$26) -> 1800000 | I23: =$F23-($F23*I$26) -> 1200000 | J23: =$F23-($F23*J$26) -> 600000 | K23: =$F23-($F23*K$26) -> 0
D24: Perifericos 2 | E24: 5 años | F24: ='Inversión Inicial'!$C$16 -> 300000 | G24: =$F24-($F24*G$26) -> 240000 | H24: =$F24-($F24*H$26) -> 180000 | I24: =$F24-($F24*I$26) -> 120000 | J24: =$F24-($F24*J$26) -> 60000 | K24: =$F24-($F24*K$26) -> 0
D25: Depreciación Total | G25: =SUM(G21:G24) -> 5280000 | H25: =SUM(H21:H24) -> 3960000 | I25: =SUM(I21:I24) -> 2640000 | J25: =SUM(J21:J24) -> 1320000 | K25: =SUM(K21:K24) -> 0
D26: Tasa de Depreciación Total | G26: 0.2 | H26: 0.4 | I26: 0.6 | J26: 0.8 | K26: 1

Sheet Balance General
A1: BALANCE GENERAL PROYECTADO
A2: EDUCAFIN S.A.S.
A4: TRIMESTRE | C4: AÑO 0 | D4: AÑO 1 | E4: AÑO 2 | F4: AÑO 3 | G4: AÑO 4 | H4: AÑO 5
A5: ACTIVOS
A6: ACTIVOS CORRIENTES
B7: Efectivo y Equivalente de Efectivo | C7: ='Proyección de Ventas e Incremen'!I7 -> 0 | D7: ='Proyección de Ventas e Incremen'!J7 -> 163296000 | E7: ='Proyección de Ventas e Incremen'!K7 -> 2.0558966e+08 | F7: ='Proyección de Ventas e Incremen'!L7 -> 2.645939e+08 | G7: ='Proyección de Ventas e Incremen'!M7 -> 3.5058691e+08 | H7: ='Proyección de Ventas e Incremen'!N7 -> 4.8170642e+08
B8: Cuentas por Cobrar al Personal y Accionistas | C8: ='[1]Proyección de Ventas e Incremen'!I8 -> 0 | D8: 0 | E8: 0 | F8: 0 | G8: 0 | H8: 0
B9: Gastos Pagados por Anticipado | C9: 0 | D9: 0 | E9: 0 | F9: 0 | G9: 0 | H9: 0
B10: Otros Activos | C10: 0 | D10: 0 | E10: 0 | F10: 0 | G10: 0 | H10: 0
B11: Total Activos Corrientes | C11: =SUM(C7:C10) -> 0 | D11: =SUM(D7:D10) -> 163296000 | E11: =SUM(E7:E10) -> 2.0558966e+08 | F11: =SUM(F7:F10) -> 2.645939e+08 | G11: =SUM(G7:G10) -> 3.5058691e+08 | H11: =SUM(H7:H10) -> 4.8170642e+08
A13: ACTIVOS NO CORRIENTES
B14: Equipos | C14: ='Inversión Inicial'!D18 -> 9100000 | D14: =C14 -> 9100000 | E14: =D14 -> 9100000 | F14: =E14 -> 9100000 | G14: =F14 -> 9100000 | H14: =G14 -> 9100000
B15: Depreciación de Equipos | C15: 0 | D15: ='Amortización y Depreciación'!G16 -> 1320000 | E15: ='Amortización y Depreciación'!H16 -> 2640000 | F15: ='Amortización y Depreciación'!I16 -> 3960000 | G15: ='Amortización y Depreciación'!J16 -> 5280000 | H15: ='Amortización y Depreciación'!K16 -> 6600000
B16: Intangibles | C16: ='Costos de Operación Gravables'!B36 -> 1451000 | D16: =C16 -> 1451000 | E16: =D16 -> 1451000 | F16: =E16 -> 1451000 | G16: =F16 -> 1451000 | H16: =G16 -> 1451000
B17: Total Activos No Corrientes | C17: =C14+C16 -> 10551000 | D17: =D14+D16-D15 -> 9231000 | E17: =E14+E16-E15 -> 7911000 | F17: =F14+F16-F15 -> 6591000 | G17: =G14+G16-G15 -> 5271000 | H17: =H14+H16-H15 -> 3951000
A19: ACTIVOS DIFERIDOS
B20: Propiedad Intelectual | C20: 0 | D20: 0 | E20: 0 | F20: 0 | G20: 0 | H20: 0
B21: Gastos Legales | C21: 0 | D21: 0 | E21: 0 | F21: 0 | G21: 0 | H21: 0
B22: Otros Seguros | C22: 0 | D22: 0 | E22: 0 | F22: 0 | G22: 0 | H22: 0
B23: Total Activos Diferidos | C23: =SUM(C20:C22) -> 0 | D23: =SUM(D20:D22) -> 0 | E23: =SUM(E20:E22) -> 0 | F23: =SUM(F20:F22) -> 0 | G23: =SUM(G20:G22) -> 0 | H23: =SUM(H20:H22) -> 0
A25: TOTAL ACTIVO | C25: =SUM(C11,C17,C23) -> 10551000 | D25: =SUM(D11,D17,D23) -> 172527000 | E25: =SUM(E11,E17,E23) -> 2.1350066e+08 | F25: =SUM(F11,F17,F23) -> 2.711849e+08 | G25: =SUM(G11,G17,G23) -> 3.5585791e+08 | H25: =SUM(H11,H17,H23) -> 4.8565742e+08
A26: PASIVOS
A27: PASIVOS CORRIENTES
B28: Prestaciones y Parafiscales | C28: ='Costos de Operación Gravables'!I7 -> 0 | D28: ='Costos de Operación Gravables'!J7 -> 21462936 | E28: ='Costos de Operación Gravables'!K7 -> 23609230 | F28: ='Costos de Operación Gravables'!L7 -> 25970153 | G28: ='Costos de Operación Gravables'!M7 -> 28567168 | H28: ='Costos de Operación Gravables'!N7 -> 31423885
B29: Infraestructura | C29: ='Costos de Operación Gravables'!I10 -> 0 | D29: ='Costos de Operación Gravables'!J10 -> 44640000 | E29: ='Costos de Operación Gravables'!K10 -> 47318400 | F29: ='Costos de Operación Gravables'!L10 -> 52050240 | G29: ='Costos de Operación Gravables'!M10 -> 57255264 | H29: ='Costos de Operación Gravables'!N10 -> 62980790
B30: Amortización | C30: ='Amortización y Depreciación'!G3 -> 0 | D30: ='Amortización y Depreciación'!G4 -> 9155561.1 | E30: ='Amortización y Depreciación'!G5 -> 9155561.1 | F30: ='Amortización y Depreciación'!G6 -> 9155561.1 | G30: ='Amortización y Depreciación'!G7 -> 9155561.1 | H30: ='Amortización y Depreciación'!G8 -> 0
B31: Nómina | C31: ='Costos de Operación Gravables'!I4 -> 0 | D31: ='Costos de Operación Gravables'!J4 -> 72000000 | E31: ='Costos de Operación Gravables'!K4 -> 79200000 | F31: ='Costos de Operación Gravables'!L4 -> 87120000 | G31: ='Costos de Operación Gravables'!M4 -> 95832000 | H31: ='Costos de Operación Gravables'!N4 -> 1.054152e+08
B32: Tributos (Impuestos) por pagar | C32: =C25*0.04 -> 422040 | D32: =D25*0.04 -> 6901080 | E32: =E25*0.04 -> 8540026.6 | F32: =F25*0.04 -> 10847396 | G32: =G25*0.04 -> 14234317 | H32: =H25*0.04 -> 19426297
B33: Total Pasivos Corrientes | C33: =SUM(C28:C32) -> 422040 | D33: =SUM(D28:D32) -> 1.5415958e+08 | E33: =SUM(E28:E32) -> 1.6782322e+08 | F33: =SUM(F28:F32) -> 1.8514335e+08 | G33: =SUM(G28:G32) -> 2.0504431e+08 | H33: =SUM(H28:H32) -> 2.1924617e+08
A35: PASIVOS NO CORRIENTES
B36: Préstamo | C36: ='Inversión Inicial'!#REF! -> #REF! | D36: 0 | E36: 0 | F36: 0 | G36: 0 | H36: 0
B37: Total Pasivos No Corrientes | C37: =SUM(C36) -> #REF! | D37: =SUM(D36) -> 0 | E37: =SUM(E36) -> 0 | F37: =SUM(F36) -> 0 | G37: =SUM(G36) -> 0 | H37: =SUM(H36) -> 0
A39: TOTAL PASIVOS | C39: =C33+C37 -> #REF! | D39: =D33+D37 -> 1.5415958e+08 | E39: =E33+E37 -> 1.6782322e+08 | F39: =F33+F37 -> 1.8514335e+08 | G39: =G33+G37 -> 2.0504431e+08 | H39: =H33+H37 -> 2.1924617e+08
A41: CAPITAL
B42: Capital Social | C42: ='Inversión Inicial'!#REF! -> #REF! | D42: =C42 -> #REF! | E42: =D42 -> #REF! | F42: =E42 -> #REF! | G42: =F42 -> #REF! | H42: =G42 -> #REF!
B43: Utilidad o Pérdida del Ejercicio | C43: ='Estado de Resultados'!#REF! -> #REF! | D43: ='Estado de Resultados'!#REF! -> #REF! | E43: ='Estado de Resultados'!#REF! -> #REF! | F43: ='Estado de Resultados'!#REF! -> #REF! | G43: ='Estado de Resultados'!#REF! -> #REF! | H43: ='Estado de Resultados'!#REF! -> #REF!
A45: TOTAL CAPITAL | C45: =SUM(C42:C43) -> #REF! | D45: =SUM(D42:D43) -> #REF! | E45: =SUM(E42:E43) -> #REF! | F45: =SUM(F42:F43) -> #REF! | G45: =SUM(G42:G43) -> #REF! | H45: =SUM(H42:H43) -> #REF!
A47: SUMA PASIVOS + CAPITAL | C47: =C39+C45 -> #REF! | D47: =D39+D45 -> #REF! | E47: =E39+E45 -> #REF! | F47: =F39+F45 -> #REF! | G47: =G39+G45 -> #REF! | H47: =H39+H45 -> #REF!

Sheet Estado de Resultados
A1: ESTADO DE RESULTADOS PROYECTADOS
A2: EDUCAFIN S.A.S.
A4: TRIMESTRE | C4: AÑO 0 | D4: AÑO 1 | E4: AÑO 2 | F4: AÑO 3 | G4: AÑO 4 | H4: AÑO 5
A5: UTILIDAD BRUTA
B6: Ingresos obtenidos por el negocio | D6: ='Proyección de Ventas e Incremen'!J7 -> 163296000 | E6: ='Proyección de Ventas e Incremen'!K7 -> 2.0558966e+08 | F6: ='Proyección de Ventas e Incremen'!L7 -> 2.645939e+08 | G6: ='Proyección de Ventas e Incremen'!M7 -> 3.5058691e+08 | H6: ='Proyección de Ventas e Incremen'!N7 -> 4.8170642e+08
B7: Costo de venta
B8: Total de Utilidad Bruta | C8: =SUM(C6:C7) -> 0 | D8: =D6-D7 -> 163296000 | E8: =E6-E7 -> 2.0558966e+08 | F8: =F6-F7 -> 2.645939e+08 | G8: =G6-G7 -> 3.5058691e+08 | H8: =H6-H7 -> 4.8170642e+08
A10: UTILIDAD PREVIO A IMPUESTOS
B11: Gastos fijos
B12: Depreciación de aparatos | D12: ='Flujo de Caja'!D23 -> 1320000 | E12: ='Flujo de Caja'!E23 -> 1320000 | F12: ='Flujo de Caja'!F23 -> 1320000 | G12: ='Flujo de Caja'!G23 -> 1320000 | H12: ='Flujo de Caja'!H23 -> 1320000
B13: Gastos y productos financieros
B14: Total de Utilidad Previo a Impuestos | C14: =SUM(C12:C13) -> 0 | D14: =SUM(D12:D13) -> 1320000 | E14: =SUM(E12:E13) -> 1320000 | F14: =SUM(F12:F13) -> 1320000 | G14: =SUM(G12:G13) -> 1320000 | H14: =SUM(H12:H13) -> 1320000
B16: Impuesto sobre la renta

Sheet Flujo de Caja
A1: FLUJO DE CAJA PROYECTADO
A2: EDUCAFIN S.A.S.
A4: TRIMESTRE | C4: AÑO 0 | D4: AÑO 1 | E4: AÑO 2 | F4: AÑO 3 | G4: AÑO 4 | H4: AÑO 5
A5: ENTRADAS
B6: Aportaciones de socios | C6: ='Proyección de Ventas e Incremen'!B17 -> 20695950
B7: Aportaciones de financiamiento bancario | C7: ='Proyección de Ventas e Incremen'!B16 -> 25295050
B8: Ingresos obtenidos del negocio | D8: ='Proyección de Ventas e Incremen'!J7 -> 163296000 | E8: ='Proyección de Ventas e Incremen'!K7 -> 2.0558966e+08 | F8: ='Proyección de Ventas e Incremen'!L7 -> 2.645939e+08 | G8: ='Proyección de Ventas e Incremen'!M7 -> 3.5058691e+08 | H8: ='Proyección de Ventas e Incremen'!N7 -> 4.8170642e+08
B9: Total Entradas/Ingresos | C9: =SUM(C6:C8) -> 45991000 | D9: =SUM(D6:D8) -> 163296000 | E9: =SUM(E6:E8) -> 2.0558966e+08 | F9: =SUM(F6:F8) -> 2.645939e+08 | G9: =SUM(G6:G8) -> 3.5058691e+08 | H9: =SUM(H6:H8) -> 4.8170642e+08
A11: SALIDAS
B12: Inversiones hacia activos fijos | C12: =SUM('Costos de Operación Gravables'!B40:B46) -> 44991000
B13: Compras realizadas
B14: Gastos generales
B15: Depreciación anual | D15: ='Amortización y Depreciación'!G16 -> 1320000 | E15: =D15 -> 1320000 | F15: =E15 -> 1320000 | G15: =F15 -> 1320000 | H15: =G15 -> 1320000
B16: Capital de trabajo | C16: ='Inversión Inicial'!B9 -> 1000000
B17: Intereses del financiamiento | D17: ='Amortización y Depreciación'!F4 -> 4209096.3 | E17: ='Amortización y Depreciación'!F5 -> 3386004.6 | F17: ='Amortización y Depreciación'!F6 -> 2425950.4 | G17: ='Amortización y Depreciación'!F7 -> 1306143.2
B18: Impuesto sobre la renta
B19: Total Salidas | C19: =SUM(C12:C18) -> 45991000 | D19: =SUM(D12:D18) -> 5529096.3 | E19: =SUM(E12:E18) -> 4706004.6 | F19: =SUM(F12:F18) -> 3745950.4 | G19: =SUM(G12:G18) -> 2626143.2 | H19: =SUM(H12:H18) -> 1320000
A21: Disponibilidad de efectivo | C21: =-C19 -> -45991000 | D21: =D9-D19 -> 1.577669e+08 | E21: =E9-E19 -> 2.0088366e+08 | F21: =F9-F19 -> 2.6084795e+08 | G21: =G9-G19 -> 3.4796077e+08 | H21: =H9-H19 -> 4.8038642e+08
B23: Depreciaciones | D23: =D15 -> 1320000 | E23: =D23 -> 1320000 | F23: =E23 -> 1320000 | G23: =F23 -> 1320000 | H23: =G23 -> 1320000
A25: FLUJOS DE EFECTIVO | C25: =C21 -> -45991000 | D25: =D21+D23 -> 1.590869e+08 | E25: =E21+E23 -> 2.0220366e+08 | F25: =F21+F23 -> 2.6216795e+08 | G25: =G21+G23 -> 3.4928077e+08 | H25: =H21+H23 -> 4.8170642e+08

Sheet Flujo de Efectivo
A1: FLUJO DE EFECTIVO
A2: EDUCAFIN S.A.S.
A4: TRIMESTRE | C4: AÑO 0 | D4: AÑO 1 | E4: AÑO 2 | F4: AÑO 3 | G4: AÑO 4 | H4: AÑO 5
A5: FLUJO DE CAJA DE OPERACIÓN
B6: Utilidad del ejercicio
B7: Depreciaciones | C7: 0 | D7: ='Flujo de Caja'!D15 -> 1320000 | E7: =D7*2 -> 2640000 | F7: =D7*3 -> 3960000 | G7: =D7*4 -> 5280000 | H7: =D7*5 -> 6600000
B8: Amortización | C8: 0 | D8: ='Amortización y Depreciación'!H4 -> 4946464.8 | E8: ='Amortización y Depreciación'!H5 -> 5769556.5 | F8: ='Amortización y Depreciación'!H6 -> 6729610.7 | G8: ='Amortización y Depreciación'!H7 -> 7849417.9 | H8: ='Amortización y Depreciación'!H8 -> -0.0046027072
B9: Intereses | C9: 0 | D9: ='Amortización y Depreciación'!F4 -> 4209096.3 | E9: ='Amortización y Depreciación'!F5 -> 3386004.6 | F9: ='Amortización y Depreciación'!F6 -> 2425950.4 | G9: ='Amortización y Depreciación'!F7 -> 1306143.2 | H9: ='Amortización y Depreciación'!F8 -> 0.0046027072
B10: Impuestos de la renta
B11: Flujo de Caja Operativo Neto | C11: =SUM(C6:C10) -> 0 | D11: =SUM(D6:D10) -> 10475561 | E11: =SUM(E6:E10) -> 11795561 | F11: =SUM(F6:F10) -> 13115561 | G11: =SUM(G6:G10) -> 14435561 | H11: =SUM(H6:H10) -> 6600000
A13: FLUJO DE CAJA DE INVERSIÓN
B14: Inversión de equipos de computación | C14: ='Inversión Inicial'!B5 -> 9100000 | D14: =0 -> 0 | E14: =0 -> 0 | F14: =0 -> 0 | G14: =0 -> 0 | H14: =0 -> 0
B15: Flujo de Caja de Inversión Neto | C15: =SUM(C14:C14) -> 9100000 | D15: =SUM(D14:D14) -> 0 | E15: =SUM(E14:E14) -> 0 | F15: =SUM(F14:F14) -> 0 | G15: =SUM(G14:G14) -> 0 | H15: =SUM(H14:H14) -> 0
A17: FLUJO DE CAJA DE FINANCIAMIENTO
B18: Capital social | C18: ='Proyección de Ventas e Incremen'!B17 -> 20695950 | D18: =0 -> 0 | E18: =0 -> 0 | F18: =0 -> 0 | G18: =0 -> 0 | H18: =0 -> 0
B19: Desembolso pasivos a largo plazo
B20: Amortizaciones | C20: =C8 -> 0 | D20: =D8 -> 4946464.8 | E20: =E8 -> 5769556.5 | F20: =F8 -> 6729610.7 | G20: =G8 -> 7849417.9 | H20: =H8 -> -0.0046027072
B21: Intereses | C21: =C9 -> 0 | D21: =D9 -> 4209096.3 | E21: =E9 -> 3386004.6 | F21: =F9 -> 2425950.4 | G21: =G9 -> 1306143.2 | H21: =H9 -> 0.0046027072
B22: Pago de dividendos
B23: Flujo de Caja de Financiamiento Neto | C23: =SUM(C18:C21) -> 20695950 | D23: =SUM(D18:D21) -> 9155561.1 | E23: =SUM(E18:E21) -> 9155561.1 | F23: =SUM(F18:F21) -> 9155561.1 | G23: =SUM(G18:G21) -> 9155561.1 | H23: =SUM(H18:H21) -> 0

Sheet Costos Fijos y Punto de Equil.
B2: Punto de equilibrio | G2: Costos Fijos y Variables
B3: Precio de venta unitario promedio | C3: ='Proyección de Ventas e Incremen'!J16 -> 2752.2936 | G3: Costos y/o gastos | I3: Administración y ventas | J3: Producción
B4: Unidades a producir y vender al año | C4: =('Proyección de Ventas e Incremen'!J13+'Proyección de Ventas e Incremen'!J14)*12 -> 59330.88 | G4: Número de producción | I4: 0 | J4: ='Proyección de Ventas e Incremen'!J7 -> 163296000
B5: Ingresos por venta total anual | C5: =C3*C4 -> 163296000 | G5: Numero permanente (100%) | H5: =J4 -> 163296000 | I5: 0 | J5: 0
B6: Costo de producción | G6: Otros gastos administrativos | I6: = | J6: 0
B7: Costo unitario promedio ponderado | G7: Depreciación de producción | I7: 0 | J7: ='Balance General'!D15 -> 1320000
B8: Costos de porduccion total | G8: Depreciación de administración | I8: 0 | J8: 0
B9: Costos fijos (Gasto general anual) | G9: Subtotal | I9: =SUM(I4:I8) -> 0 | J9: =SUM(J4:J8) -> 164616000
G10: Imprevistos | H10: 0.1 | I10: =I9*$H$10 -> 0 | J10: =J9*$H$10 -> 16461600
G11: Total | I11: =I9+I10 -> 0 | J11: =J9+J10 -> 181077600
B13: Estimaciones del Punto de Equilibrio
B14: Ventas Iniciales Planteadas | C14: 3300
B15: Costo de producción por unidad | C15: =J11/C14 -> 54872
B16: Costo por unidad | C16: =SUM(I11:J11)/C14 -> 54872
B17: Valor agregado (19%) | C17: =C16*0.19 -> 10425.68
B18: Precio por unidad | C18: =SUM(C16:C17) -> 65297.68
B19: Punto de equilibrio | C19: =((C16-C15)*C14)/(C18-C16) -> 0
B21: Punto de Equilibrio
B22: Costo de referencia | C22: =C18 -> 65297.68
B23: Unidades mínimas vendidas | C23: 270
B24: Ventas anuales mínimas | C24: =C22*C23 -> 17630374

Sheet Grafica Punto de Equilibrio
C1: ='Costos Fijos y Punto de Equil.'!I11 -> 0
C2: ='Costos Fijos y Punto de Equil.'!C16 -> 54872 | D2: ='Costos Fijos y Punto de Equil.'!C18 -> 65297.68
C3: Costos | D3: Ventas
B4: 0 | C4: =($C$2*B4)+$C$1 -> 0 | D4: =$D$2*B4 -> 0
B5: 1 | C5: =($C$2*B5)+$C$1 -> 54872 | D5: =$D$2*B5 -> 65297.68
B6: 2 | C6: =($C$2*B6)+$C$1 -> 109744 | D6: =$D$2*B6 -> 130595.36
B7: 3 | C7: =($C$2*B7)+$C$1 -> 164616 | D7: =$D$2*B7 -> 195893.04
B8: 4 | C8: =($C$2*B8)+$C$1 -> 219488 | D8: =$D$2*B8 -> 261190.72
B9: 5 | C9: =($C$2*B9)+$C$1 -> 274360 | D9: =$D$2*B9 -> 326488.4
B10: 6 | C10: =($C$2*B10)+$C$1 -> 329232 | D10: =$D$2*B10 -> 391786.08
B11: 7 | C11: =($C$2*B11)+$C$1 -> 384104 | D11: =$D$2*B11 -> 457083.76
B12: 8 | C12: =($C$2*B12)+$C$1 -> 438976 | D12: =$D$2*B12 -> 522381.44
B13: 9 | C13: =($C$2*B13)+$C$1 -> 493848 | D13: =$D$2*B13 -> 587679.12
B14: 10 | C14: =($C$2*B14)+$C$1 -> 548720 | D14: =$D$2*B14 -> 652976.8
B15: 11 | C15: =($C$2*B15)+$C$1 -> 603592 | D15: =$D$2*B15 -> 718274.48
... B304: 300 | C304: =($C$2*B304)+$C$1 -> 16461600 | D304: =$D$2*B304 -> 19589304

Sheet Indicadores Financieros
B2: Indicadores financieros | I2: Flujo de caja libre | L2: VAN, TIR y RBC
B3: Período | C3: Año 1 | D3: Año 2 | E3: Año 3 | F3: Año 4 | G3: Año 5 | I3: Período | J3: Flujo de efectivo | L3: Tipo | M3: Valor
B4: Liquidez - razón corriente | C4: ='Balance General'!D11/'Balance General'!D33 -> 1.059266 | D4: ='Balance General'!E11/'Balance General'!E33 -> 1.2250371 | E4: ='Balance General'!F11/'Balance General'!F33 -> 1.4291299 | F4: ='Balance General'!G11/'Balance General'!G33 -> 1.7098105 | G4: ='Balance General'!H11/'Balance General'!H33 -> 2.197103 | I4: Año 0 | J4: ='Flujo de Caja'!#REF! -> #REF! | L4: TIO | M4: 0.15
B5: Nivel de endeudamiento total | C5: ='Balance General'!D39/'Balance General'!D25 -> 0.89353885 | D5: ='Balance General'!E39/'Balance General'!E25 -> 0.78605478 | E5: ='Balance General'!F39/'Balance General'!F25 -> 0.68271999 | F5: ='Balance General'!G39/'Balance General'!G25 -> 0.57619713 | G5: ='Balance General'!H39/'Balance General'!H25 -> 0.45144203 | I5: Año 1 | J5: ='Flujo de Caja'!#REF! -> #REF! | L5: VPN | M5: =M6+J4 -> #REF!
B6: Rentabilidad operacional | C6: ='Estado de Resultados'!#REF!/'Estado de Resultados'!#REF! -> #REF! | D6: ='Estado de Resultados'!#REF!/'Estado de Resultados'!#REF! -> #REF! | E6: ='Estado de Resultados'!#REF!/'Estado de Resultados'!#REF! -> #REF! | F6: ='Estado de Resultados'!#REF!/'Estado de Resultados'!#REF! -> #REF! | G6: ='Estado de Resultados'!#REF!/'Estado de Resultados'!#REF! -> #REF! | I6: Año 2 | J6: ='Flujo de Caja'!#REF! -> #REF! | L6: VAN | M6: =NPV(M4,J5:J9) -> #REF!
B7: Rentabilidad neta | C7: ='Estado de Resultados'!#REF!/'Estado de Resultados'!#REF! -> #REF! | D7: ='Estado de Resultados'!#REF!/'Estado de Resultados'!#REF! -> #REF! | E7: ='Estado de Resultados'!#REF!/'Estado de Resultados'!#REF! -> #REF! | F7: ='Estado de Resultados'!#REF!/'Estado de Resultados'!#REF! -> #REF! | G7: ='Estado de Resultados'!#REF!/'Estado de Resultados'!#REF! -> #REF! | I7: Año 3 | J7: ='Flujo de Caja'!#REF! -> #REF! | L7: TIR | M7: =IRR(J4:J9) -> #VALUE!
B8: Rentabilidad de patriominio | C8: ='Estado de Resultados'!#REF!/'Balance General'!#REF! -> #REF! | D8: ='Estado de Resultados'!#REF!/'Balance General'!#REF! -> #REF! | E8: ='Estado de Resultados'!#REF!/'Balance General'!#REF! -> #REF! | F8: ='Estado de Resultados'!#REF!/'Balance General'!#REF! -> #REF! | G8: ='Estado de Resultados'!#REF!/'Balance General'!#REF! -> #REF! | I8: Año 4 | J8: ='Flujo de Caja'!#REF! -> #REF! | L8: RBC | M8: =-NPV(M4,J5:J9)/J4 -> #REF!
I9: Año 5 | J9: ='Flujo de Caja'!#REF! -> #REF!
